Workbook
Name Excel_BuiltIn_Print_Area: '1-1 ciencias naturales experime'!$A$6:$O$68
Name Excel_BuiltIn_Print_Area: '1-1 ingles II'!$A$6:$O$68
Name Excel_BuiltIn_Print_Area: '1-1 actividades fisicas y depor'!$A$6:$O$68
Name Excel_BuiltIn_Print_Area: '1-1 taller de ciencias i'!$A$6:$O$68
Name Excel_BuiltIn_Print_Area: '1-1 educacion para la salud ii'!$A$6:$O$68
Name Excel_BuiltIn_Print_Area: '1-1 lengua y comunicacion ii'!$A$6:$O$68
Name Excel_BuiltIn_Print_Area: '1-1 pensamiento filosofico y hu'!$A$6:$O$68
Name Excel_BuiltIn_Print_Area: '1-1 ciencias sociales ii'!$A$6:$O$68
Name Excel_BuiltIn_Print_Area: '1-1 pensamiento matematico ii'!$A$6:$O$68
Name Excel_BuiltIn_Print_Area: '1-1 temas selectos de igualdad '!$A$6:$O$68
Name Excel_BuiltIn_Print_Area: '1-1 cultura digital ii'!$A$6:$O$68

Sheet 1-1 lengua y comunicacion ii
O1: HORAS IMPARTIDAS
C2: ORIENTADOR | D2: JOSE EDGAR SALAZAR ZUÑIGA | H2: ESCUELA PREPARATORIA OFICIAL NÚM.67 | O2: Febrero | P2: 12
H3: “2026. Año del Humanismo Mexicano en el Estado de México ”. | O3: Marzo | P3: 15
H4: CICLO ESCOLAR: 2025 -2026 | O4: Abril | P4: 5
E5: TURNO : | G5: MATUTINO | J5: Grado | K5: 1° | L5: Grupo | M5: 1 | O5: Mayo | P5: 11
E6: PROFESOR(A): | K6: ASIGNATURA | L6: LENGUA Y COMUNICACIÓN II | O6: Junio | P6: 14
G7: HOMBRES | H7: =A67 -> 28 | O7: Julio | P7: 3
G8: MUJERES | H8: =B67 -> 25 | O8: TOTAL | P8: =SUM(P2:P7) -> 60
G9: TOTAL | H9: =H7+H8 -> 53
A10: N | B10: P | C10: NOMBRE DEL ALUMNO | G10: PRIMERA EVALUACIÓN | I10: SEGUNDA EVALUACIÓN | K10: TERCERA EVALUACIÓN | M10: EVALUACIÓN FINAL
A11: H | B11: M | G11: FALTAS | H11: CALIF. | I11: FALTAS | J11: CALIF. | K11: FALTAS | L11: CALIF. | M11: TOT. DE FALTAS | N11: % FALTAS | O11: TOTAL DE PUNTOS | P11: CALIF. FINAL | Q11: FIRMA DEL ALUMNO | R11: ESTATUS
B12: 1 | C12: ALVAREZ | D12: HERNANDEZ | E12: DAYANNA ZOE | G12: 0 | H12: 9 | I12: 0 | J12: 9 | K12: 0 | L12: 9 | M12: =G12+I12+K12 -> 0 | N12: =(M12*100)/$P$8 -> 0 | O12: =H12+J12+L12 -> 27 | P12: =IF(AVERAGE(H12,J12,L12)<6,(5),(ROUND(AVERAGE(H12,J12,L12),0))) -> 9 | R12: =IF(N12>20,"EXTRA","ORD") -> ORD
B13: 2 | C13: ANAYA | D13: LEAL | E13: ANA IXCHEL | G13: 2 | H13: 8 | I13: 2 | J13: 8 | K13: 2 | L13: 8 | M13: =G13+I13+K13 -> 6 | N13: =(M13*100)/$P$8 -> 10 | O13: =H13+J13+L13 -> 24 | P13: =IF(AVERAGE(H13,J13,L13)<6,(5),(ROUND(AVERAGE(H13,J13,L13),0))) -> 8 | R13: =IF(N13>20,"EXTRA","ORD") -> ORD
B14: 3 | C14: ARIAS | D14: APARICIO | E14: AILISH ELIZABETH | G14: 3 | H14: 7 | I14: 3 | J14: 7 | K14: 3 | L14: 7 | M14: =G14+I14+K14 -> 9 | N14: =(M14*100)/$P$8 -> 15 | O14: =H14+J14+L14 -> 21 | P14: =IF(AVERAGE(H14,J14,L14)<6,(5),(ROUND(AVERAGE(H14,J14,L14),0))) -> 7 | R14: =IF(N14>20,"EXTRA","ORD") -> ORD
A15: 4 | C15: ARRAZOLA | D15: ROMERO | E15: DIEGO IVAN | G15: 1 | H15: 7 | I15: 10 | J15: 7 | K15: 2 | L15: 7 | M15: =G15+I15+K15 -> 13 | N15: =(M15*100)/$P$8 -> 21.666667 | O15: =H15+J15+L15 -> 21 | P15: =IF(AVERAGE(H15,J15,L15)<6,(5),(ROUND(AVERAGE(H15,J15,L15),0))) -> 7 | R15: =IF(N15>20,"EXTRA","ORD") -> EXTRA
A16: 5 | C16: ARREDONDO | D16: LOREDO | E16: JOSHUA JAAFET | G16: 0 | H16: 8 | I16: 0 | J16: 8 | K16: 0 | L16: 8 | M16: =G16+I16+K16 -> 0 | N16: =(M16*100)/$P$8 -> 0 | O16: =H16+J16+L16 -> 24 | P16: =IF(AVERAGE(H16,J16,L16)<6,(5),(ROUND(AVERAGE(H16,J16,L16),0))) -> 8 | R16: =IF(N16>20,"EXTRA","ORD") -> ORD
B17: 6 | C17: AVILES | D17: ACOSTA | E17: ARELI | G17: 1 | H17: 7 | I17: 1 | J17: 7 | K17: 1 | L17: 7 | M17: =G17+I17+K17 -> 3 | N17: =(M17*100)/$P$8 -> 5 | O17: =H17+J17+L17 -> 21 | P17: =IF(AVERAGE(H17,J17,L17)<6,(5),(ROUND(AVERAGE(H17,J17,L17),0))) -> 7 | R17: =IF(N17>20,"EXTRA","ORD") -> ORD
A18: 7 | C18: CARBAJAL | D18: RODRIGUEZ | E18: GAEL | G18: 0 | H18: 7 | I18: 0 | J18: 7 | K18: 0 | L18: 7 | M18: =G18+I18+K18 -> 0 | N18: =(M18*100)/$P$8 -> 0 | O18: =H18+J18+L18 -> 21 | P18: =IF(AVERAGE(H18,J18,L18)<6,(5),(ROUND(AVERAGE(H18,J18,L18),0))) -> 7 | R18: =IF(N18>20,"EXTRA","ORD") -> ORD
A19: 8 | C19: CARDENAS | D19: MORENO | E19: CRISTOPHER TADEO | G19: 0 | H19: 5 | I19: 0 | J19: 5 | K19: 0 | L19: 5 | M19: =G19+I19+K19 -> 0 | N19: =(M19*100)/$P$8 -> 0 | O19: =H19+J19+L19 -> 15 | P19: =IF(AVERAGE(H19,J19,L19)<6,(5),(ROUND(AVERAGE(H19,J19,L19),0))) -> 5 | R19: =IF(N19>20,"EXTRA","ORD") -> ORD
B20: 9 | C20: CASTILLO | D20: HERNANDEZ | E20: XUNELLY | G20: 3 | H20: 6 | I20: 3 | J20: 6 | K20: 3 | L20: 6 | M20: =G20+I20+K20 -> 9 | N20: =(M20*100)/$P$8 -> 15 | O20: =H20+J20+L20 -> 18 | P20: =IF(AVERAGE(H20,J20,L20)<6,(5),(ROUND(AVERAGE(H20,J20,L20),0))) -> 6 | R20: =IF(N20>20,"EXTRA","ORD") -> ORD
B21: 10 | C21: CEREZO | D21: MORALES | E21: LOURDES YURYCO | G21: 0 | H21: 6 | I21: 0 | J21: 6 | K21: 0 | L21: 6 | M21: =G21+I21+K21 -> 0 | N21: =(M21*100)/$P$8 -> 0 | O21: =H21+J21+L21 -> 18 | P21: =IF(AVERAGE(H21,J21,L21)<6,(5),(ROUND(AVERAGE(H21,J21,L21),0))) -> 6 | R21: =IF(N21>20,"EXTRA","ORD") -> ORD
A22: 11 | C22: CONTRERAS | D22: QUIÑONES | E22: OLIVER | G22: 1 | H22: 7 | I22: 1 | J22: 7 | K22: 1 | L22: 7 | M22: =G22+I22+K22 -> 3 | N22: =(M22*100)/$P$8 -> 5 | O22: =H22+J22+L22 -> 21 | P22: =IF(AVERAGE(H22,J22,L22)<6,(5),(ROUND(AVERAGE(H22,J22,L22),0))) -> 7 | R22: =IF(N22>20,"EXTRA","ORD") -> ORD
B23: 12 | C23: CRUZ | D23: CENTENO | E23: ALEXA ABIGAIL | G23: 0 | H23: 6 | I23: 0 | J23: 6 | K23: 0 | L23: 6 | M23: =G23+I23+K23 -> 0 | N23: =(M23*100)/$P$8 -> 0 | O23: =H23+J23+L23 -> 18 | P23: =IF(AVERAGE(H23,J23,L23)<6,(5),(ROUND(AVERAGE(H23,J23,L23),0))) -> 6 | R23: =IF(N23>20,"EXTRA","ORD") -> ORD
A24: 13 | C24: CRUZ | D24: PAZ | E24: CARLOS ALFONSO | G24: 0 | H24: 5 | I24: 0 | J24: 5 | K24: 0 | L24: 5 | M24: =G24+I24+K24 -> 0 | N24: =(M24*100)/$P$8 -> 0 | O24: =H24+J24+L24 -> 15 | P24: =IF(AVERAGE(H24,J24,L24)<6,(5),(ROUND(AVERAGE(H24,J24,L24),0))) -> 5 | R24: =IF(N24>20,"EXTRA","ORD") -> ORD
B25: 14 | C25: DIAZ | D25: MOLINA | E25: EMILIANA ALESSANDRA | G25: 1 | H25: 7 | I25: 1 | J25: 7 | K25: 1 | L25: 7 | M25: =G25+I25+K25 -> 3 | N25: =(M25*100)/$P$8 -> 5 | O25: =H25+J25+L25 -> 21 | P25: =IF(AVERAGE(H25,J25,L25)<6,(5),(ROUND(AVERAGE(H25,J25,L25),0))) -> 7 | R25: =IF(N25>20,"EXTRA","ORD") -> ORD
A26: 15 | C26: DUARTE | D26: ADJUNTAS | E26: RICARDO JESUS | G26: 0 | H26: 7 | I26: 0 | J26: 7 | K26: 0 | L26: 7 | M26: =G26+I26+K26 -> 0 | N26: =(M26*100)/$P$8 -> 0 | O26: =H26+J26+L26 -> 21 | P26: =IF(AVERAGE(H26,J26,L26)<6,(5),(ROUND(AVERAGE(H26,J26,L26),0))) -> 7 | R26: =IF(N26>20,"EXTRA","ORD") -> ORD
A27: 16 | C27: ESTRADA | D27: VENEGAS | E27: DAVID RICARDO | G27: 0 | H27: 7 | I27: 0 | J27: 7 | K27: 0 | L27: 7 | M27: =G27+I27+K27 -> 0 | N27: =(M27*100)/$P$8 -> 0 | O27: =H27+J27+L27 -> 21 | P27: =IF(AVERAGE(H27,J27,L27)<6,(5),(ROUND(AVERAGE(H27,J27,L27),0))) -> 7 | R27: =IF(N27>20,"EXTRA","ORD") -> ORD
B28: 17 | C28: FLORES | D28: VARGAS | E28: FERNANDA DESSIRE | G28: 2 | H28: 8 | I28: 2 | J28: 8 | K28: 2 | L28: 8 | M28: =G28+I28+K28 -> 6 | N28: =(M28*100)/$P$8 -> 10 | O28: =H28+J28+L28 -> 24 | P28: =IF(AVERAGE(H28,J28,L28)<6,(5),(ROUND(AVERAGE(H28,J28,L28),0))) -> 8 | R28: =IF(N28>20,"EXTRA","ORD") -> ORD
A29: 18 | C29: FUENTES | D29: HERNANDEZ | E29: DIEGO ISRAEL | G29: 0 | H29: 6 | I29: 0 | J29: 6 | K29: 0 | L29: 6 | M29: =G29+I29+K29 -> 0 | N29: =(M29*100)/$P$8 -> 0 | O29: =H29+J29+L29 -> 18 | P29: =IF(AVERAGE(H29,J29,L29)<6,(5),(ROUND(AVERAGE(H29,J29,L29),0))) -> 6 | R29: =IF(N29>20,"EXTRA","ORD") -> ORD
B30: 19 | C30: GALINDO | D30: CRUZ | E30: LUISA VALENTINA | G30: 1 | H30: 7 | I30: 1 | J30: 7 | K30: 1 | L30: 7 | M30: =G30+I30+K30 -> 3 | N30: =(M30*100)/$P$8 -> 5 | O30: =H30+J30+L30 -> 21 | P30: =IF(AVERAGE(H30,J30,L30)<6,(5),(ROUND(AVERAGE(H30,J30,L30),0))) -> 7 | R30: =IF(N30>20,"EXTRA","ORD") -> ORD
B31: 20 | C31: GARCIA | D31: ARELLANO | E31: YULIANA REBECA | G31: 0 | H31: 7 | I31: 0 | J31: 7 | K31: 0 | L31: 7 | M31: =G31+I31+K31 -> 0 | N31: =(M31*100)/$P$8 -> 0 | O31: =H31+J31+L31 -> 21 | P31: =IF(AVERAGE(H31,J31,L31)<6,(5),(ROUND(AVERAGE(H31,J31,L31),0))) -> 7 | R31: =IF(N31>20,"EXTRA","ORD") -> ORD
A32: 21 | C32: GARCIA | D32: PEÑA | E32: ANDREI | G32: 0 | H32: 6 | I32: 0 | J32: 6 | K32: 0 | L32: 6 | M32: =G32+I32+K32 -> 0 | N32: =(M32*100)/$P$8 -> 0 | O32: =H32+J32+L32 -> 18 | P32: =IF(AVERAGE(H32,J32,L32)<6,(5),(ROUND(AVERAGE(H32,J32,L32),0))) -> 6 | R32: =IF(N32>20,"EXTRA","ORD") -> ORD
A33: 22 | C33: GARCILAZO | D33: MARTINEZ | E33: ALFONSO | G33: 1 | H33: 6 | I33: 1 | J33: 6 | K33: 1 | L33: 6 | M33: =G33+I33+K33 -> 3 | N33: =(M33*100)/$P$8 -> 5 | O33: =H33+J33+L33 -> 18 | P33: =IF(AVERAGE(H33,J33,L33)<6,(5),(ROUND(AVERAGE(H33,J33,L33),0))) -> 6 | R33: =IF(N33>20,"EXTRA","ORD") -> ORD
A34: 23 | C34: GODOY | D34: MARQUEZ | E34: DUSTIN YALIL | G34: 0 | H34: 8 | I34: 0 | J34: 8 | K34: 0 | L34: 8 | M34: =G34+I34+K34 -> 0 | N34: =(M34*100)/$P$8 -> 0 | O34: =H34+J34+L34 -> 24 | P34: =IF(AVERAGE(H34,J34,L34)<6,(5),(ROUND(AVERAGE(H34,J34,L34),0))) -> 8 | R34: =IF(N34>20,"EXTRA","ORD") -> ORD
B35: 24 | C35: GONZALEZ | D35: RAMOS | E35: FATIMA NAOMY | G35: 0 | H35: 7 | I35: 0 | J35: 7 | K35: 0 | L35: 7 | M35: =G35+I35+K35 -> 0 | N35: =(M35*100)/$P$8 -> 0 | O35: =H35+J35+L35 -> 21 | P35: =IF(AVERAGE(H35,J35,L35)<6,(5),(ROUND(AVERAGE(H35,J35,L35),0))) -> 7 | R35: =IF(N35>20,"EXTRA","ORD") -> ORD
B36: 25 | C36: GUERRERO | D36: ORTIZ | E36: VALERIA ROMINA | G36: 0 | H36: 7 | I36: 0 | J36: 7 | K36: 0 | L36: 7 | M36: =G36+I36+K36 -> 0 | N36: =(M36*100)/$P$8 -> 0 | O36: =H36+J36+L36 -> 21 | P36: =IF(AVERAGE(H36,J36,L36)<6,(5),(ROUND(AVERAGE(H36,J36,L36),0))) -> 7 | R36: =IF(N36>20,"EXTRA","ORD") -> ORD
B37: 26 | C37: GUTIERREZ | D37: ANGELES | E37: SAMANTHA PAOLA | G37: 0 | H37: 7 | I37: 0 | J37: 7 | K37: 0 | L37: 7 | M37: =G37+I37+K37 -> 0 | N37: =(M37*100)/$P$8 -> 0 | O37: =H37+J37+L37 -> 21 | P37: =IF(AVERAGE(H37,J37,L37)<6,(5),(ROUND(AVERAGE(H37,J37,L37),0))) -> 7 | R37: =IF(N37>20,"EXTRA","ORD") -> ORD
A38: 27 | C38: HERNANDEZ | D38: VARGAS | E38: MOISES | G38: 0 | H38: 7 | I38: 0 | J38: 7 | K38: 0 | L38: 7 | M38: =G38+I38+K38 -> 0 | N38: =(M38*100)/$P$8 -> 0 | O38: =H38+J38+L38 -> 21 | P38: =IF(AVERAGE(H38,J38,L38)<6,(5),(ROUND(AVERAGE(H38,J38,L38),0))) -> 7 | R38: =IF(N38>20,"EXTRA","ORD") -> ORD
B39: 28 | C39: HERNANDEZ | D39: VIVEROS | E39: SAMANTHA SHARON | G39: 1 | H39: 7 | I39: 1 | J39: 7 | K39: 1 | L39: 7 | M39: =G39+I39+K39 -> 3 | N39: =(M39*100)/$P$8 -> 5 | O39: =H39+J39+L39 -> 21 | P39: =IF(AVERAGE(H39,J39,L39)<6,(5),(ROUND(AVERAGE(H39,J39,L39),0))) -> 7 | R39: =IF(N39>20,"EXTRA","ORD") -> ORD
B40: 29 | C40: ISLAS | D40: GARCIA | E40: MARIANA | G40: 3 | H40: 7 | I40: 3 | J40: 7 | K40: 3 | L40: 7 | M40: =G40+I40+K40 -> 9 | N40: =(M40*100)/$P$8 -> 15 | O40: =H40+J40+L40 -> 21 | P40: =IF(AVERAGE(H40,J40,L40)<6,(5),(ROUND(AVERAGE(H40,J40,L40),0))) -> 7 | R40: =IF(N40>20,"EXTRA","ORD") -> ORD
...

Sheet 1-1 ingles II
O1: HORAS IMPARTIDAS
C2: ORIENTADOR | D2: JOSE EDGAR SALAZAR ZUÑIGA | H2: ESCUELA PREPARATORIA OFICIAL NÚM.67 | O2: Febrero | P2: 12
H3: “2026. Año del Humanismo Mexicano en el Estado de México ”. | O3: Marzo | P3: 15
H4: CICLO ESCOLAR: 2025 -2026 | O4: Abril | P4: 50
E5: TURNO : | G5: MATUTINO | J5: Grado | K5: 1° | L5: Grupo | M5: 1 | O5: Mayo | P5: 11
E6: PROFESOR(A): | K6: UAC | L6: INGLÉS II | O6: Junio | P6: 14
G7: HOMBRES | H7: =A67 -> 28 | O7: Julio | P7: 3
G8: MUJERES | H8: =B67 -> 25 | O8: TOTAL | P8: =SUM(P2:P7) -> 105
G9: TOTAL | H9: =H7+H8 -> 53
A10: N | B10: P | C10: NOMBRE DEL ALUMNO | G10: PRIMERA EVALUACIÓN | I10: SEGUNDA EVALUACIÓN | K10: TERCERA EVALUACIÓN | M10: EVALUACIÓN FINAL
A11: H | B11: M | G11: FALTAS | H11: CALIF. | I11: FALTAS | J11: CALIF. | K11: FALTAS | L11: CALIF. | M11: TOT. DE FALTAS | N11: % FALTAS | O11: TOTAL DE PUNTOS | P11: CALIF. FINAL | Q11: FIRMA DEL ALUMNO | R11: ESTATUS
B12: 1 | C12: ALVAREZ | D12: HERNANDEZ | E12: DAYANNA ZOE | G12: 21 | H12: 7 | M12: =G12+I12+K12 -> 21 | N12: =(M12*100)/$P$8 -> 20 | O12: =H12+J12+L12 -> 7 | P12: =IF(AVERAGE(H12,J12,L12)<6,(5),(ROUND(AVERAGE(H12,J12,L12),0))) -> 7 | R12: =IF(N12>20,"EXTRA","ORD") -> ORD
B13: 2 | C13: ANAYA | D13: LEAL | E13: ANA IXCHEL | G13: 0 | H13: 10 | M13: =G13+I13+K13 -> 0 | N13: =(M13*100)/$P$8 -> 0 | O13: =H13+J13+L13 -> 10 | P13: =IF(AVERAGE(H13,J13,L13)<6,(5),(ROUND(AVERAGE(H13,J13,L13),0))) -> 10 | R13: =IF(N13>20,"EXTRA","ORD") -> ORD
B14: 3 | C14: ARIAS | D14: APARICIO | E14: AILISH ELIZABETH | G14: 0 | H14: 10 | M14: =G14+I14+K14 -> 0 | N14: =(M14*100)/$P$8 -> 0 | O14: =H14+J14+L14 -> 10 | P14: =IF(AVERAGE(H14,J14,L14)<6,(5),(ROUND(AVERAGE(H14,J14,L14),0))) -> 10 | R14: =IF(N14>20,"EXTRA","ORD") -> ORD
A15: 4 | C15: ARRAZOLA | D15: ROMERO | E15: DIEGO IVAN | G15: 0 | H15: 6 | M15: =G15+I15+K15 -> 0 | N15: =(M15*100)/$P$8 -> 0 | O15: =H15+J15+L15 -> 6 | P15: =IF(AVERAGE(H15,J15,L15)<6,(5),(ROUND(AVERAGE(H15,J15,L15),0))) -> 6 | R15: =IF(N15>20,"EXTRA","ORD") -> ORD
A16: 5 | C16: ARREDONDO | D16: LOREDO | E16: JOSHUA JAAFET | G16: 0 | H16: 8 | M16: =G16+I16+K16 -> 0 | N16: =(M16*100)/$P$8 -> 0 | O16: =H16+J16+L16 -> 8 | P16: =IF(AVERAGE(H16,J16,L16)<6,(5),(ROUND(AVERAGE(H16,J16,L16),0))) -> 8 | R16: =IF(N16>20,"EXTRA","ORD") -> ORD
B17: 6 | C17: AVILES | D17: ACOSTA | E17: ARELI | G17: 0 | H17: 8 | M17: =G17+I17+K17 -> 0 | N17: =(M17*100)/$P$8 -> 0 | O17: =H17+J17+L17 -> 8 | P17: =IF(AVERAGE(H17,J17,L17)<6,(5),(ROUND(AVERAGE(H17,J17,L17),0))) -> 8 | R17: =IF(N17>20,"EXTRA","ORD") -> ORD
A18: 7 | C18: CARBAJAL | D18: RODRIGUEZ | E18: GAEL | G18: 0 | H18: 8 | M18: =G18+I18+K18 -> 0 | N18: =(M18*100)/$P$8 -> 0 | O18: =H18+J18+L18 -> 8 | P18: =IF(AVERAGE(H18,J18,L18)<6,(5),(ROUND(AVERAGE(H18,J18,L18),0))) -> 8 | R18: =IF(N18>20,"EXTRA","ORD") -> ORD
A19: 8 | C19: CARDENAS | D19: MORENO | E19: CRISTOPHER TADEO | G19: 0 | H19: 10 | M19: =G19+I19+K19 -> 0 | N19: =(M19*100)/$P$8 -> 0 | O19: =H19+J19+L19 -> 10 | P19: =IF(AVERAGE(H19,J19,L19)<6,(5),(ROUND(AVERAGE(H19,J19,L19),0))) -> 10 | R19: =IF(N19>20,"EXTRA","ORD") -> ORD
B20: 9 | C20: CASTILLO | D20: HERNANDEZ | E20: XUNELLY | G20: 0 | H20: 5 | M20: =G20+I20+K20 -> 0 | N20: =(M20*100)/$P$8 -> 0 | O20: =H20+J20+L20 -> 5 | P20: =IF(AVERAGE(H20,J20,L20)<6,(5),(ROUND(AVERAGE(H20,J20,L20),0))) -> 5 | R20: =IF(N20>20,"EXTRA","ORD") -> ORD
B21: 10 | C21: CEREZO | D21: MORALES | E21: LOURDES YURYCO | G21: 0 | H21: 10 | M21: =G21+I21+K21 -> 0 | N21: =(M21*100)/$P$8 -> 0 | O21: =H21+J21+L21 -> 10 | P21: =IF(AVERAGE(H21,J21,L21)<6,(5),(ROUND(AVERAGE(H21,J21,L21),0))) -> 10 | R21: =IF(N21>20,"EXTRA","ORD") -> ORD
A22: 11 | C22: CONTRERAS | D22: QUIÑONES | E22: OLIVER | G22: 0 | H22: 8 | M22: =G22+I22+K22 -> 0 | N22: =(M22*100)/$P$8 -> 0 | O22: =H22+J22+L22 -> 8 | P22: =IF(AVERAGE(H22,J22,L22)<6,(5),(ROUND(AVERAGE(H22,J22,L22),0))) -> 8 | R22: =IF(N22>20,"EXTRA","ORD") -> ORD
B23: 12 | C23: CRUZ | D23: CENTENO | E23: ALEXA ABIGAIL | G23: 0 | H23: 6 | M23: =G23+I23+K23 -> 0 | N23: =(M23*100)/$P$8 -> 0 | O23: =H23+J23+L23 -> 6 | P23: =IF(AVERAGE(H23,J23,L23)<6,(5),(ROUND(AVERAGE(H23,J23,L23),0))) -> 6 | R23: =IF(N23>20,"EXTRA","ORD") -> ORD
A24: 13 | C24: CRUZ | D24: PAZ | E24: CARLOS ALFONSO | G24: 0 | H24: 7 | M24: =G24+I24+K24 -> 0 | N24: =(M24*100)/$P$8 -> 0 | O24: =H24+J24+L24 -> 7 | P24: =IF(AVERAGE(H24,J24,L24)<6,(5),(ROUND(AVERAGE(H24,J24,L24),0))) -> 7 | R24: =IF(N24>20,"EXTRA","ORD") -> ORD
B25: 14 | C25: DIAZ | D25: MOLINA | E25: EMILIANA ALESSANDRA | G25: 0 | H25: 10 | M25: =G25+I25+K25 -> 0 | N25: =(M25*100)/$P$8 -> 0 | O25: =H25+J25+L25 -> 10 | P25: =IF(AVERAGE(H25,J25,L25)<6,(5),(ROUND(AVERAGE(H25,J25,L25),0))) -> 10 | R25: =IF(N25>20,"EXTRA","ORD") -> ORD
A26: 15 | C26: DUARTE | D26: ADJUNTAS | E26: RICARDO JESUS | G26: 0 | H26: 10 | M26: =G26+I26+K26 -> 0 | N26: =(M26*100)/$P$8 -> 0 | O26: =H26+J26+L26 -> 10 | P26: =IF(AVERAGE(H26,J26,L26)<6,(5),(ROUND(AVERAGE(H26,J26,L26),0))) -> 10 | R26: =IF(N26>20,"EXTRA","ORD") -> ORD
A27: 16 | C27: ESTRADA | D27: VENEGAS | E27: DAVID RICARDO | G27: 0 | H27: 5 | M27: =G27+I27+K27 -> 0 | N27: =(M27*100)/$P$8 -> 0 | O27: =H27+J27+L27 -> 5 | P27: =IF(AVERAGE(H27,J27,L27)<6,(5),(ROUND(AVERAGE(H27,J27,L27),0))) -> 5 | R27: =IF(N27>20,"EXTRA","ORD") -> ORD
B28: 17 | C28: FLORES | D28: VARGAS | E28: FERNANDA DESSIRE | G28: 0 | H28: 7 | M28: =G28+I28+K28 -> 0 | N28: =(M28*100)/$P$8 -> 0 | O28: =H28+J28+L28 -> 7 | P28: =IF(AVERAGE(H28,J28,L28)<6,(5),(ROUND(AVERAGE(H28,J28,L28),0))) -> 7 | R28: =IF(N28>20,"EXTRA","ORD") -> ORD
A29: 18 | C29: FUENTES | D29: HERNANDEZ | E29: DIEGO ISRAEL | G29: 0 | H29: 6 | M29: =G29+I29+K29 -> 0 | N29: =(M29*100)/$P$8 -> 0 | O29: =H29+J29+L29 -> 6 | P29: =IF(AVERAGE(H29,J29,L29)<6,(5),(ROUND(AVERAGE(H29,J29,L29),0))) -> 6 | R29: =IF(N29>20,"EXTRA","ORD") -> ORD
B30: 19 | C30: GALINDO | D30: CRUZ | E30: LUISA VALENTINA | G30: 1 | H30: 6 | M30: =G30+I30+K30 -> 1 | N30: =(M30*100)/$P$8 -> 0.95238095 | O30: =H30+J30+L30 -> 6 | P30: =IF(AVERAGE(H30,J30,L30)<6,(5),(ROUND(AVERAGE(H30,J30,L30),0))) -> 6 | R30: =IF(N30>20,"EXTRA","ORD") -> ORD
B31: 20 | C31: GARCIA | D31: ARELLANO | E31: YULIANA REBECA | G31: 0 | H31: 10 | M31: =G31+I31+K31 -> 0 | N31: =(M31*100)/$P$8 -> 0 | O31: =H31+J31+L31 -> 10 | P31: =IF(AVERAGE(H31,J31,L31)<6,(5),(ROUND(AVERAGE(H31,J31,L31),0))) -> 10 | R31: =IF(N31>20,"EXTRA","ORD") -> ORD
A32: 21 | C32: GARCIA | D32: PEÑA | E32: ANDREI | G32: 0 | H32: 9 | M32: =G32+I32+K32 -> 0 | N32: =(M32*100)/$P$8 -> 0 | O32: =H32+J32+L32 -> 9 | P32: =IF(AVERAGE(H32,J32,L32)<6,(5),(ROUND(AVERAGE(H32,J32,L32),0))) -> 9 | R32: =IF(N32>20,"EXTRA","ORD") -> ORD
A33: 22 | C33: GARCILAZO | D33: MARTINEZ | E33: ALFONSO | G33: 0 | H33: 7 | M33: =G33+I33+K33 -> 0 | N33: =(M33*100)/$P$8 -> 0 | O33: =H33+J33+L33 -> 7 | P33: =IF(AVERAGE(H33,J33,L33)<6,(5),(ROUND(AVERAGE(H33,J33,L33),0))) -> 7 | R33: =IF(N33>20,"EXTRA","ORD") -> ORD
A34: 23 | C34: GODOY | D34: MARQUEZ | E34: DUSTIN YALIL | G34: 1 | H34: 5 | M34: =G34+I34+K34 -> 1 | N34: =(M34*100)/$P$8 -> 0.95238095 | O34: =H34+J34+L34 -> 5 | P34: =IF(AVERAGE(H34,J34,L34)<6,(5),(ROUND(AVERAGE(H34,J34,L34),0))) -> 5 | R34: =IF(N34>20,"EXTRA","ORD") -> ORD
B35: 24 | C35: GONZALEZ | D35: RAMOS | E35: FATIMA NAOMY | G35: 2 | H35: 10 | M35: =G35+I35+K35 -> 2 | N35: =(M35*100)/$P$8 -> 1.9047619 | O35: =H35+J35+L35 -> 10 | P35: =IF(AVERAGE(H35,J35,L35)<6,(5),(ROUND(AVERAGE(H35,J35,L35),0))) -> 10 | R35: =IF(N35>20,"EXTRA","ORD") -> ORD
B36: 25 | C36: GUERRERO | D36: ORTIZ | E36: VALERIA ROMINA | G36: 0 | H36: 10 | M36: =G36+I36+K36 -> 0 | N36: =(M36*100)/$P$8 -> 0 | O36: =H36+J36+L36 -> 10 | P36: =IF(AVERAGE(H36,J36,L36)<6,(5),(ROUND(AVERAGE(H36,J36,L36),0))) -> 10 | R36: =IF(N36>20,"EXTRA","ORD") -> ORD
B37: 26 | C37: GUTIERREZ | D37: ANGELES | E37: SAMANTHA PAOLA | G37: 0 | H37: 10 | M37: =G37+I37+K37 -> 0 | N37: =(M37*100)/$P$8 -> 0 | O37: =H37+J37+L37 -> 10 | P37: =IF(AVERAGE(H37,J37,L37)<6,(5),(ROUND(AVERAGE(H37,J37,L37),0))) -> 10 | R37: =IF(N37>20,"EXTRA","ORD") -> ORD
A38: 27 | C38: HERNANDEZ | D38: VARGAS | E38: MOISES | G38: 0 | H38: 10 | M38: =G38+I38+K38 -> 0 | N38: =(M38*100)/$P$8 -> 0 | O38: =H38+J38+L38 -> 10 | P38: =IF(AVERAGE(H38,J38,L38)<6,(5),(ROUND(AVERAGE(H38,J38,L38),0))) -> 10 | R38: =IF(N38>20,"EXTRA","ORD") -> ORD
B39: 28 | C39: HERNANDEZ | D39: VIVEROS | E39: SAMANTHA SHARON | G39: 0 | H39: 9 | M39: =G39+I39+K39 -> 0 | N39: =(M39*100)/$P$8 -> 0 | O39: =H39+J39+L39 -> 9 | P39: =IF(AVERAGE(H39,J39,L39)<6,(5),(ROUND(AVERAGE(H39,J39,L39),0))) -> 9 | R39: =IF(N39>20,"EXTRA","ORD") -> ORD
B40: 29 | C40: ISLAS | D40: GARCIA | E40: MARIANA | G40: 0 | H40: 9 | M40: =G40+I40+K40 -> 0 | N40: =(M40*100)/$P$8 -> 0 | O40: =H40+J40+L40 -> 9 | P40: =IF(AVERAGE(H40,J40,L40)<6,(5),(ROUND(AVERAGE(H40,J40,L40),0))) -> 9 | R40: =IF(N40>20,"EXTRA","ORD") -> ORD
...

Sheet 1-1 pensamiento matematico ii
O1: HORAS IMPARTIDAS
C2: ORIENTADOR | D2: JOSE EDGAR SALAZAR ZUÑIGA | H2: ESCUELA PREPARATORIA OFICIAL NÚM.67 | O2: Febrero | P2: 12
H3: “2026. Año del Humanismo Mexicano en el Estado de México ”. | O3: Marzo | P3: 15
H4: CICLO ESCOLAR: 2025 -2026 | O4: Abril | P4: 5
E5: TURNO : | G5: MATUTINO | J5: Grado | K5: 1° | L5: Grupo | M5: 1 | O5: Mayo | P5: 11
E6: PROFESOR(A): | K6: UAC | L6: PENSAMIENTO MATEMÁTICO II | O6: Junio | P6: 14
G7: HOMBRES | H7: =A67 -> 28 | O7: Julio | P7: 3
G8: MUJERES | H8: =B67 -> 25 | O8: TOTAL | P8: =SUM(P2:P7) -> 60
G9: TOTAL | H9: =H7+H8 -> 53
A10: N | B10: P | C10: NOMBRE DEL ALUMNO | G10: PRIMERA EVALUACIÓN | I10: SEGUNDA EVALUACIÓN | K10: TERCERA EVALUACIÓN | M10: EVALUACIÓN FINAL
A11: H | B11: M | G11: FALTAS | H11: CALIF. | I11: FALTAS | J11: CALIF. | K11: FALTAS | L11: CALIF. | M11: TOT. DE FALTAS | N11: % FALTAS | O11: TOTAL DE PUNTOS | P11: CALIF. FINAL | Q11: FIRMA DEL ALUMNO | R11: ESTATUS
B12: 1 | C12: ALVAREZ | D12: HERNANDEZ | E12: DAYANNA ZOE | G12: 0 | H12: 6 | M12: =G12+I12+K12 -> 0 | N12: =(M12*100)/$P$8 -> 0 | O12: =H12+J12+L12 -> 6 | P12: =IF(AVERAGE(H12,J12,L12)<6,(5),(ROUND(AVERAGE(H12,J12,L12),0))) -> 6 | R12: =IF(N12>20,"EXTRA","ORD") -> ORD
B13: 2 | C13: ANAYA | D13: LEAL | E13: ANA IXCHEL | G13: 0 | H13: 6 | M13: =G13+I13+K13 -> 0 | N13: =(M13*100)/$P$8 -> 0 | O13: =H13+J13+L13 -> 6 | P13: =IF(AVERAGE(H13,J13,L13)<6,(5),(ROUND(AVERAGE(H13,J13,L13),0))) -> 6 | R13: =IF(N13>20,"EXTRA","ORD") -> ORD
B14: 3 | C14: ARIAS | D14: APARICIO | E14: AILISH ELIZABETH | G14: 0 | H14: 6 | M14: =G14+I14+K14 -> 0 | N14: =(M14*100)/$P$8 -> 0 | O14: =H14+J14+L14 -> 6 | P14: =IF(AVERAGE(H14,J14,L14)<6,(5),(ROUND(AVERAGE(H14,J14,L14),0))) -> 6 | R14: =IF(N14>20,"EXTRA","ORD") -> ORD
A15: 4 | C15: ARRAZOLA | D15: ROMERO | E15: DIEGO IVAN | G15: 0 | H15: 6 | M15: =G15+I15+K15 -> 0 | N15: =(M15*100)/$P$8 -> 0 | O15: =H15+J15+L15 -> 6 | P15: =IF(AVERAGE(H15,J15,L15)<6,(5),(ROUND(AVERAGE(H15,J15,L15),0))) -> 6 | R15: =IF(N15>20,"EXTRA","ORD") -> ORD
A16: 5 | C16: ARREDONDO | D16: LOREDO | E16: JOSHUA JAAFET | G16: 0 | H16: 6 | M16: =G16+I16+K16 -> 0 | N16: =(M16*100)/$P$8 -> 0 | O16: =H16+J16+L16 -> 6 | P16: =IF(AVERAGE(H16,J16,L16)<6,(5),(ROUND(AVERAGE(H16,J16,L16),0))) -> 6 | R16: =IF(N16>20,"EXTRA","ORD") -> ORD
B17: 6 | C17: AVILES | D17: ACOSTA | E17: ARELI | G17: 0 | H17: 6 | M17: =G17+I17+K17 -> 0 | N17: =(M17*100)/$P$8 -> 0 | O17: =H17+J17+L17 -> 6 | P17: =IF(AVERAGE(H17,J17,L17)<6,(5),(ROUND(AVERAGE(H17,J17,L17),0))) -> 6 | R17: =IF(N17>20,"EXTRA","ORD") -> ORD
A18: 7 | C18: CARBAJAL | D18: RODRIGUEZ | E18: GAEL | G18: 0 | H18: 6 | M18: =G18+I18+K18 -> 0 | N18: =(M18*100)/$P$8 -> 0 | O18: =H18+J18+L18 -> 6 | P18: =IF(AVERAGE(H18,J18,L18)<6,(5),(ROUND(AVERAGE(H18,J18,L18),0))) -> 6 | R18: =IF(N18>20,"EXTRA","ORD") -> ORD
A19: 8 | C19: CARDENAS | D19: MORENO | E19: CRISTOPHER TADEO | G19: 0 | H19: 8 | M19: =G19+I19+K19 -> 0 | N19: =(M19*100)/$P$8 -> 0 | O19: =H19+J19+L19 -> 8 | P19: =IF(AVERAGE(H19,J19,L19)<6,(5),(ROUND(AVERAGE(H19,J19,L19),0))) -> 8 | R19: =IF(N19>20,"EXTRA","ORD") -> ORD
B20: 9 | C20: CASTILLO | D20: HERNANDEZ | E20: XUNELLY | G20: 0 | H20: 5 | M20: =G20+I20+K20 -> 0 | N20: =(M20*100)/$P$8 -> 0 | O20: =H20+J20+L20 -> 5 | P20: =IF(AVERAGE(H20,J20,L20)<6,(5),(ROUND(AVERAGE(H20,J20,L20),0))) -> 5 | R20: =IF(N20>20,"EXTRA","ORD") -> ORD
B21: 10 | C21: CEREZO | D21: MORALES | E21: LOURDES YURYCO | G21: 0 | H21: 6 | M21: =G21+I21+K21 -> 0 | N21: =(M21*100)/$P$8 -> 0 | O21: =H21+J21+L21 -> 6 | P21: =IF(AVERAGE(H21,J21,L21)<6,(5),(ROUND(AVERAGE(H21,J21,L21),0))) -> 6 | R21: =IF(N21>20,"EXTRA","ORD") -> ORD
A22: 11 | C22: CONTRERAS | D22: QUIÑONES | E22: OLIVER | G22: 0 | H22: 6 | M22: =G22+I22+K22 -> 0 | N22: =(M22*100)/$P$8 -> 0 | O22: =H22+J22+L22 -> 6 | P22: =IF(AVERAGE(H22,J22,L22)<6,(5),(ROUND(AVERAGE(H22,J22,L22),0))) -> 6 | R22: =IF(N22>20,"EXTRA","ORD") -> ORD
B23: 12 | C23: CRUZ | D23: CENTENO | E23: ALEXA ABIGAIL | G23: 0 | H23: 6 | M23: =G23+I23+K23 -> 0 | N23: =(M23*100)/$P$8 -> 0 | O23: =H23+J23+L23 -> 6 | P23: =IF(AVERAGE(H23,J23,L23)<6,(5),(ROUND(AVERAGE(H23,J23,L23),0))) -> 6 | R23: =IF(N23>20,"EXTRA","ORD") -> ORD
A24: 13 | C24: CRUZ | D24: PAZ | E24: CARLOS ALFONSO | G24: 0 | H24: 5 | M24: =G24+I24+K24 -> 0 | N24: =(M24*100)/$P$8 -> 0 | O24: =H24+J24+L24 -> 5 | P24: =IF(AVERAGE(H24,J24,L24)<6,(5),(ROUND(AVERAGE(H24,J24,L24),0))) -> 5 | R24: =IF(N24>20,"EXTRA","ORD") -> ORD
B25: 14 | C25: DIAZ | D25: MOLINA | E25: EMILIANA ALESSANDRA | G25: 0 | H25: 6 | M25: =G25+I25+K25 -> 0 | N25: =(M25*100)/$P$8 -> 0 | O25: =H25+J25+L25 -> 6 | P25: =IF(AVERAGE(H25,J25,L25)<6,(5),(ROUND(AVERAGE(H25,J25,L25),0))) -> 6 | R25: =IF(N25>20,"EXTRA","ORD") -> ORD
A26: 15 | C26: DUARTE | D26: ADJUNTAS | E26: RICARDO JESUS | G26: 0 | H26: 10 | M26: =G26+I26+K26 -> 0 | N26: =(M26*100)/$P$8 -> 0 | O26: =H26+J26+L26 -> 10 | P26: =IF(AVERAGE(H26,J26,L26)<6,(5),(ROUND(AVERAGE(H26,J26,L26),0))) -> 10 | R26: =IF(N26>20,"EXTRA","ORD") -> ORD
A27: 16 | C27: ESTRADA | D27: VENEGAS | E27: DAVID RICARDO | G27: 0 | H27: 5 | M27: =G27+I27+K27 -> 0 | N27: =(M27*100)/$P$8 -> 0 | O27: =H27+J27+L27 -> 5 | P27: =IF(AVERAGE(H27,J27,L27)<6,(5),(ROUND(AVERAGE(H27,J27,L27),0))) -> 5 | R27: =IF(N27>20,"EXTRA","ORD") -> ORD
B28: 17 | C28: FLORES | D28: VARGAS | E28: FERNANDA DESSIRE | G28: 0 | H28: 7 | M28: =G28+I28+K28 -> 0 | N28: =(M28*100)/$P$8 -> 0 | O28: =H28+J28+L28 -> 7 | P28: =IF(AVERAGE(H28,J28,L28)<6,(5),(ROUND(AVERAGE(H28,J28,L28),0))) -> 7 | R28: =IF(N28>20,"EXTRA","ORD") -> ORD
A29: 18 | C29: FUENTES | D29: HERNANDEZ | E29: DIEGO ISRAEL | G29: 0 | H29: 6 | M29: =G29+I29+K29 -> 0 | N29: =(M29*100)/$P$8 -> 0 | O29: =H29+J29+L29 -> 6 | P29: =IF(AVERAGE(H29,J29,L29)<6,(5),(ROUND(AVERAGE(H29,J29,L29),0))) -> 6 | R29: =IF(N29>20,"EXTRA","ORD") -> ORD
B30: 19 | C30: GALINDO | D30: CRUZ | E30: LUISA VALENTINA | G30: 1 | H30: 6 | M30: =G30+I30+K30 -> 1 | N30: =(M30*100)/$P$8 -> 1.6666667 | O30: =H30+J30+L30 -> 6 | P30: =IF(AVERAGE(H30,J30,L30)<6,(5),(ROUND(AVERAGE(H30,J30,L30),0))) -> 6 | R30: =IF(N30>20,"EXTRA","ORD") -> ORD
B31: 20 | C31: GARCIA | D31: ARELLANO | E31: YULIANA REBECA | G31: 0 | H31: 10 | M31: =G31+I31+K31 -> 0 | N31: =(M31*100)/$P$8 -> 0 | O31: =H31+J31+L31 -> 10 | P31: =IF(AVERAGE(H31,J31,L31)<6,(5),(ROUND(AVERAGE(H31,J31,L31),0))) -> 10 | R31: =IF(N31>20,"EXTRA","ORD") -> ORD
A32: 21 | C32: GARCIA | D32: PEÑA | E32: ANDREI | G32: 0 | H32: 9 | M32: =G32+I32+K32 -> 0 | N32: =(M32*100)/$P$8 -> 0 | O32: =H32+J32+L32 -> 9 | P32: =IF(AVERAGE(H32,J32,L32)<6,(5),(ROUND(AVERAGE(H32,J32,L32),0))) -> 9 | R32: =IF(N32>20,"EXTRA","ORD") -> ORD
A33: 22 | C33: GARCILAZO | D33: MARTINEZ | E33: ALFONSO | G33: 0 | H33: 6 | M33: =G33+I33+K33 -> 0 | N33: =(M33*100)/$P$8 -> 0 | O33: =H33+J33+L33 -> 6 | P33: =IF(AVERAGE(H33,J33,L33)<6,(5),(ROUND(AVERAGE(H33,J33,L33),0))) -> 6 | R33: =IF(N33>20,"EXTRA","ORD") -> ORD
A34: 23 | C34: GODOY | D34: MARQUEZ | E34: DUSTIN YALIL | G34: 1 | H34: 5 | M34: =G34+I34+K34 -> 1 | N34: =(M34*100)/$P$8 -> 1.6666667 | O34: =H34+J34+L34 -> 5 | P34: =IF(AVERAGE(H34,J34,L34)<6,(5),(ROUND(AVERAGE(H34,J34,L34),0))) -> 5 | R34: =IF(N34>20,"EXTRA","ORD") -> ORD
B35: 24 | C35: GONZALEZ | D35: RAMOS | E35: FATIMA NAOMY | G35: 2 | H35: 7 | M35: =G35+I35+K35 -> 2 | N35: =(M35*100)/$P$8 -> 3.3333333 | O35: =H35+J35+L35 -> 7 | P35: =IF(AVERAGE(H35,J35,L35)<6,(5),(ROUND(AVERAGE(H35,J35,L35),0))) -> 7 | R35: =IF(N35>20,"EXTRA","ORD") -> ORD
B36: 25 | C36: GUERRERO | D36: ORTIZ | E36: VALERIA ROMINA | G36: 0 | H36: 7 | M36: =G36+I36+K36 -> 0 | N36: =(M36*100)/$P$8 -> 0 | O36: =H36+J36+L36 -> 7 | P36: =IF(AVERAGE(H36,J36,L36)<6,(5),(ROUND(AVERAGE(H36,J36,L36),0))) -> 7 | R36: =IF(N36>20,"EXTRA","ORD") -> ORD
B37: 26 | C37: GUTIERREZ | D37: ANGELES | E37: SAMANTHA PAOLA | G37: 0 | H37: 7 | M37: =G37+I37+K37 -> 0 | N37: =(M37*100)/$P$8 -> 0 | O37: =H37+J37+L37 -> 7 | P37: =IF(AVERAGE(H37,J37,L37)<6,(5),(ROUND(AVERAGE(H37,J37,L37),0))) -> 7 | R37: =IF(N37>20,"EXTRA","ORD") -> ORD
A38: 27 | C38: HERNANDEZ | D38: VARGAS | E38: MOISES | G38: 0 | H38: 7 | M38: =G38+I38+K38 -> 0 | N38: =(M38*100)/$P$8 -> 0 | O38: =H38+J38+L38 -> 7 | P38: =IF(AVERAGE(H38,J38,L38)<6,(5),(ROUND(AVERAGE(H38,J38,L38),0))) -> 7 | R38: =IF(N38>20,"EXTRA","ORD") -> ORD
B39: 28 | C39: HERNANDEZ | D39: VIVEROS | E39: SAMANTHA SHARON | G39: 0 | H39: 8 | M39: =G39+I39+K39 -> 0 | N39: =(M39*100)/$P$8 -> 0 | O39: =H39+J39+L39 -> 8 | P39: =IF(AVERAGE(H39,J39,L39)<6,(5),(ROUND(AVERAGE(H39,J39,L39),0))) -> 8 | R39: =IF(N39>20,"EXTRA","ORD") -> ORD
B40: 29 | C40: ISLAS | D40: GARCIA | E40: MARIANA | G40: 0 | H40: 5 | M40: =G40+I40+K40 -> 0 | N40: =(M40*100)/$P$8 -> 0 | O40: =H40+J40+L40 -> 5 | P40: =IF(AVERAGE(H40,J40,L40)<6,(5),(ROUND(AVERAGE(H40,J40,L40),0))) -> 5 | R40: =IF(N40>20,"EXTRA","ORD") -> ORD
...

Sheet 1-1 cultura digital ii
O1: HORAS IMPARTIDAS
C2: ORIENTADOR | D2: JOSE EDGAR SALAZAR ZUÑIGA | H2: ESCUELA PREPARATORIA OFICIAL NÚM.67 | O2: Febrero
H3: “2026. Año del Humanismo Mexicano en el Estado de México ”. | O3: Marzo
H4: CICLO ESCOLAR: 2025 -2026 | O4: Abril
E5: TURNO : | G5: MATUTINO | J5: Grado | K5: 1° | L5: Grupo | M5: 1 | O5: Mayo | P5: 15
E6: PROFESOR(A): | K6: UAC | L6: CULTURA DIGITAL II | O6: Junio
G7: HOMBRES | H7: =A67 -> 28 | O7: Julio
G8: MUJERES | H8: =B67 -> 25 | O8: TOTAL | P8: =SUM(P2:P7) -> 15
G9: TOTAL | H9: =H7+H8 -> 53
A10: N | B10: P | C10: NOMBRE DEL ALUMNO | G10: PRIMERA EVALUACIÓN | I10: SEGUNDA EVALUACIÓN | K10: TERCERA EVALUACIÓN | M10: EVALUACIÓN FINAL
A11: H | B11: M | G11: FALTAS | H11: CALIF. | I11: FALTAS | J11: CALIF. | K11: FALTAS | L11: CALIF. | M11: TOT. DE FALTAS | N11: % FALTAS | O11: TOTAL DE PUNTOS | P11: CALIF. FINAL | Q11: FIRMA DEL ALUMNO | R11: ESTATUS
B12: 1 | C12: ALVAREZ | D12: HERNANDEZ | E12: DAYANNA ZOE | G12: 0 | H12: 7 | M12: =G12+I12+K12 -> 0 | N12: =(M12*100)/$P$8 -> 0 | O12: =H12+J12+L12 -> 7 | P12: =IF(AVERAGE(H12,J12,L12)<6,(5),(ROUND(AVERAGE(H12,J12,L12),0))) -> 7 | R12: =IF(N12>20,"EXTRA","ORD") -> ORD
B13: 2 | C13: ANAYA | D13: LEAL | E13: ANA IXCHEL | G13: 0 | H13: 10 | M13: =G13+I13+K13 -> 0 | N13: =(M13*100)/$P$8 -> 0 | O13: =H13+J13+L13 -> 10 | P13: =IF(AVERAGE(H13,J13,L13)<6,(5),(ROUND(AVERAGE(H13,J13,L13),0))) -> 10 | R13: =IF(N13>20,"EXTRA","ORD") -> ORD
B14: 3 | C14: ARIAS | D14: APARICIO | E14: AILISH ELIZABETH | G14: 0 | H14: 10 | M14: =G14+I14+K14 -> 0 | N14: =(M14*100)/$P$8 -> 0 | O14: =H14+J14+L14 -> 10 | P14: =IF(AVERAGE(H14,J14,L14)<6,(5),(ROUND(AVERAGE(H14,J14,L14),0))) -> 10 | R14: =IF(N14>20,"EXTRA","ORD") -> ORD
A15: 4 | C15: ARRAZOLA | D15: ROMERO | E15: DIEGO IVAN | G15: 0 | H15: 6 | M15: =G15+I15+K15 -> 0 | N15: =(M15*100)/$P$8 -> 0 | O15: =H15+J15+L15 -> 6 | P15: =IF(AVERAGE(H15,J15,L15)<6,(5),(ROUND(AVERAGE(H15,J15,L15),0))) -> 6 | R15: =IF(N15>20,"EXTRA","ORD") -> ORD
A16: 5 | C16: ARREDONDO | D16: LOREDO | E16: JOSHUA JAAFET | G16: 0 | H16: 8 | M16: =G16+I16+K16 -> 0 | N16: =(M16*100)/$P$8 -> 0 | O16: =H16+J16+L16 -> 8 | P16: =IF(AVERAGE(H16,J16,L16)<6,(5),(ROUND(AVERAGE(H16,J16,L16),0))) -> 8 | R16: =IF(N16>20,"EXTRA","ORD") -> ORD
B17: 6 | C17: AVILES | D17: ACOSTA | E17: ARELI | G17: 0 | H17: 8 | M17: =G17+I17+K17 -> 0 | N17: =(M17*100)/$P$8 -> 0 | O17: =H17+J17+L17 -> 8 | P17: =IF(AVERAGE(H17,J17,L17)<6,(5),(ROUND(AVERAGE(H17,J17,L17),0))) -> 8 | R17: =IF(N17>20,"EXTRA","ORD") -> ORD
A18: 7 | C18: CARBAJAL | D18: RODRIGUEZ | E18: GAEL | G18: 0 | H18: 8 | M18: =G18+I18+K18 -> 0 | N18: =(M18*100)/$P$8 -> 0 | O18: =H18+J18+L18 -> 8 | P18: =IF(AVERAGE(H18,J18,L18)<6,(5),(ROUND(AVERAGE(H18,J18,L18),0))) -> 8 | R18: =IF(N18>20,"EXTRA","ORD") -> ORD
A19: 8 | C19: CARDENAS | D19: MORENO | E19: CRISTOPHER TADEO | G19: 0 | H19: 10 | M19: =G19+I19+K19 -> 0 | N19: =(M19*100)/$P$8 -> 0 | O19: =H19+J19+L19 -> 10 | P19: =IF(AVERAGE(H19,J19,L19)<6,(5),(ROUND(AVERAGE(H19,J19,L19),0))) -> 10 | R19: =IF(N19>20,"EXTRA","ORD") -> ORD
B20: 9 | C20: CASTILLO | D20: HERNANDEZ | E20: XUNELLY | G20: 0 | H20: 5 | M20: =G20+I20+K20 -> 0 | N20: =(M20*100)/$P$8 -> 0 | O20: =H20+J20+L20 -> 5 | P20: =IF(AVERAGE(H20,J20,L20)<6,(5),(ROUND(AVERAGE(H20,J20,L20),0))) -> 5 | R20: =IF(N20>20,"EXTRA","ORD") -> ORD
B21: 10 | C21: CEREZO | D21: MORALES | E21: LOURDES YURYCO | G21: 0 | H21: 10 | M21: =G21+I21+K21 -> 0 | N21: =(M21*100)/$P$8 -> 0 | O21: =H21+J21+L21 -> 10 | P21: =IF(AVERAGE(H21,J21,L21)<6,(5),(ROUND(AVERAGE(H21,J21,L21),0))) -> 10 | R21: =IF(N21>20,"EXTRA","ORD") -> ORD
A22: 11 | C22: CONTRERAS | D22: QUIÑONES | E22: OLIVER | G22: 0 | H22: 8 | M22: =G22+I22+K22 -> 0 | N22: =(M22*100)/$P$8 -> 0 | O22: =H22+J22+L22 -> 8 | P22: =IF(AVERAGE(H22,J22,L22)<6,(5),(ROUND(AVERAGE(H22,J22,L22),0))) -> 8 | R22: =IF(N22>20,"EXTRA","ORD") -> ORD
B23: 12 | C23: CRUZ | D23: CENTENO | E23: ALEXA ABIGAIL | G23: 0 | H23: 6 | M23: =G23+I23+K23 -> 0 | N23: =(M23*100)/$P$8 -> 0 | O23: =H23+J23+L23 -> 6 | P23: =IF(AVERAGE(H23,J23,L23)<6,(5),(ROUND(AVERAGE(H23,J23,L23),0))) -> 6 | R23: =IF(N23>20,"EXTRA","ORD") -> ORD
A24: 13 | C24: CRUZ | D24: PAZ | E24: CARLOS ALFONSO | G24: 0 | H24: 5 | M24: =G24+I24+K24 -> 0 | N24: =(M24*100)/$P$8 -> 0 | O24: =H24+J24+L24 -> 5 | P24: =IF(AVERAGE(H24,J24,L24)<6,(5),(ROUND(AVERAGE(H24,J24,L24),0))) -> 5 | R24: =IF(N24>20,"EXTRA","ORD") -> ORD
B25: 14 | C25: DIAZ | D25: MOLINA | E25: EMILIANA ALESSANDRA | G25: 0 | H25: 10 | M25: =G25+I25+K25 -> 0 | N25: =(M25*100)/$P$8 -> 0 | O25: =H25+J25+L25 -> 10 | P25: =IF(AVERAGE(H25,J25,L25)<6,(5),(ROUND(AVERAGE(H25,J25,L25),0))) -> 10 | R25: =IF(N25>20,"EXTRA","ORD") -> ORD
A26: 15 | C26: DUARTE | D26: ADJUNTAS | E26: RICARDO JESUS | G26: 0 | H26: 10 | M26: =G26+I26+K26 -> 0 | N26: =(M26*100)/$P$8 -> 0 | O26: =H26+J26+L26 -> 10 | P26: =IF(AVERAGE(H26,J26,L26)<6,(5),(ROUND(AVERAGE(H26,J26,L26),0))) -> 10 | R26: =IF(N26>20,"EXTRA","ORD") -> ORD
A27: 16 | C27: ESTRADA | D27: VENEGAS | E27: DAVID RICARDO | G27: 0 | H27: 5 | M27: =G27+I27+K27 -> 0 | N27: =(M27*100)/$P$8 -> 0 | O27: =H27+J27+L27 -> 5 | P27: =IF(AVERAGE(H27,J27,L27)<6,(5),(ROUND(AVERAGE(H27,J27,L27),0))) -> 5 | R27: =IF(N27>20,"EXTRA","ORD") -> ORD
B28: 17 | C28: FLORES | D28: VARGAS | E28: FERNANDA DESSIRE | G28: 0 | H28: 7 | M28: =G28+I28+K28 -> 0 | N28: =(M28*100)/$P$8 -> 0 | O28: =H28+J28+L28 -> 7 | P28: =IF(AVERAGE(H28,J28,L28)<6,(5),(ROUND(AVERAGE(H28,J28,L28),0))) -> 7 | R28: =IF(N28>20,"EXTRA","ORD") -> ORD
A29: 18 | C29: FUENTES | D29: HERNANDEZ | E29: DIEGO ISRAEL | G29: 0 | H29: 6 | M29: =G29+I29+K29 -> 0 | N29: =(M29*100)/$P$8 -> 0 | O29: =H29+J29+L29 -> 6 | P29: =IF(AVERAGE(H29,J29,L29)<6,(5),(ROUND(AVERAGE(H29,J29,L29),0))) -> 6 | R29: =IF(N29>20,"EXTRA","ORD") -> ORD
B30: 19 | C30: GALINDO | D30: CRUZ | E30: LUISA VALENTINA | G30: 1 | H30: 6 | M30: =G30+I30+K30 -> 1 | N30: =(M30*100)/$P$8 -> 6.6666667 | O30: =H30+J30+L30 -> 6 | P30: =IF(AVERAGE(H30,J30,L30)<6,(5),(ROUND(AVERAGE(H30,J30,L30),0))) -> 6 | R30: =IF(N30>20,"EXTRA","ORD") -> ORD
B31: 20 | C31: GARCIA | D31: ARELLANO | E31: YULIANA REBECA | G31: 0 | H31: 10 | M31: =G31+I31+K31 -> 0 | N31: =(M31*100)/$P$8 -> 0 | O31: =H31+J31+L31 -> 10 | P31: =IF(AVERAGE(H31,J31,L31)<6,(5),(ROUND(AVERAGE(H31,J31,L31),0))) -> 10 | R31: =IF(N31>20,"EXTRA","ORD") -> ORD
A32: 21 | C32: GARCIA | D32: PEÑA | E32: ANDREI | G32: 0 | H32: 9 | M32: =G32+I32+K32 -> 0 | N32: =(M32*100)/$P$8 -> 0 | O32: =H32+J32+L32 -> 9 | P32: =IF(AVERAGE(H32,J32,L32)<6,(5),(ROUND(AVERAGE(H32,J32,L32),0))) -> 9 | R32: =IF(N32>20,"EXTRA","ORD") -> ORD
A33: 22 | C33: GARCILAZO | D33: MARTINEZ | E33: ALFONSO | G33: 0 | H33: 6 | M33: =G33+I33+K33 -> 0 | N33: =(M33*100)/$P$8 -> 0 | O33: =H33+J33+L33 -> 6 | P33: =IF(AVERAGE(H33,J33,L33)<6,(5),(ROUND(AVERAGE(H33,J33,L33),0))) -> 6 | R33: =IF(N33>20,"EXTRA","ORD") -> ORD
A34: 23 | C34: GODOY | D34: MARQUEZ | E34: DUSTIN YALIL | G34: 1 | H34: 5 | M34: =G34+I34+K34 -> 1 | N34: =(M34*100)/$P$8 -> 6.6666667 | O34: =H34+J34+L34 -> 5 | P34: =IF(AVERAGE(H34,J34,L34)<6,(5),(ROUND(AVERAGE(H34,J34,L34),0))) -> 5 | R34: =IF(N34>20,"EXTRA","ORD") -> ORD
B35: 24 | C35: GONZALEZ | D35: RAMOS | E35: FATIMA NAOMY | G35: 2 | H35: 7 | M35: =G35+I35+K35 -> 2 | N35: =(M35*100)/$P$8 -> 13.333333 | O35: =H35+J35+L35 -> 7 | P35: =IF(AVERAGE(H35,J35,L35)<6,(5),(ROUND(AVERAGE(H35,J35,L35),0))) -> 7 | R35: =IF(N35>20,"EXTRA","ORD") -> ORD
B36: 25 | C36: GUERRERO | D36: ORTIZ | E36: VALERIA ROMINA | G36: 0 | H36: 7 | M36: =G36+I36+K36 -> 0 | N36: =(M36*100)/$P$8 -> 0 | O36: =H36+J36+L36 -> 7 | P36: =IF(AVERAGE(H36,J36,L36)<6,(5),(ROUND(AVERAGE(H36,J36,L36),0))) -> 7 | R36: =IF(N36>20,"EXTRA","ORD") -> ORD
B37: 26 | C37: GUTIERREZ | D37: ANGELES | E37: SAMANTHA PAOLA | G37: 0 | H37: 7 | M37: =G37+I37+K37 -> 0 | N37: =(M37*100)/$P$8 -> 0 | O37: =H37+J37+L37 -> 7 | P37: =IF(AVERAGE(H37,J37,L37)<6,(5),(ROUND(AVERAGE(H37,J37,L37),0))) -> 7 | R37: =IF(N37>20,"EXTRA","ORD") -> ORD
A38: 27 | C38: HERNANDEZ | D38: VARGAS | E38: MOISES | G38: 0 | H38: 7 | M38: =G38+I38+K38 -> 0 | N38: =(M38*100)/$P$8 -> 0 | O38: =H38+J38+L38 -> 7 | P38: =IF(AVERAGE(H38,J38,L38)<6,(5),(ROUND(AVERAGE(H38,J38,L38),0))) -> 7 | R38: =IF(N38>20,"EXTRA","ORD") -> ORD
B39: 28 | C39: HERNANDEZ | D39: VIVEROS | E39: SAMANTHA SHARON | G39: 0 | H39: 8 | M39: =G39+I39+K39 -> 0 | N39: =(M39*100)/$P$8 -> 0 | O39: =H39+J39+L39 -> 8 | P39: =IF(AVERAGE(H39,J39,L39)<6,(5),(ROUND(AVERAGE(H39,J39,L39),0))) -> 8 | R39: =IF(N39>20,"EXTRA","ORD") -> ORD
B40: 29 | C40: ISLAS | D40: GARCIA | E40: MARIANA | G40: 0 | H40: 8 | M40: =G40+I40+K40 -> 0 | N40: =(M40*100)/$P$8 -> 0 | O40: =H40+J40+L40 -> 8 | P40: =IF(AVERAGE(H40,J40,L40)<6,(5),(ROUND(AVERAGE(H40,J40,L40),0))) -> 8 | R40: =IF(N40>20,"EXTRA","ORD") -> ORD
...

Sheet 1-1 ciencias naturales experime
O1: HORAS IMPARTIDAS
C2: ORIENTADOR | D2: JOSE EDGAR SALAZAR ZUÑIGA | H2: ESCUELA PREPARATORIA OFICIAL NÚM.67 | O2: Febrero
H3: “2026. Año del Humanismo Mexicano en el Estado de México ”. | O3: Marzo
H4: CICLO ESCOLAR: 2025 -2026 | O4: Abril
E5: TURNO : | G5: MATUTINO | J5: Grado | K5: 1° | L5: Grupo | M5: 1 | O5: Mayo | P5: 9
E6: PROFESOR(A): | K6: UAC | L6: CIENCIAS NATURALES, EXPERIMENTALES Y TECNOLOGÍA II | O6: Junio
G7: HOMBRES | H7: =A67 -> 28 | O7: Julio
G8: MUJERES | H8: =B67 -> 25 | O8: TOTAL | P8: =SUM(P2:P7) -> 9
G9: TOTAL | H9: =H7+H8 -> 53
A10: N | B10: P | C10: NOMBRE DEL ALUMNO | G10: PRIMERA EVALUACIÓN | I10: SEGUNDA EVALUACIÓN | K10: TERCERA EVALUACIÓN | M10: EVALUACIÓN FINAL
A11: H | B11: M | G11: FALTAS | H11: CALIF. | I11: FALTAS | J11: CALIF. | K11: FALTAS | L11: CALIF. | M11: TOT. DE FALTAS | N11: % FALTAS | O11: TOTAL DE PUNTOS | P11: CALIF. FINAL | Q11: FIRMA DEL ALUMNO
B12: 1 | C12: ALVAREZ | D12: HERNANDEZ | E12: DAYANNA ZOE | G12: 0 | H12: 7 | M12: =G12+I12+K12 -> 0 | N12: =(M12*100)/$P$8 -> 0 | O12: =H12+J12+L12 -> 7 | P12: =IF(AVERAGE(H12,J12,L12)<6,(5),(ROUND(AVERAGE(H12,J12,L12),0))) -> 7 | R12: =IF(N12>20,"EXTRA","ORD") -> ORD
B13: 2 | C13: ANAYA | D13: LEAL | E13: ANA IXCHEL | G13: 0 | H13: 10 | M13: =G13+I13+K13 -> 0 | N13: =(M13*100)/$P$8 -> 0 | O13: =H13+J13+L13 -> 10 | P13: =IF(AVERAGE(H13,J13,L13)<6,(5),(ROUND(AVERAGE(H13,J13,L13),0))) -> 10 | R13: =IF(N13>20,"EXTRA","ORD") -> ORD
B14: 3 | C14: ARIAS | D14: APARICIO | E14: AILISH ELIZABETH | G14: 0 | H14: 10 | M14: =G14+I14+K14 -> 0 | N14: =(M14*100)/$P$8 -> 0 | O14: =H14+J14+L14 -> 10 | P14: =IF(AVERAGE(H14,J14,L14)<6,(5),(ROUND(AVERAGE(H14,J14,L14),0))) -> 10 | R14: =IF(N14>20,"EXTRA","ORD") -> ORD
A15: 4 | C15: ARRAZOLA | D15: ROMERO | E15: DIEGO IVAN | G15: 0 | H15: 6 | M15: =G15+I15+K15 -> 0 | N15: =(M15*100)/$P$8 -> 0 | O15: =H15+J15+L15 -> 6 | P15: =IF(AVERAGE(H15,J15,L15)<6,(5),(ROUND(AVERAGE(H15,J15,L15),0))) -> 6 | R15: =IF(N15>20,"EXTRA","ORD") -> ORD
A16: 5 | C16: ARREDONDO | D16: LOREDO | E16: JOSHUA JAAFET | G16: 0 | H16: 8 | M16: =G16+I16+K16 -> 0 | N16: =(M16*100)/$P$8 -> 0 | O16: =H16+J16+L16 -> 8 | P16: =IF(AVERAGE(H16,J16,L16)<6,(5),(ROUND(AVERAGE(H16,J16,L16),0))) -> 8 | R16: =IF(N16>20,"EXTRA","ORD") -> ORD
B17: 6 | C17: AVILES | D17: ACOSTA | E17: ARELI | G17: 0 | H17: 8 | M17: =G17+I17+K17 -> 0 | N17: =(M17*100)/$P$8 -> 0 | O17: =H17+J17+L17 -> 8 | P17: =IF(AVERAGE(H17,J17,L17)<6,(5),(ROUND(AVERAGE(H17,J17,L17),0))) -> 8 | R17: =IF(N17>20,"EXTRA","ORD") -> ORD
A18: 7 | C18: CARBAJAL | D18: RODRIGUEZ | E18: GAEL | G18: 0 | H18: 8 | M18: =G18+I18+K18 -> 0 | N18: =(M18*100)/$P$8 -> 0 | O18: =H18+J18+L18 -> 8 | P18: =IF(AVERAGE(H18,J18,L18)<6,(5),(ROUND(AVERAGE(H18,J18,L18),0))) -> 8 | R18: =IF(N18>20,"EXTRA","ORD") -> ORD
A19: 8 | C19: CARDENAS | D19: MORENO | E19: CRISTOPHER TADEO | G19: 0 | H19: 10 | M19: =G19+I19+K19 -> 0 | N19: =(M19*100)/$P$8 -> 0 | O19: =H19+J19+L19 -> 10 | P19: =IF(AVERAGE(H19,J19,L19)<6,(5),(ROUND(AVERAGE(H19,J19,L19),0))) -> 10 | R19: =IF(N19>20,"EXTRA","ORD") -> ORD
B20: 9 | C20: CASTILLO | D20: HERNANDEZ | E20: XUNELLY | G20: 0 | H20: 5 | M20: =G20+I20+K20 -> 0 | N20: =(M20*100)/$P$8 -> 0 | O20: =H20+J20+L20 -> 5 | P20: =IF(AVERAGE(H20,J20,L20)<6,(5),(ROUND(AVERAGE(H20,J20,L20),0))) -> 5 | R20: =IF(N20>20,"EXTRA","ORD") -> ORD
B21: 10 | C21: CEREZO | D21: MORALES | E21: LOURDES YURYCO | G21: 0 | H21: 10 | M21: =G21+I21+K21 -> 0 | N21: =(M21*100)/$P$8 -> 0 | O21: =H21+J21+L21 -> 10 | P21: =IF(AVERAGE(H21,J21,L21)<6,(5),(ROUND(AVERAGE(H21,J21,L21),0))) -> 10 | R21: =IF(N21>20,"EXTRA","ORD") -> ORD
A22: 11 | C22: CONTRERAS | D22: QUIÑONES | E22: OLIVER | G22: 0 | H22: 8 | M22: =G22+I22+K22 -> 0 | N22: =(M22*100)/$P$8 -> 0 | O22: =H22+J22+L22 -> 8 | P22: =IF(AVERAGE(H22,J22,L22)<6,(5),(ROUND(AVERAGE(H22,J22,L22),0))) -> 8 | R22: =IF(N22>20,"EXTRA","ORD") -> ORD
B23: 12 | C23: CRUZ | D23: CENTENO | E23: ALEXA ABIGAIL | G23: 0 | H23: 6 | M23: =G23+I23+K23 -> 0 | N23: =(M23*100)/$P$8 -> 0 | O23: =H23+J23+L23 -> 6 | P23: =IF(AVERAGE(H23,J23,L23)<6,(5),(ROUND(AVERAGE(H23,J23,L23),0))) -> 6 | R23: =IF(N23>20,"EXTRA","ORD") -> ORD
A24: 13 | C24: CRUZ | D24: PAZ | E24: CARLOS ALFONSO | G24: 0 | H24: 5 | M24: =G24+I24+K24 -> 0 | N24: =(M24*100)/$P$8 -> 0 | O24: =H24+J24+L24 -> 5 | P24: =IF(AVERAGE(H24,J24,L24)<6,(5),(ROUND(AVERAGE(H24,J24,L24),0))) -> 5 | R24: =IF(N24>20,"EXTRA","ORD") -> ORD
B25: 14 | C25: DIAZ | D25: MOLINA | E25: EMILIANA ALESSANDRA | G25: 0 | H25: 10 | M25: =G25+I25+K25 -> 0 | N25: =(M25*100)/$P$8 -> 0 | O25: =H25+J25+L25 -> 10 | P25: =IF(AVERAGE(H25,J25,L25)<6,(5),(ROUND(AVERAGE(H25,J25,L25),0))) -> 10 | R25: =IF(N25>20,"EXTRA","ORD") -> ORD
A26: 15 | C26: DUARTE | D26: ADJUNTAS | E26: RICARDO JESUS | G26: 0 | H26: 10 | M26: =G26+I26+K26 -> 0 | N26: =(M26*100)/$P$8 -> 0 | O26: =H26+J26+L26 -> 10 | P26: =IF(AVERAGE(H26,J26,L26)<6,(5),(ROUND(AVERAGE(H26,J26,L26),0))) -> 10 | R26: =IF(N26>20,"EXTRA","ORD") -> ORD
A27: 16 | C27: ESTRADA | D27: VENEGAS | E27: DAVID RICARDO | G27: 0 | H27: 5 | M27: =G27+I27+K27 -> 0 | N27: =(M27*100)/$P$8 -> 0 | O27: =H27+J27+L27 -> 5 | P27: =IF(AVERAGE(H27,J27,L27)<6,(5),(ROUND(AVERAGE(H27,J27,L27),0))) -> 5 | R27: =IF(N27>20,"EXTRA","ORD") -> ORD
B28: 17 | C28: FLORES | D28: VARGAS | E28: FERNANDA DESSIRE | G28: 0 | H28: 7 | M28: =G28+I28+K28 -> 0 | N28: =(M28*100)/$P$8 -> 0 | O28: =H28+J28+L28 -> 7 | P28: =IF(AVERAGE(H28,J28,L28)<6,(5),(ROUND(AVERAGE(H28,J28,L28),0))) -> 7 | R28: =IF(N28>20,"EXTRA","ORD") -> ORD
A29: 18 | C29: FUENTES | D29: HERNANDEZ | E29: DIEGO ISRAEL | G29: 0 | H29: 6 | M29: =G29+I29+K29 -> 0 | N29: =(M29*100)/$P$8 -> 0 | O29: =H29+J29+L29 -> 6 | P29: =IF(AVERAGE(H29,J29,L29)<6,(5),(ROUND(AVERAGE(H29,J29,L29),0))) -> 6 | R29: =IF(N29>20,"EXTRA","ORD") -> ORD
B30: 19 | C30: GALINDO | D30: CRUZ | E30: LUISA VALENTINA | G30: 1 | H30: 6 | M30: =G30+I30+K30 -> 1 | N30: =(M30*100)/$P$8 -> 11.111111 | O30: =H30+J30+L30 -> 6 | P30: =IF(AVERAGE(H30,J30,L30)<6,(5),(ROUND(AVERAGE(H30,J30,L30),0))) -> 6 | R30: =IF(N30>20,"EXTRA","ORD") -> ORD
B31: 20 | C31: GARCIA | D31: ARELLANO | E31: YULIANA REBECA | G31: 0 | H31: 10 | M31: =G31+I31+K31 -> 0 | N31: =(M31*100)/$P$8 -> 0 | O31: =H31+J31+L31 -> 10 | P31: =IF(AVERAGE(H31,J31,L31)<6,(5),(ROUND(AVERAGE(H31,J31,L31),0))) -> 10 | R31: =IF(N31>20,"EXTRA","ORD") -> ORD
A32: 21 | C32: GARCIA | D32: PEÑA | E32: ANDREI | G32: 0 | H32: 9 | M32: =G32+I32+K32 -> 0 | N32: =(M32*100)/$P$8 -> 0 | O32: =H32+J32+L32 -> 9 | P32: =IF(AVERAGE(H32,J32,L32)<6,(5),(ROUND(AVERAGE(H32,J32,L32),0))) -> 9 | R32: =IF(N32>20,"EXTRA","ORD") -> ORD
A33: 22 | C33: GARCILAZO | D33: MARTINEZ | E33: ALFONSO | G33: 0 | H33: 6 | M33: =G33+I33+K33 -> 0 | N33: =(M33*100)/$P$8 -> 0 | O33: =H33+J33+L33 -> 6 | P33: =IF(AVERAGE(H33,J33,L33)<6,(5),(ROUND(AVERAGE(H33,J33,L33),0))) -> 6 | R33: =IF(N33>20,"EXTRA","ORD") -> ORD
A34: 23 | C34: GODOY | D34: MARQUEZ | E34: DUSTIN YALIL | G34: 1 | H34: 5 | M34: =G34+I34+K34 -> 1 | N34: =(M34*100)/$P$8 -> 11.111111 | O34: =H34+J34+L34 -> 5 | P34: =IF(AVERAGE(H34,J34,L34)<6,(5),(ROUND(AVERAGE(H34,J34,L34),0))) -> 5 | R34: =IF(N34>20,"EXTRA","ORD") -> ORD
B35: 24 | C35: GONZALEZ | D35: RAMOS | E35: FATIMA NAOMY | G35: 2 | H35: 7 | M35: =G35+I35+K35 -> 2 | N35: =(M35*100)/$P$8 -> 22.222222 | O35: =H35+J35+L35 -> 7 | P35: =IF(AVERAGE(H35,J35,L35)<6,(5),(ROUND(AVERAGE(H35,J35,L35),0))) -> 7 | R35: =IF(N35>20,"EXTRA","ORD") -> EXTRA
B36: 25 | C36: GUERRERO | D36: ORTIZ | E36: VALERIA ROMINA | G36: 0 | H36: 7 | M36: =G36+I36+K36 -> 0 | N36: =(M36*100)/$P$8 -> 0 | O36: =H36+J36+L36 -> 7 | P36: =IF(AVERAGE(H36,J36,L36)<6,(5),(ROUND(AVERAGE(H36,J36,L36),0))) -> 7 | R36: =IF(N36>20,"EXTRA","ORD") -> ORD
B37: 26 | C37: GUTIERREZ | D37: ANGELES | E37: SAMANTHA PAOLA | G37: 0 | H37: 7 | M37: =G37+I37+K37 -> 0 | N37: =(M37*100)/$P$8 -> 0 | O37: =H37+J37+L37 -> 7 | P37: =IF(AVERAGE(H37,J37,L37)<6,(5),(ROUND(AVERAGE(H37,J37,L37),0))) -> 7 | R37: =IF(N37>20,"EXTRA","ORD") -> ORD
A38: 27 | C38: HERNANDEZ | D38: VARGAS | E38: MOISES | G38: 0 | H38: 7 | M38: =G38+I38+K38 -> 0 | N38: =(M38*100)/$P$8 -> 0 | O38: =H38+J38+L38 -> 7 | P38: =IF(AVERAGE(H38,J38,L38)<6,(5),(ROUND(AVERAGE(H38,J38,L38),0))) -> 7 | R38: =IF(N38>20,"EXTRA","ORD") -> ORD
B39: 28 | C39: HERNANDEZ | D39: VIVEROS | E39: SAMANTHA SHARON | G39: 0 | H39: 8 | M39: =G39+I39+K39 -> 0 | N39: =(M39*100)/$P$8 -> 0 | O39: =H39+J39+L39 -> 8 | P39: =IF(AVERAGE(H39,J39,L39)<6,(5),(ROUND(AVERAGE(H39,J39,L39),0))) -> 8 | R39: =IF(N39>20,"EXTRA","ORD") -> ORD
B40: 29 | C40: ISLAS | D40: GARCIA | E40: MARIANA | G40: 0 | H40: 8 | M40: =G40+I40+K40 -> 0 | N40: =(M40*100)/$P$8 -> 0 | O40: =H40+J40+L40 -> 8 | P40: =IF(AVERAGE(H40,J40,L40)<6,(5),(ROUND(AVERAGE(H40,J40,L40),0))) -> 8 | R40: =IF(N40>20,"EXTRA","ORD") -> ORD
...

Sheet 1-1 pensamiento filosofico y hu
O1: HORAS IMPARTIDAS
C2: ORIENTADOR | D2: JOSE EDGAR SALAZAR ZUÑIGA | H2: ESCUELA PREPARATORIA OFICIAL NÚM.67 | O2: Febrero
H3: “2026. Año del Humanismo Mexicano en el Estado de México ”. | O3: Marzo | P3: 12
H4: CICLO ESCOLAR: 2025 -2026 | O4: Abril
E5: TURNO : | G5: MATUTINO | J5: Grado | K5: 1° | L5: Grupo | M5: 1 | O5: Mayo
E6: PROFESOR(A): | K6: UAC | L6: PENSAMIENTO FILOSÓFICO Y HUMANIDADES II | O6: Junio
G7: HOMBRES | H7: =A67 -> 28 | O7: Julio
G8: MUJERES | H8: =B67 -> 25 | O8: TOTAL | P8: =SUM(P2:P7) -> 12
G9: TOTAL | H9: =H7+H8 -> 53
A10: N | B10: P | C10: NOMBRE DEL ALUMNO | G10: PRIMERA EVALUACIÓN | I10: SEGUNDA EVALUACIÓN | K10: TERCERA EVALUACIÓN | M10: EVALUACIÓN FINAL
A11: H | B11: M | G11: FALTAS | H11: CALIF. | I11: FALTAS | J11: CALIF. | K11: FALTAS | L11: CALIF. | M11: TOT. DE FALTAS | N11: % FALTAS | O11: TOTAL DE PUNTOS | P11: CALIF. FINAL | Q11: FIRMA DEL ALUMNO | R11: ESTATUS
B12: 1 | C12: ALVAREZ | D12: HERNANDEZ | E12: DAYANNA ZOE | G12: 0 | H12: 7 | M12: =G12+I12+K12 -> 0 | N12: =(M12*100)/$P$8 -> 0 | O12: =H12+J12+L12 -> 7 | P12: =IF(AVERAGE(H12,J12,L12)<6,(5),(ROUND(AVERAGE(H12,J12,L12),0))) -> 7 | R12: =IF(N12>20,"EXTRA","ORD") -> ORD
B13: 2 | C13: ANAYA | D13: LEAL | E13: ANA IXCHEL | G13: 0 | H13: 10 | M13: =G13+I13+K13 -> 0 | N13: =(M13*100)/$P$8 -> 0 | O13: =H13+J13+L13 -> 10 | P13: =IF(AVERAGE(H13,J13,L13)<6,(5),(ROUND(AVERAGE(H13,J13,L13),0))) -> 10 | R13: =IF(N13>20,"EXTRA","ORD") -> ORD
B14: 3 | C14: ARIAS | D14: APARICIO | E14: AILISH ELIZABETH | G14: 0 | H14: 10 | M14: =G14+I14+K14 -> 0 | N14: =(M14*100)/$P$8 -> 0 | O14: =H14+J14+L14 -> 10 | P14: =IF(AVERAGE(H14,J14,L14)<6,(5),(ROUND(AVERAGE(H14,J14,L14),0))) -> 10 | R14: =IF(N14>20,"EXTRA","ORD") -> ORD
A15: 4 | C15: ARRAZOLA | D15: ROMERO | E15: DIEGO IVAN | G15: 0 | H15: 6 | M15: =G15+I15+K15 -> 0 | N15: =(M15*100)/$P$8 -> 0 | O15: =H15+J15+L15 -> 6 | P15: =IF(AVERAGE(H15,J15,L15)<6,(5),(ROUND(AVERAGE(H15,J15,L15),0))) -> 6 | R15: =IF(N15>20,"EXTRA","ORD") -> ORD
A16: 5 | C16: ARREDONDO | D16: LOREDO | E16: JOSHUA JAAFET | G16: 0 | H16: 8 | M16: =G16+I16+K16 -> 0 | N16: =(M16*100)/$P$8 -> 0 | O16: =H16+J16+L16 -> 8 | P16: =IF(AVERAGE(H16,J16,L16)<6,(5),(ROUND(AVERAGE(H16,J16,L16),0))) -> 8 | R16: =IF(N16>20,"EXTRA","ORD") -> ORD
B17: 6 | C17: AVILES | D17: ACOSTA | E17: ARELI | G17: 0 | H17: 8 | M17: =G17+I17+K17 -> 0 | N17: =(M17*100)/$P$8 -> 0 | O17: =H17+J17+L17 -> 8 | P17: =IF(AVERAGE(H17,J17,L17)<6,(5),(ROUND(AVERAGE(H17,J17,L17),0))) -> 8 | R17: =IF(N17>20,"EXTRA","ORD") -> ORD
A18: 7 | C18: CARBAJAL | D18: RODRIGUEZ | E18: GAEL | G18: 0 | H18: 8 | M18: =G18+I18+K18 -> 0 | N18: =(M18*100)/$P$8 -> 0 | O18: =H18+J18+L18 -> 8 | P18: =IF(AVERAGE(H18,J18,L18)<6,(5),(ROUND(AVERAGE(H18,J18,L18),0))) -> 8 | R18: =IF(N18>20,"EXTRA","ORD") -> ORD
A19: 8 | C19: CARDENAS | D19: MORENO | E19: CRISTOPHER TADEO | G19: 0 | H19: 10 | M19: =G19+I19+K19 -> 0 | N19: =(M19*100)/$P$8 -> 0 | O19: =H19+J19+L19 -> 10 | P19: =IF(AVERAGE(H19,J19,L19)<6,(5),(ROUND(AVERAGE(H19,J19,L19),0))) -> 10 | R19: =IF(N19>20,"EXTRA","ORD") -> ORD
B20: 9 | C20: CASTILLO | D20: HERNANDEZ | E20: XUNELLY | G20: 0 | H20: 5 | M20: =G20+I20+K20 -> 0 | N20: =(M20*100)/$P$8 -> 0 | O20: =H20+J20+L20 -> 5 | P20: =IF(AVERAGE(H20,J20,L20)<6,(5),(ROUND(AVERAGE(H20,J20,L20),0))) -> 5 | R20: =IF(N20>20,"EXTRA","ORD") -> ORD
B21: 10 | C21: CEREZO | D21: MORALES | E21: LOURDES YURYCO | G21: 0 | H21: 10 | M21: =G21+I21+K21 -> 0 | N21: =(M21*100)/$P$8 -> 0 | O21: =H21+J21+L21 -> 10 | P21: =IF(AVERAGE(H21,J21,L21)<6,(5),(ROUND(AVERAGE(H21,J21,L21),0))) -> 10 | R21: =IF(N21>20,"EXTRA","ORD") -> ORD
A22: 11 | C22: CONTRERAS | D22: QUIÑONES | E22: OLIVER | G22: 0 | H22: 8 | M22: =G22+I22+K22 -> 0 | N22: =(M22*100)/$P$8 -> 0 | O22: =H22+J22+L22 -> 8 | P22: =IF(AVERAGE(H22,J22,L22)<6,(5),(ROUND(AVERAGE(H22,J22,L22),0))) -> 8 | R22: =IF(N22>20,"EXTRA","ORD") -> ORD
B23: 12 | C23: CRUZ | D23: CENTENO | E23: ALEXA ABIGAIL | G23: 0 | H23: 6 | M23: =G23+I23+K23 -> 0 | N23: =(M23*100)/$P$8 -> 0 | O23: =H23+J23+L23 -> 6 | P23: =IF(AVERAGE(H23,J23,L23)<6,(5),(ROUND(AVERAGE(H23,J23,L23),0))) -> 6 | R23: =IF(N23>20,"EXTRA","ORD") -> ORD
A24: 13 | C24: CRUZ | D24: PAZ | E24: CARLOS ALFONSO | G24: 0 | H24: 5 | M24: =G24+I24+K24 -> 0 | N24: =(M24*100)/$P$8 -> 0 | O24: =H24+J24+L24 -> 5 | P24: =IF(AVERAGE(H24,J24,L24)<6,(5),(ROUND(AVERAGE(H24,J24,L24),0))) -> 5 | R24: =IF(N24>20,"EXTRA","ORD") -> ORD
B25: 14 | C25: DIAZ | D25: MOLINA | E25: EMILIANA ALESSANDRA | G25: 0 | H25: 10 | M25: =G25+I25+K25 -> 0 | N25: =(M25*100)/$P$8 -> 0 | O25: =H25+J25+L25 -> 10 | P25: =IF(AVERAGE(H25,J25,L25)<6,(5),(ROUND(AVERAGE(H25,J25,L25),0))) -> 10 | R25: =IF(N25>20,"EXTRA","ORD") -> ORD
A26: 15 | C26: DUARTE | D26: ADJUNTAS | E26: RICARDO JESUS | G26: 0 | H26: 10 | M26: =G26+I26+K26 -> 0 | N26: =(M26*100)/$P$8 -> 0 | O26: =H26+J26+L26 -> 10 | P26: =IF(AVERAGE(H26,J26,L26)<6,(5),(ROUND(AVERAGE(H26,J26,L26),0))) -> 10 | R26: =IF(N26>20,"EXTRA","ORD") -> ORD
A27: 16 | C27: ESTRADA | D27: VENEGAS | E27: DAVID RICARDO | G27: 0 | H27: 5 | M27: =G27+I27+K27 -> 0 | N27: =(M27*100)/$P$8 -> 0 | O27: =H27+J27+L27 -> 5 | P27: =IF(AVERAGE(H27,J27,L27)<6,(5),(ROUND(AVERAGE(H27,J27,L27),0))) -> 5 | R27: =IF(N27>20,"EXTRA","ORD") -> ORD
B28: 17 | C28: FLORES | D28: VARGAS | E28: FERNANDA DESSIRE | G28: 0 | H28: 7 | M28: =G28+I28+K28 -> 0 | N28: =(M28*100)/$P$8 -> 0 | O28: =H28+J28+L28 -> 7 | P28: =IF(AVERAGE(H28,J28,L28)<6,(5),(ROUND(AVERAGE(H28,J28,L28),0))) -> 7 | R28: =IF(N28>20,"EXTRA","ORD") -> ORD
A29: 18 | C29: FUENTES | D29: HERNANDEZ | E29: DIEGO ISRAEL | G29: 0 | H29: 6 | M29: =G29+I29+K29 -> 0 | N29: =(M29*100)/$P$8 -> 0 | O29: =H29+J29+L29 -> 6 | P29: =IF(AVERAGE(H29,J29,L29)<6,(5),(ROUND(AVERAGE(H29,J29,L29),0))) -> 6 | R29: =IF(N29>20,"EXTRA","ORD") -> ORD
B30: 19 | C30: GALINDO | D30: CRUZ | E30: LUISA VALENTINA | G30: 1 | H30: 6 | M30: =G30+I30+K30 -> 1 | N30: =(M30*100)/$P$8 -> 8.3333333 | O30: =H30+J30+L30 -> 6 | P30: =IF(AVERAGE(H30,J30,L30)<6,(5),(ROUND(AVERAGE(H30,J30,L30),0))) -> 6 | R30: =IF(N30>20,"EXTRA","ORD") -> ORD
B31: 20 | C31: GARCIA | D31: ARELLANO | E31: YULIANA REBECA | G31: 0 | H31: 10 | M31: =G31+I31+K31 -> 0 | N31: =(M31*100)/$P$8 -> 0 | O31: =H31+J31+L31 -> 10 | P31: =IF(AVERAGE(H31,J31,L31)<6,(5),(ROUND(AVERAGE(H31,J31,L31),0))) -> 10 | R31: =IF(N31>20,"EXTRA","ORD") -> ORD
A32: 21 | C32: GARCIA | D32: PEÑA | E32: ANDREI | G32: 0 | H32: 9 | M32: =G32+I32+K32 -> 0 | N32: =(M32*100)/$P$8 -> 0 | O32: =H32+J32+L32 -> 9 | P32: =IF(AVERAGE(H32,J32,L32)<6,(5),(ROUND(AVERAGE(H32,J32,L32),0))) -> 9 | R32: =IF(N32>20,"EXTRA","ORD") -> ORD
A33: 22 | C33: GARCILAZO | D33: MARTINEZ | E33: ALFONSO | G33: 0 | H33: 6 | M33: =G33+I33+K33 -> 0 | N33: =(M33*100)/$P$8 -> 0 | O33: =H33+J33+L33 -> 6 | P33: =IF(AVERAGE(H33,J33,L33)<6,(5),(ROUND(AVERAGE(H33,J33,L33),0))) -> 6 | R33: =IF(N33>20,"EXTRA","ORD") -> ORD
A34: 23 | C34: GODOY | D34: MARQUEZ | E34: DUSTIN YALIL | G34: 1 | H34: 5 | M34: =G34+I34+K34 -> 1 | N34: =(M34*100)/$P$8 -> 8.3333333 | O34: =H34+J34+L34 -> 5 | P34: =IF(AVERAGE(H34,J34,L34)<6,(5),(ROUND(AVERAGE(H34,J34,L34),0))) -> 5 | R34: =IF(N34>20,"EXTRA","ORD") -> ORD
B35: 24 | C35: GONZALEZ | D35: RAMOS | E35: FATIMA NAOMY | G35: 2 | H35: 7 | M35: =G35+I35+K35 -> 2 | N35: =(M35*100)/$P$8 -> 16.666667 | O35: =H35+J35+L35 -> 7 | P35: =IF(AVERAGE(H35,J35,L35)<6,(5),(ROUND(AVERAGE(H35,J35,L35),0))) -> 7 | R35: =IF(N35>20,"EXTRA","ORD") -> ORD
B36: 25 | C36: GUERRERO | D36: ORTIZ | E36: VALERIA ROMINA | G36: 0 | H36: 7 | M36: =G36+I36+K36 -> 0 | N36: =(M36*100)/$P$8 -> 0 | O36: =H36+J36+L36 -> 7 | P36: =IF(AVERAGE(H36,J36,L36)<6,(5),(ROUND(AVERAGE(H36,J36,L36),0))) -> 7 | R36: =IF(N36>20,"EXTRA","ORD") -> ORD
B37: 26 | C37: GUTIERREZ | D37: ANGELES | E37: SAMANTHA PAOLA | G37: 0 | H37: 7 | M37: =G37+I37+K37 -> 0 | N37: =(M37*100)/$P$8 -> 0 | O37: =H37+J37+L37 -> 7 | P37: =IF(AVERAGE(H37,J37,L37)<6,(5),(ROUND(AVERAGE(H37,J37,L37),0))) -> 7 | R37: =IF(N37>20,"EXTRA","ORD") -> ORD
A38: 27 | C38: HERNANDEZ | D38: VARGAS | E38: MOISES | G38: 0 | H38: 7 | M38: =G38+I38+K38 -> 0 | N38: =(M38*100)/$P$8 -> 0 | O38: =H38+J38+L38 -> 7 | P38: =IF(AVERAGE(H38,J38,L38)<6,(5),(ROUND(AVERAGE(H38,J38,L38),0))) -> 7 | R38: =IF(N38>20,"EXTRA","ORD") -> ORD
B39: 28 | C39: HERNANDEZ | D39: VIVEROS | E39: SAMANTHA SHARON | G39: 0 | H39: 8 | M39: =G39+I39+K39 -> 0 | N39: =(M39*100)/$P$8 -> 0 | O39: =H39+J39+L39 -> 8 | P39: =IF(AVERAGE(H39,J39,L39)<6,(5),(ROUND(AVERAGE(H39,J39,L39),0))) -> 8 | R39: =IF(N39>20,"EXTRA","ORD") -> ORD
B40: 29 | C40: ISLAS | D40: GARCIA | E40: MARIANA | G40: 0 | H40: 8 | M40: =G40+I40+K40 -> 0 | N40: =(M40*100)/$P$8 -> 0 | O40: =H40+J40+L40 -> 8 | P40: =IF(AVERAGE(H40,J40,L40)<6,(5),(ROUND(AVERAGE(H40,J40,L40),0))) -> 8 | R40: =IF(N40>20,"EXTRA","ORD") -> ORD
...

Sheet 1-1 ciencias sociales ii
O1: HORAS IMPARTIDAS
C2: ORIENTADOR | D2: JOSE EDGAR SALAZAR ZUÑIGA | H2: ESCUELA PREPARATORIA OFICIAL NÚM.67 | O2: Febrero
H3: “2026. Año del Humanismo Mexicano en el Estado de México ”. | O3: Marzo | P3: 7
H4: CICLO ESCOLAR: 2025 -2026 | O4: Abril
E5: TURNO : | G5: MATUTINO | J5: Grado | K5: 1° | L5: Grupo | M5: 1 | O5: Mayo
E6: PROFESOR(A): | K6: UAC | L6: CIENCIAS SOCIALES II | O6: Junio
G7: HOMBRES | H7: =A67 -> 28 | O7: Julio
G8: MUJERES | H8: =B67 -> 25 | O8: TOTAL | P8: =SUM(P2:P7) -> 7
G9: TOTAL | H9: =H7+H8 -> 53
A10: N | B10: P | C10: NOMBRE DEL ALUMNO | G10: PRIMERA EVALUACIÓN | I10: SEGUNDA EVALUACIÓN | K10: TERCERA EVALUACIÓN | M10: EVALUACIÓN FINAL
A11: H | B11: M | G11: FALTAS | H11: CALIF. | I11: FALTAS | J11: CALIF. | K11: FALTAS | L11: CALIF. | M11: TOT. DE FALTAS | N11: % FALTAS | O11: TOTAL DE PUNTOS | P11: CALIF. FINAL | Q11: FIRMA DEL ALUMNO | R11: ESTATUS
B12: 1 | C12: ALVAREZ | D12: HERNANDEZ | E12: DAYANNA ZOE | G12: 0 | H12: 7 | M12: =G12+I12+K12 -> 0 | N12: =(M12*100)/$P$8 -> 0 | O12: =H12+J12+L12 -> 7 | P12: =IF(AVERAGE(H12,J12,L12)<6,(5),(ROUND(AVERAGE(H12,J12,L12),0))) -> 7 | R12: =IF(N12>20,"EXTRA","ORD") -> ORD
B13: 2 | C13: ANAYA | D13: LEAL | E13: ANA IXCHEL | G13: 0 | H13: 10 | M13: =G13+I13+K13 -> 0 | N13: =(M13*100)/$P$8 -> 0 | O13: =H13+J13+L13 -> 10 | P13: =IF(AVERAGE(H13,J13,L13)<6,(5),(ROUND(AVERAGE(H13,J13,L13),0))) -> 10 | R13: =IF(N13>20,"EXTRA","ORD") -> ORD
B14: 3 | C14: ARIAS | D14: APARICIO | E14: AILISH ELIZABETH | G14: 0 | H14: 10 | M14: =G14+I14+K14 -> 0 | N14: =(M14*100)/$P$8 -> 0 | O14: =H14+J14+L14 -> 10 | P14: =IF(AVERAGE(H14,J14,L14)<6,(5),(ROUND(AVERAGE(H14,J14,L14),0))) -> 10 | R14: =IF(N14>20,"EXTRA","ORD") -> ORD
A15: 4 | C15: ARRAZOLA | D15: ROMERO | E15: DIEGO IVAN | G15: 0 | H15: 6 | M15: =G15+I15+K15 -> 0 | N15: =(M15*100)/$P$8 -> 0 | O15: =H15+J15+L15 -> 6 | P15: =IF(AVERAGE(H15,J15,L15)<6,(5),(ROUND(AVERAGE(H15,J15,L15),0))) -> 6 | R15: =IF(N15>20,"EXTRA","ORD") -> ORD
A16: 5 | C16: ARREDONDO | D16: LOREDO | E16: JOSHUA JAAFET | G16: 0 | H16: 8 | M16: =G16+I16+K16 -> 0 | N16: =(M16*100)/$P$8 -> 0 | O16: =H16+J16+L16 -> 8 | P16: =IF(AVERAGE(H16,J16,L16)<6,(5),(ROUND(AVERAGE(H16,J16,L16),0))) -> 8 | R16: =IF(N16>20,"EXTRA","ORD") -> ORD
B17: 6 | C17: AVILES | D17: ACOSTA | E17: ARELI | G17: 0 | H17: 8 | M17: =G17+I17+K17 -> 0 | N17: =(M17*100)/$P$8 -> 0 | O17: =H17+J17+L17 -> 8 | P17: =IF(AVERAGE(H17,J17,L17)<6,(5),(ROUND(AVERAGE(H17,J17,L17),0))) -> 8 | R17: =IF(N17>20,"EXTRA","ORD") -> ORD
A18: 7 | C18: CARBAJAL | D18: RODRIGUEZ | E18: GAEL | G18: 0 | H18: 8 | M18: =G18+I18+K18 -> 0 | N18: =(M18*100)/$P$8 -> 0 | O18: =H18+J18+L18 -> 8 | P18: =IF(AVERAGE(H18,J18,L18)<6,(5),(ROUND(AVERAGE(H18,J18,L18),0))) -> 8 | R18: =IF(N18>20,"EXTRA","ORD") -> ORD
A19: 8 | C19: CARDENAS | D19: MORENO | E19: CRISTOPHER TADEO | G19: 0 | H19: 10 | M19: =G19+I19+K19 -> 0 | N19: =(M19*100)/$P$8 -> 0 | O19: =H19+J19+L19 -> 10 | P19: =IF(AVERAGE(H19,J19,L19)<6,(5),(ROUND(AVERAGE(H19,J19,L19),0))) -> 10 | R19: =IF(N19>20,"EXTRA","ORD") -> ORD
B20: 9 | C20: CASTILLO | D20: HERNANDEZ | E20: XUNELLY | G20: 0 | H20: 5 | M20: =G20+I20+K20 -> 0 | N20: =(M20*100)/$P$8 -> 0 | O20: =H20+J20+L20 -> 5 | P20: =IF(AVERAGE(H20,J20,L20)<6,(5),(ROUND(AVERAGE(H20,J20,L20),0))) -> 5 | R20: =IF(N20>20,"EXTRA","ORD") -> ORD
B21: 10 | C21: CEREZO | D21: MORALES | E21: LOURDES YURYCO | G21: 0 | H21: 10 | M21: =G21+I21+K21 -> 0 | N21: =(M21*100)/$P$8 -> 0 | O21: =H21+J21+L21 -> 10 | P21: =IF(AVERAGE(H21,J21,L21)<6,(5),(ROUND(AVERAGE(H21,J21,L21),0))) -> 10 | R21: =IF(N21>20,"EXTRA","ORD") -> ORD
A22: 11 | C22: CONTRERAS | D22: QUIÑONES | E22: OLIVER | G22: 0 | H22: 8 | M22: =G22+I22+K22 -> 0 | N22: =(M22*100)/$P$8 -> 0 | O22: =H22+J22+L22 -> 8 | P22: =IF(AVERAGE(H22,J22,L22)<6,(5),(ROUND(AVERAGE(H22,J22,L22),0))) -> 8 | R22: =IF(N22>20,"EXTRA","ORD") -> ORD
B23: 12 | C23: CRUZ | D23: CENTENO | E23: ALEXA ABIGAIL | G23: 0 | H23: 6 | M23: =G23+I23+K23 -> 0 | N23: =(M23*100)/$P$8 -> 0 | O23: =H23+J23+L23 -> 6 | P23: =IF(AVERAGE(H23,J23,L23)<6,(5),(ROUND(AVERAGE(H23,J23,L23),0))) -> 6 | R23: =IF(N23>20,"EXTRA","ORD") -> ORD
A24: 13 | C24: CRUZ | D24: PAZ | E24: CARLOS ALFONSO | G24: 0 | H24: 5 | M24: =G24+I24+K24 -> 0 | N24: =(M24*100)/$P$8 -> 0 | O24: =H24+J24+L24 -> 5 | P24: =IF(AVERAGE(H24,J24,L24)<6,(5),(ROUND(AVERAGE(H24,J24,L24),0))) -> 5 | R24: =IF(N24>20,"EXTRA","ORD") -> ORD
B25: 14 | C25: DIAZ | D25: MOLINA | E25: EMILIANA ALESSANDRA | G25: 0 | H25: 10 | M25: =G25+I25+K25 -> 0 | N25: =(M25*100)/$P$8 -> 0 | O25: =H25+J25+L25 -> 10 | P25: =IF(AVERAGE(H25,J25,L25)<6,(5),(ROUND(AVERAGE(H25,J25,L25),0))) -> 10 | R25: =IF(N25>20,"EXTRA","ORD") -> ORD
A26: 15 | C26: DUARTE | D26: ADJUNTAS | E26: RICARDO JESUS | G26: 0 | H26: 10 | M26: =G26+I26+K26 -> 0 | N26: =(M26*100)/$P$8 -> 0 | O26: =H26+J26+L26 -> 10 | P26: =IF(AVERAGE(H26,J26,L26)<6,(5),(ROUND(AVERAGE(H26,J26,L26),0))) -> 10 | R26: =IF(N26>20,"EXTRA","ORD") -> ORD
A27: 16 | C27: ESTRADA | D27: VENEGAS | E27: DAVID RICARDO | G27: 0 | H27: 5 | M27: =G27+I27+K27 -> 0 | N27: =(M27*100)/$P$8 -> 0 | O27: =H27+J27+L27 -> 5 | P27: =IF(AVERAGE(H27,J27,L27)<6,(5),(ROUND(AVERAGE(H27,J27,L27),0))) -> 5 | R27: =IF(N27>20,"EXTRA","ORD") -> ORD
