Workbook
Name Excel_BuiltIn_Print_Area: '3-1 conciencia historica iii'!$A$6:$O$62
Name Excel_BuiltIn_Print_Area: '3-1 economia i'!$A$6:$O$62
Name Excel_BuiltIn_Print_Area: '3-1 temas selectos de igualdad '!$A$6:$O$62
Name Excel_BuiltIn_Print_Area: '3-1 diseño digital'!$A$6:$O$62
Name Excel_BuiltIn_Print_Area: '3-1 ciencias de la comunicacion'!$A$6:$O$60
Name Excel_BuiltIn_Print_Area: '3-1 organismos'!$A$6:$O$62
Name Excel_BuiltIn_Print_Area: '3-1 temas selectos de matematic'!$A$6:$O$62
Name Excel_BuiltIn_Print_Area: '3-1 temas selectos de ingles ii'!$A$6:$O$62
Name Excel_BuiltIn_Print_Area: '3-1 paginas web'!$A$6:$O$62
Name Excel_BuiltIn_Print_Area: '3-1 actividades artisticas y cu'!$A$6:$O$62
Name Excel_BuiltIn_Print_Area: '3-1 practica y colaboracion ciu'!$A$6:$O$62
Name Excel_BuiltIn_Print_Area: '3-1 temas selectos de filosofia'!$A$6:$O$62

Sheet 3-1 ciencias de la comunicacion
O1: HORAS IMPARTIDAS
C2: ORIENTADORA | D2: NEFATLÍ MARGARITA MORLÁN ORTÍZ | H2: ESCUELA PREPARATORIA OFICIAL NÚM.67 | O2: Febrero | P2: 12
H3: “2026. Año del Humanismo Mexicano en el Estado de México ”. | O3: Marzo | P3: 15
H4: CICLO ESCOLAR: 2025 -2026 | O4: Abril | P4: 5
E5: TURNO : | G5: MATUTINO | J5: Grado | K5: 3° | L5: Grupo | M5: 1 | O5: Mayo | P5: 11
E6: PROFESOR(A): | K6: UAC | L6: CIENCIAS DE LA COMUNICACIÓN I | O6: Junio | P6: 14
G7: HOMBRES | H7: =A59 -> 23 | O7: Julio | P7: 3
G8: MUJERES | H8: =B59 -> 22 | O8: TOTAL | P8: =SUM(P2:P7) -> 60
G9: TOTAL | H9: =H7+H8 -> 45
A10: N | B10: P | C10: NOMBRE DEL ALUMNO | G10: PRIMERA EVALUACIÓN | I10: SEGUNDA EVALUACIÓN | K10: TERCERA EVALUACIÓN | M10: EVALUACIÓN FINAL
A11: H | B11: M | G11: FALTAS | H11: CALIF. | I11: FALTAS | J11: CALIF. | K11: FALTAS | L11: CALIF. | M11: TOT. DE FALTAS | N11: % FALTAS | O11: TOTAL DE PUNTOS | P11: CALIF. FINAL | Q11: FIRMA DEL ALUMNO | R11: ESTATUS
A12: 1 | C12: ABARCA | D12: MELENDEZ | E12: ANDRES SAID | G12: 0 | H12: 7 | M12: =G12+I12+K12 -> 0 | N12: =(M12*100)/$P$8 -> 0 | O12: =H12+J12+L12 -> 7 | P12: =IF(AVERAGE(H12,J12,L12)<6,(5),(ROUND(AVERAGE(H12,J12,L12),0))) -> 7 | R12: =IF(N12>20,"EXTRA","ORD") -> ORD
B13: 2 | C13: ALCANTARA | D13: BELTRAN | E13: JESSICA | G13: 0 | H13: 10 | M13: =G13+I13+K13 -> 0 | N13: =(M13*100)/$P$8 -> 0 | O13: =H13+J13+L13 -> 10 | P13: =IF(AVERAGE(H13,J13,L13)<6,(5),(ROUND(AVERAGE(H13,J13,L13),0))) -> 10 | R13: =IF(N13>20,"EXTRA","ORD") -> ORD
A14: 3 | C14: ALVAREZ | D14: BERNALDO | E14: ANGEL ALBERTO | G14: 0 | H14: 10 | M14: =G14+I14+K14 -> 0 | N14: =(M14*100)/$P$8 -> 0 | O14: =H14+J14+L14 -> 10 | P14: =IF(AVERAGE(H14,J14,L14)<6,(5),(ROUND(AVERAGE(H14,J14,L14),0))) -> 10 | R14: =IF(N14>20,"EXTRA","ORD") -> ORD
B15: 4 | C15: ALVAREZ | D15: GONZALEZ | E15: ALLISON JADE | G15: 0 | H15: 6 | M15: =G15+I15+K15 -> 0 | N15: =(M15*100)/$P$8 -> 0 | O15: =H15+J15+L15 -> 6 | P15: =IF(AVERAGE(H15,J15,L15)<6,(5),(ROUND(AVERAGE(H15,J15,L15),0))) -> 6 | R15: =IF(N15>20,"EXTRA","ORD") -> ORD
A16: 5 | C16: ANZALDO | D16: MARTINEZ | E16: NAYONEL YAEL | G16: 0 | H16: 8 | M16: =G16+I16+K16 -> 0 | N16: =(M16*100)/$P$8 -> 0 | O16: =H16+J16+L16 -> 8 | P16: =IF(AVERAGE(H16,J16,L16)<6,(5),(ROUND(AVERAGE(H16,J16,L16),0))) -> 8 | R16: =IF(N16>20,"EXTRA","ORD") -> ORD
A17: 6 | C17: AVILA | D17: ESCAMILLA | E17: JUSTIN YAHEL | G17: 21 | H17: 8 | M17: =G17+I17+K17 -> 21 | N17: =(M17*100)/$P$8 -> 35 | O17: =H17+J17+L17 -> 8 | P17: =IF(AVERAGE(H17,J17,L17)<6,(5),(ROUND(AVERAGE(H17,J17,L17),0))) -> 8 | R17: =IF(N17>20,"EXTRA","ORD") -> EXTRA
A18: 7 | C18: AYALA | D18: LARA | E18: ISAAC | G18: 0 | H18: 8 | M18: =G18+I18+K18 -> 0 | N18: =(M18*100)/$P$8 -> 0 | O18: =H18+J18+L18 -> 8 | P18: =IF(AVERAGE(H18,J18,L18)<6,(5),(ROUND(AVERAGE(H18,J18,L18),0))) -> 8 | R18: =IF(N18>20,"EXTRA","ORD") -> ORD
B19: 8 | C19: BATRES | D19: CERDA | E19: MARIA DEL PILAR | G19: 0 | H19: 10 | M19: =G19+I19+K19 -> 0 | N19: =(M19*100)/$P$8 -> 0 | O19: =H19+J19+L19 -> 10 | P19: =IF(AVERAGE(H19,J19,L19)<6,(5),(ROUND(AVERAGE(H19,J19,L19),0))) -> 10 | R19: =IF(N19>20,"EXTRA","ORD") -> ORD
A20: 9 | C20: BONILLA | D20: TREJO | E20: FRANCISCO TONATIUH | G20: 0 | H20: 5 | M20: =G20+I20+K20 -> 0 | N20: =(M20*100)/$P$8 -> 0 | O20: =H20+J20+L20 -> 5 | P20: =IF(AVERAGE(H20,J20,L20)<6,(5),(ROUND(AVERAGE(H20,J20,L20),0))) -> 5 | R20: =IF(N20>20,"EXTRA","ORD") -> ORD
A21: 10 | C21: CABRERA | D21: MARTINEZ | E21: JESUS ADRIAN | G21: 0 | H21: 10 | M21: =G21+I21+K21 -> 0 | N21: =(M21*100)/$P$8 -> 0 | O21: =H21+J21+L21 -> 10 | P21: =IF(AVERAGE(H21,J21,L21)<6,(5),(ROUND(AVERAGE(H21,J21,L21),0))) -> 10 | R21: =IF(N21>20,"EXTRA","ORD") -> ORD
B22: 11 | C22: CARDONA | D22: ZARATE | E22: JULIA EMILY | G22: 0 | H22: 8 | M22: =G22+I22+K22 -> 0 | N22: =(M22*100)/$P$8 -> 0 | O22: =H22+J22+L22 -> 8 | P22: =IF(AVERAGE(H22,J22,L22)<6,(5),(ROUND(AVERAGE(H22,J22,L22),0))) -> 8 | R22: =IF(N22>20,"EXTRA","ORD") -> ORD
A23: 12 | C23: CASALES | D23: LORANCA | E23: EDSON | G23: 0 | H23: 6 | M23: =G23+I23+K23 -> 0 | N23: =(M23*100)/$P$8 -> 0 | O23: =H23+J23+L23 -> 6 | P23: =IF(AVERAGE(H23,J23,L23)<6,(5),(ROUND(AVERAGE(H23,J23,L23),0))) -> 6 | R23: =IF(N23>20,"EXTRA","ORD") -> ORD
A24: 13 | C24: CRUZ | D24: GARCÍA | E24: PEDRO YASHIR | G24: 0 | H24: 5 | M24: =G24+I24+K24 -> 0 | N24: =(M24*100)/$P$8 -> 0 | O24: =H24+J24+L24 -> 5 | P24: =IF(AVERAGE(H24,J24,L24)<6,(5),(ROUND(AVERAGE(H24,J24,L24),0))) -> 5 | R24: =IF(N24>20,"EXTRA","ORD") -> ORD
B25: 14 | C25: FUENTES | D25: VALADEZ | E25: ALEXIA DANNAE | G25: 0 | H25: 10 | M25: =G25+I25+K25 -> 0 | N25: =(M25*100)/$P$8 -> 0 | O25: =H25+J25+L25 -> 10 | P25: =IF(AVERAGE(H25,J25,L25)<6,(5),(ROUND(AVERAGE(H25,J25,L25),0))) -> 10 | R25: =IF(N25>20,"EXTRA","ORD") -> ORD
A26: 15 | C26: GARCIA | D26: RANGEL | E26: ADRIAN | G26: 0 | H26: 10 | M26: =G26+I26+K26 -> 0 | N26: =(M26*100)/$P$8 -> 0 | O26: =H26+J26+L26 -> 10 | P26: =IF(AVERAGE(H26,J26,L26)<6,(5),(ROUND(AVERAGE(H26,J26,L26),0))) -> 10 | R26: =IF(N26>20,"EXTRA","ORD") -> ORD
B27: 16 | C27: GOMEZ | D27: ARREDONDO | E27: AMERICA NAOMI | G27: 0 | H27: 5 | M27: =G27+I27+K27 -> 0 | N27: =(M27*100)/$P$8 -> 0 | O27: =H27+J27+L27 -> 5 | P27: =IF(AVERAGE(H27,J27,L27)<6,(5),(ROUND(AVERAGE(H27,J27,L27),0))) -> 5 | R27: =IF(N27>20,"EXTRA","ORD") -> ORD
B28: 17 | C28: GOMEZ | D28: VAZQUEZ | E28: BIBIANA | G28: 0 | H28: 7 | M28: =G28+I28+K28 -> 0 | N28: =(M28*100)/$P$8 -> 0 | O28: =H28+J28+L28 -> 7 | P28: =IF(AVERAGE(H28,J28,L28)<6,(5),(ROUND(AVERAGE(H28,J28,L28),0))) -> 7 | R28: =IF(N28>20,"EXTRA","ORD") -> ORD
B29: 18 | C29: GONZALEZ | D29: REYNA | E29: PAULA EDITH | G29: 0 | H29: 6 | M29: =G29+I29+K29 -> 0 | N29: =(M29*100)/$P$8 -> 0 | O29: =H29+J29+L29 -> 6 | P29: =IF(AVERAGE(H29,J29,L29)<6,(5),(ROUND(AVERAGE(H29,J29,L29),0))) -> 6 | R29: =IF(N29>20,"EXTRA","ORD") -> ORD
A30: 19 | C30: HERNANDEZ | D30: CHAVEZ | E30: DEREK | G30: 1 | H30: 6 | M30: =G30+I30+K30 -> 1 | N30: =(M30*100)/$P$8 -> 1.6666667 | O30: =H30+J30+L30 -> 6 | P30: =IF(AVERAGE(H30,J30,L30)<6,(5),(ROUND(AVERAGE(H30,J30,L30),0))) -> 6 | R30: =IF(N30>20,"EXTRA","ORD") -> ORD
B31: 20 | C31: HERNANDEZ | D31: LEDEZMA | E31: IRIARY GUADALUPE | G31: 0 | H31: 10 | M31: =G31+I31+K31 -> 0 | N31: =(M31*100)/$P$8 -> 0 | O31: =H31+J31+L31 -> 10 | P31: =IF(AVERAGE(H31,J31,L31)<6,(5),(ROUND(AVERAGE(H31,J31,L31),0))) -> 10 | R31: =IF(N31>20,"EXTRA","ORD") -> ORD
A32: 21 | C32: JARALEÑO | D32: BLANCO | E32: IRVING GAEL | G32: 0 | H32: 9 | M32: =G32+I32+K32 -> 0 | N32: =(M32*100)/$P$8 -> 0 | O32: =H32+J32+L32 -> 9 | P32: =IF(AVERAGE(H32,J32,L32)<6,(5),(ROUND(AVERAGE(H32,J32,L32),0))) -> 9 | R32: =IF(N32>20,"EXTRA","ORD") -> ORD
B33: 22 | C33: LIMA | D33: ACEVES | E33: DAFNE ERIN | G33: 0 | H33: 6 | M33: =G33+I33+K33 -> 0 | N33: =(M33*100)/$P$8 -> 0 | O33: =H33+J33+L33 -> 6 | P33: =IF(AVERAGE(H33,J33,L33)<6,(5),(ROUND(AVERAGE(H33,J33,L33),0))) -> 6 | R33: =IF(N33>20,"EXTRA","ORD") -> ORD
B34: 23 | C34: LOPEZ | D34: GODINEZ | E34: AZUL XIMENA | G34: 1 | H34: 5 | M34: =G34+I34+K34 -> 1 | N34: =(M34*100)/$P$8 -> 1.6666667 | O34: =H34+J34+L34 -> 5 | P34: =IF(AVERAGE(H34,J34,L34)<6,(5),(ROUND(AVERAGE(H34,J34,L34),0))) -> 5 | R34: =IF(N34>20,"EXTRA","ORD") -> ORD
A35: 24 | C35: LUGO | D35: GONZALEZ | E35: LUIS DARIO | G35: 2 | H35: 7 | M35: =G35+I35+K35 -> 2 | N35: =(M35*100)/$P$8 -> 3.3333333 | O35: =H35+J35+L35 -> 7 | P35: =IF(AVERAGE(H35,J35,L35)<6,(5),(ROUND(AVERAGE(H35,J35,L35),0))) -> 7 | R35: =IF(N35>20,"EXTRA","ORD") -> ORD
A36: 25 | C36: MARQUEZ | D36: YAÑEZ | E36: ISRAEL | G36: 0 | H36: 7 | M36: =G36+I36+K36 -> 0 | N36: =(M36*100)/$P$8 -> 0 | O36: =H36+J36+L36 -> 7 | P36: =IF(AVERAGE(H36,J36,L36)<6,(5),(ROUND(AVERAGE(H36,J36,L36),0))) -> 7 | R36: =IF(N36>20,"EXTRA","ORD") -> ORD
A37: 26 | C37: MARTINEZ | D37: MONTERO | E37: ANGEL YAIR | G37: 0 | H37: 7 | M37: =G37+I37+K37 -> 0 | N37: =(M37*100)/$P$8 -> 0 | O37: =H37+J37+L37 -> 7 | P37: =IF(AVERAGE(H37,J37,L37)<6,(5),(ROUND(AVERAGE(H37,J37,L37),0))) -> 7 | R37: =IF(N37>20,"EXTRA","ORD") -> ORD
A38: 27 | C38: MENDOZA | D38: CRUZ | E38: IAN YAMIL | G38: 0 | H38: 7 | M38: =G38+I38+K38 -> 0 | N38: =(M38*100)/$P$8 -> 0 | O38: =H38+J38+L38 -> 7 | P38: =IF(AVERAGE(H38,J38,L38)<6,(5),(ROUND(AVERAGE(H38,J38,L38),0))) -> 7 | R38: =IF(N38>20,"EXTRA","ORD") -> ORD
B39: 28 | C39: MONTOYA | D39: LOPEZ | E39: WENDY MARIEL | G39: 0 | H39: 8 | M39: =G39+I39+K39 -> 0 | N39: =(M39*100)/$P$8 -> 0 | O39: =H39+J39+L39 -> 8 | P39: =IF(AVERAGE(H39,J39,L39)<6,(5),(ROUND(AVERAGE(H39,J39,L39),0))) -> 8 | R39: =IF(N39>20,"EXTRA","ORD") -> ORD
B40: 29 | C40: MORA | D40: SORIANO | E40: GIANNINA | G40: 0 | H40: 8 | M40: =G40+I40+K40 -> 0 | N40: =(M40*100)/$P$8 -> 0 | O40: =H40+J40+L40 -> 8 | P40: =IF(AVERAGE(H40,J40,L40)<6,(5),(ROUND(AVERAGE(H40,J40,L40),0))) -> 8 | R40: =IF(N40>20,"EXTRA","ORD") -> ORD
...

Sheet 3-1 temas selectos de ingles ii
O1: HORAS IMPARTIDAS
C2: ORIENTADORA | D2: NEFATLÍ MARGARITA MORLÁN ORTÍZ | H2: ESCUELA PREPARATORIA OFICIAL NÚM.67 | O2: Febrero | P2: 12
H3: “2026. Año del Humanismo Mexicano en el Estado de México ”. | O3: Marzo | P3: 15
H4: CICLO ESCOLAR: 2025 -2026 | O4: Abril | P4: 5
E5: TURNO : | G5: MATUTINO | J5: Grado | K5: 3° | L5: Grupo | M5: 1 | O5: Mayo | P5: 11
E6: PROFESOR(A): | K6: UAC | L6: TEMAS SELECTOS DE INGLÉS II | O6: Junio | P6: 14
G7: HOMBRES | H7: =A59 -> 23 | O7: Julio | P7: 3
G8: MUJERES | H8: =B59 -> 22 | O8: TOTAL | P8: =SUM(P2:P7) -> 60
G9: TOTAL | H9: =H7+H8 -> 45
A10: N | B10: P | C10: NOMBRE DEL ALUMNO | G10: PRIMERA EVALUACIÓN | I10: SEGUNDA EVALUACIÓN | K10: TERCERA EVALUACIÓN | M10: EVALUACIÓN FINAL
A11: H | B11: M | G11: FALTAS | H11: CALIF. | I11: FALTAS | J11: CALIF. | K11: FALTAS | L11: CALIF. | M11: TOT. DE FALTAS | N11: % FALTAS | O11: TOTAL DE PUNTOS | P11: CALIF. FINAL | Q11: FIRMA DEL ALUMNO | R11: ESTATUS
A12: 1 | C12: ABARCA | D12: MELENDEZ | E12: ANDRES SAID | G12: 0 | H12: 7 | M12: =G12+I12+K12 -> 0 | N12: =(M12*100)/$P$8 -> 0 | O12: =H12+J12+L12 -> 7 | P12: =IF(AVERAGE(H12,J12,L12)<6,(5),(ROUND(AVERAGE(H12,J12,L12),0))) -> 7 | R12: =IF(N12>20,"EXTRA","ORD") -> ORD
B13: 2 | C13: ALCANTARA | D13: BELTRAN | E13: JESSICA | G13: 0 | H13: 10 | M13: =G13+I13+K13 -> 0 | N13: =(M13*100)/$P$8 -> 0 | O13: =H13+J13+L13 -> 10 | P13: =IF(AVERAGE(H13,J13,L13)<6,(5),(ROUND(AVERAGE(H13,J13,L13),0))) -> 10 | R13: =IF(N13>20,"EXTRA","ORD") -> ORD
A14: 3 | C14: ALVAREZ | D14: BERNALDO | E14: ANGEL ALBERTO | G14: 0 | H14: 10 | M14: =G14+I14+K14 -> 0 | N14: =(M14*100)/$P$8 -> 0 | O14: =H14+J14+L14 -> 10 | P14: =IF(AVERAGE(H14,J14,L14)<6,(5),(ROUND(AVERAGE(H14,J14,L14),0))) -> 10 | R14: =IF(N14>20,"EXTRA","ORD") -> ORD
B15: 4 | C15: ALVAREZ | D15: GONZALEZ | E15: ALLISON JADE | G15: 0 | H15: 6 | M15: =G15+I15+K15 -> 0 | N15: =(M15*100)/$P$8 -> 0 | O15: =H15+J15+L15 -> 6 | P15: =IF(AVERAGE(H15,J15,L15)<6,(5),(ROUND(AVERAGE(H15,J15,L15),0))) -> 6 | R15: =IF(N15>20,"EXTRA","ORD") -> ORD
A16: 5 | C16: ANZALDO | D16: MARTINEZ | E16: NAYONEL YAEL | G16: 0 | H16: 8 | M16: =G16+I16+K16 -> 0 | N16: =(M16*100)/$P$8 -> 0 | O16: =H16+J16+L16 -> 8 | P16: =IF(AVERAGE(H16,J16,L16)<6,(5),(ROUND(AVERAGE(H16,J16,L16),0))) -> 8 | R16: =IF(N16>20,"EXTRA","ORD") -> ORD
A17: 6 | C17: AVILA | D17: ESCAMILLA | E17: JUSTIN YAHEL | G17: 21 | H17: 8 | M17: =G17+I17+K17 -> 21 | N17: =(M17*100)/$P$8 -> 35 | O17: =H17+J17+L17 -> 8 | P17: =IF(AVERAGE(H17,J17,L17)<6,(5),(ROUND(AVERAGE(H17,J17,L17),0))) -> 8 | R17: =IF(N17>20,"EXTRA","ORD") -> EXTRA
A18: 7 | C18: AYALA | D18: LARA | E18: ISAAC | G18: 0 | H18: 8 | M18: =G18+I18+K18 -> 0 | N18: =(M18*100)/$P$8 -> 0 | O18: =H18+J18+L18 -> 8 | P18: =IF(AVERAGE(H18,J18,L18)<6,(5),(ROUND(AVERAGE(H18,J18,L18),0))) -> 8 | R18: =IF(N18>20,"EXTRA","ORD") -> ORD
B19: 8 | C19: BATRES | D19: CERDA | E19: MARIA DEL PILAR | G19: 0 | H19: 10 | M19: =G19+I19+K19 -> 0 | N19: =(M19*100)/$P$8 -> 0 | O19: =H19+J19+L19 -> 10 | P19: =IF(AVERAGE(H19,J19,L19)<6,(5),(ROUND(AVERAGE(H19,J19,L19),0))) -> 10 | R19: =IF(N19>20,"EXTRA","ORD") -> ORD
A20: 9 | C20: BONILLA | D20: TREJO | E20: FRANCISCO TONATIUH | G20: 0 | H20: 5 | M20: =G20+I20+K20 -> 0 | N20: =(M20*100)/$P$8 -> 0 | O20: =H20+J20+L20 -> 5 | P20: =IF(AVERAGE(H20,J20,L20)<6,(5),(ROUND(AVERAGE(H20,J20,L20),0))) -> 5 | R20: =IF(N20>20,"EXTRA","ORD") -> ORD
A21: 10 | C21: CABRERA | D21: MARTINEZ | E21: JESUS ADRIAN | G21: 0 | H21: 10 | M21: =G21+I21+K21 -> 0 | N21: =(M21*100)/$P$8 -> 0 | O21: =H21+J21+L21 -> 10 | P21: =IF(AVERAGE(H21,J21,L21)<6,(5),(ROUND(AVERAGE(H21,J21,L21),0))) -> 10 | R21: =IF(N21>20,"EXTRA","ORD") -> ORD
B22: 11 | C22: CARDONA | D22: ZARATE | E22: JULIA EMILY | G22: 0 | H22: 8 | M22: =G22+I22+K22 -> 0 | N22: =(M22*100)/$P$8 -> 0 | O22: =H22+J22+L22 -> 8 | P22: =IF(AVERAGE(H22,J22,L22)<6,(5),(ROUND(AVERAGE(H22,J22,L22),0))) -> 8 | R22: =IF(N22>20,"EXTRA","ORD") -> ORD
A23: 12 | C23: CASALES | D23: LORANCA | E23: EDSON | G23: 0 | H23: 6 | M23: =G23+I23+K23 -> 0 | N23: =(M23*100)/$P$8 -> 0 | O23: =H23+J23+L23 -> 6 | P23: =IF(AVERAGE(H23,J23,L23)<6,(5),(ROUND(AVERAGE(H23,J23,L23),0))) -> 6 | R23: =IF(N23>20,"EXTRA","ORD") -> ORD
A24: 13 | C24: CRUZ | D24: GARCÍA | E24: PEDRO YASHIR | G24: 0 | H24: 5 | M24: =G24+I24+K24 -> 0 | N24: =(M24*100)/$P$8 -> 0 | O24: =H24+J24+L24 -> 5 | P24: =IF(AVERAGE(H24,J24,L24)<6,(5),(ROUND(AVERAGE(H24,J24,L24),0))) -> 5 | R24: =IF(N24>20,"EXTRA","ORD") -> ORD
B25: 14 | C25: FUENTES | D25: VALADEZ | E25: ALEXIA DANNAE | G25: 0 | H25: 10 | M25: =G25+I25+K25 -> 0 | N25: =(M25*100)/$P$8 -> 0 | O25: =H25+J25+L25 -> 10 | P25: =IF(AVERAGE(H25,J25,L25)<6,(5),(ROUND(AVERAGE(H25,J25,L25),0))) -> 10 | R25: =IF(N25>20,"EXTRA","ORD") -> ORD
A26: 15 | C26: GARCIA | D26: RANGEL | E26: ADRIAN | G26: 0 | H26: 10 | M26: =G26+I26+K26 -> 0 | N26: =(M26*100)/$P$8 -> 0 | O26: =H26+J26+L26 -> 10 | P26: =IF(AVERAGE(H26,J26,L26)<6,(5),(ROUND(AVERAGE(H26,J26,L26),0))) -> 10 | R26: =IF(N26>20,"EXTRA","ORD") -> ORD
B27: 16 | C27: GOMEZ | D27: ARREDONDO | E27: AMERICA NAOMI | G27: 0 | H27: 5 | M27: =G27+I27+K27 -> 0 | N27: =(M27*100)/$P$8 -> 0 | O27: =H27+J27+L27 -> 5 | P27: =IF(AVERAGE(H27,J27,L27)<6,(5),(ROUND(AVERAGE(H27,J27,L27),0))) -> 5 | R27: =IF(N27>20,"EXTRA","ORD") -> ORD
B28: 17 | C28: GOMEZ | D28: VAZQUEZ | E28: BIBIANA | G28: 0 | H28: 7 | M28: =G28+I28+K28 -> 0 | N28: =(M28*100)/$P$8 -> 0 | O28: =H28+J28+L28 -> 7 | P28: =IF(AVERAGE(H28,J28,L28)<6,(5),(ROUND(AVERAGE(H28,J28,L28),0))) -> 7 | R28: =IF(N28>20,"EXTRA","ORD") -> ORD
B29: 18 | C29: GONZALEZ | D29: REYNA | E29: PAULA EDITH | G29: 0 | H29: 6 | M29: =G29+I29+K29 -> 0 | N29: =(M29*100)/$P$8 -> 0 | O29: =H29+J29+L29 -> 6 | P29: =IF(AVERAGE(H29,J29,L29)<6,(5),(ROUND(AVERAGE(H29,J29,L29),0))) -> 6 | R29: =IF(N29>20,"EXTRA","ORD") -> ORD
A30: 19 | C30: HERNANDEZ | D30: CHAVEZ | E30: DEREK | G30: 1 | H30: 6 | M30: =G30+I30+K30 -> 1 | N30: =(M30*100)/$P$8 -> 1.6666667 | O30: =H30+J30+L30 -> 6 | P30: =IF(AVERAGE(H30,J30,L30)<6,(5),(ROUND(AVERAGE(H30,J30,L30),0))) -> 6 | R30: =IF(N30>20,"EXTRA","ORD") -> ORD
B31: 20 | C31: HERNANDEZ | D31: LEDEZMA | E31: IRIARY GUADALUPE | G31: 0 | H31: 10 | M31: =G31+I31+K31 -> 0 | N31: =(M31*100)/$P$8 -> 0 | O31: =H31+J31+L31 -> 10 | P31: =IF(AVERAGE(H31,J31,L31)<6,(5),(ROUND(AVERAGE(H31,J31,L31),0))) -> 10 | R31: =IF(N31>20,"EXTRA","ORD") -> ORD
A32: 21 | C32: JARALEÑO | D32: BLANCO | E32: IRVING GAEL | G32: 0 | H32: 9 | M32: =G32+I32+K32 -> 0 | N32: =(M32*100)/$P$8 -> 0 | O32: =H32+J32+L32 -> 9 | P32: =IF(AVERAGE(H32,J32,L32)<6,(5),(ROUND(AVERAGE(H32,J32,L32),0))) -> 9 | R32: =IF(N32>20,"EXTRA","ORD") -> ORD
B33: 22 | C33: LIMA | D33: ACEVES | E33: DAFNE ERIN | G33: 0 | H33: 6 | M33: =G33+I33+K33 -> 0 | N33: =(M33*100)/$P$8 -> 0 | O33: =H33+J33+L33 -> 6 | P33: =IF(AVERAGE(H33,J33,L33)<6,(5),(ROUND(AVERAGE(H33,J33,L33),0))) -> 6 | R33: =IF(N33>20,"EXTRA","ORD") -> ORD
B34: 23 | C34: LOPEZ | D34: GODINEZ | E34: AZUL XIMENA | G34: 1 | H34: 5 | M34: =G34+I34+K34 -> 1 | N34: =(M34*100)/$P$8 -> 1.6666667 | O34: =H34+J34+L34 -> 5 | P34: =IF(AVERAGE(H34,J34,L34)<6,(5),(ROUND(AVERAGE(H34,J34,L34),0))) -> 5 | R34: =IF(N34>20,"EXTRA","ORD") -> ORD
A35: 24 | C35: LUGO | D35: GONZALEZ | E35: LUIS DARIO | G35: 2 | H35: 7 | M35: =G35+I35+K35 -> 2 | N35: =(M35*100)/$P$8 -> 3.3333333 | O35: =H35+J35+L35 -> 7 | P35: =IF(AVERAGE(H35,J35,L35)<6,(5),(ROUND(AVERAGE(H35,J35,L35),0))) -> 7 | R35: =IF(N35>20,"EXTRA","ORD") -> ORD
A36: 25 | C36: MARQUEZ | D36: YAÑEZ | E36: ISRAEL | G36: 0 | H36: 7 | M36: =G36+I36+K36 -> 0 | N36: =(M36*100)/$P$8 -> 0 | O36: =H36+J36+L36 -> 7 | P36: =IF(AVERAGE(H36,J36,L36)<6,(5),(ROUND(AVERAGE(H36,J36,L36),0))) -> 7 | R36: =IF(N36>20,"EXTRA","ORD") -> ORD
A37: 26 | C37: MARTINEZ | D37: MONTERO | E37: ANGEL YAIR | G37: 0 | H37: 7 | M37: =G37+I37+K37 -> 0 | N37: =(M37*100)/$P$8 -> 0 | O37: =H37+J37+L37 -> 7 | P37: =IF(AVERAGE(H37,J37,L37)<6,(5),(ROUND(AVERAGE(H37,J37,L37),0))) -> 7 | R37: =IF(N37>20,"EXTRA","ORD") -> ORD
A38: 27 | C38: MENDOZA | D38: CRUZ | E38: IAN YAMIL | G38: 0 | H38: 7 | M38: =G38+I38+K38 -> 0 | N38: =(M38*100)/$P$8 -> 0 | O38: =H38+J38+L38 -> 7 | P38: =IF(AVERAGE(H38,J38,L38)<6,(5),(ROUND(AVERAGE(H38,J38,L38),0))) -> 7 | R38: =IF(N38>20,"EXTRA","ORD") -> ORD
B39: 28 | C39: MONTOYA | D39: LOPEZ | E39: WENDY MARIEL | G39: 0 | H39: 8 | M39: =G39+I39+K39 -> 0 | N39: =(M39*100)/$P$8 -> 0 | O39: =H39+J39+L39 -> 8 | P39: =IF(AVERAGE(H39,J39,L39)<6,(5),(ROUND(AVERAGE(H39,J39,L39),0))) -> 8 | R39: =IF(N39>20,"EXTRA","ORD") -> ORD
B40: 29 | C40: MORA | D40: SORIANO | E40: GIANNINA | G40: 0 | H40: 8 | M40: =G40+I40+K40 -> 0 | N40: =(M40*100)/$P$8 -> 0 | O40: =H40+J40+L40 -> 8 | P40: =IF(AVERAGE(H40,J40,L40)<6,(5),(ROUND(AVERAGE(H40,J40,L40),0))) -> 8 | R40: =IF(N40>20,"EXTRA","ORD") -> ORD
...

Sheet 3-1 temas selectos de matematic
O1: HORAS IMPARTIDAS
C2: ORIENTADORA | D2: NEFATLÍ MARGARITA MORLÁN ORTÍZ | H2: ESCUELA PREPARATORIA OFICIAL NÚM.67 | O2: Febrero | P2: 12
H3: “2026. Año del Humanismo Mexicano en el Estado de México ”. | O3: Marzo | P3: 15
H4: CICLO ESCOLAR: 2025 -2026 | O4: Abril | P4: 5
E5: TURNO : | G5: MATUTINO | J5: Grado | K5: 3° | L5: Grupo | M5: 1 | O5: Mayo | P5: 11
E6: PROFESOR(A): | K6: UAC | L6: TEMAS SELECTOS DE MATEMÁTICAS II | O6: Junio | P6: 14
G7: HOMBRES | H7: =A59 -> 23 | O7: Julio | P7: 3
G8: MUJERES | H8: =B59 -> 22 | O8: TOTAL | P8: =SUM(P2:P7) -> 60
G9: TOTAL | H9: =H7+H8 -> 45
A10: N | B10: P | C10: NOMBRE DEL ALUMNO | G10: PRIMERA EVALUACIÓN | I10: SEGUNDA EVALUACIÓN | K10: TERCERA EVALUACIÓN | M10: EVALUACIÓN FINAL
A11: H | B11: M | G11: FALTAS | H11: CALIF. | I11: FALTAS | J11: CALIF. | K11: FALTAS | L11: CALIF. | M11: TOT. DE FALTAS | N11: % FALTAS | O11: TOTAL DE PUNTOS | P11: CALIF. FINAL | Q11: FIRMA DEL ALUMNO | R11: ESTATUS
A12: 1 | C12: ABARCA | D12: MELENDEZ | E12: ANDRES SAID | G12: 0 | H12: 7 | M12: =G12+I12+K12 -> 0 | N12: =(M12*100)/$P$8 -> 0 | O12: =H12+J12+L12 -> 7 | P12: =IF(AVERAGE(H12,J12,L12)<6,(5),(ROUND(AVERAGE(H12,J12,L12),0))) -> 7 | R12: =IF(N12>20,"EXTRA","ORD") -> ORD
B13: 2 | C13: ALCANTARA | D13: BELTRAN | E13: JESSICA | G13: 0 | H13: 10 | M13: =G13+I13+K13 -> 0 | N13: =(M13*100)/$P$8 -> 0 | O13: =H13+J13+L13 -> 10 | P13: =IF(AVERAGE(H13,J13,L13)<6,(5),(ROUND(AVERAGE(H13,J13,L13),0))) -> 10 | R13: =IF(N13>20,"EXTRA","ORD") -> ORD
A14: 3 | C14: ALVAREZ | D14: BERNALDO | E14: ANGEL ALBERTO | G14: 0 | H14: 10 | M14: =G14+I14+K14 -> 0 | N14: =(M14*100)/$P$8 -> 0 | O14: =H14+J14+L14 -> 10 | P14: =IF(AVERAGE(H14,J14,L14)<6,(5),(ROUND(AVERAGE(H14,J14,L14),0))) -> 10 | R14: =IF(N14>20,"EXTRA","ORD") -> ORD
B15: 4 | C15: ALVAREZ | D15: GONZALEZ | E15: ALLISON JADE | G15: 0 | H15: 6 | M15: =G15+I15+K15 -> 0 | N15: =(M15*100)/$P$8 -> 0 | O15: =H15+J15+L15 -> 6 | P15: =IF(AVERAGE(H15,J15,L15)<6,(5),(ROUND(AVERAGE(H15,J15,L15),0))) -> 6 | R15: =IF(N15>20,"EXTRA","ORD") -> ORD
A16: 5 | C16: ANZALDO | D16: MARTINEZ | E16: NAYONEL YAEL | G16: 0 | H16: 8 | M16: =G16+I16+K16 -> 0 | N16: =(M16*100)/$P$8 -> 0 | O16: =H16+J16+L16 -> 8 | P16: =IF(AVERAGE(H16,J16,L16)<6,(5),(ROUND(AVERAGE(H16,J16,L16),0))) -> 8 | R16: =IF(N16>20,"EXTRA","ORD") -> ORD
A17: 6 | C17: AVILA | D17: ESCAMILLA | E17: JUSTIN YAHEL | G17: 21 | H17: 8 | M17: =G17+I17+K17 -> 21 | N17: =(M17*100)/$P$8 -> 35 | O17: =H17+J17+L17 -> 8 | P17: =IF(AVERAGE(H17,J17,L17)<6,(5),(ROUND(AVERAGE(H17,J17,L17),0))) -> 8 | R17: =IF(N17>20,"EXTRA","ORD") -> EXTRA
A18: 7 | C18: AYALA | D18: LARA | E18: ISAAC | G18: 0 | H18: 8 | M18: =G18+I18+K18 -> 0 | N18: =(M18*100)/$P$8 -> 0 | O18: =H18+J18+L18 -> 8 | P18: =IF(AVERAGE(H18,J18,L18)<6,(5),(ROUND(AVERAGE(H18,J18,L18),0))) -> 8 | R18: =IF(N18>20,"EXTRA","ORD") -> ORD
B19: 8 | C19: BATRES | D19: CERDA | E19: MARIA DEL PILAR | G19: 0 | H19: 10 | M19: =G19+I19+K19 -> 0 | N19: =(M19*100)/$P$8 -> 0 | O19: =H19+J19+L19 -> 10 | P19: =IF(AVERAGE(H19,J19,L19)<6,(5),(ROUND(AVERAGE(H19,J19,L19),0))) -> 10 | R19: =IF(N19>20,"EXTRA","ORD") -> ORD
A20: 9 | C20: BONILLA | D20: TREJO | E20: FRANCISCO TONATIUH | G20: 0 | H20: 5 | M20: =G20+I20+K20 -> 0 | N20: =(M20*100)/$P$8 -> 0 | O20: =H20+J20+L20 -> 5 | P20: =IF(AVERAGE(H20,J20,L20)<6,(5),(ROUND(AVERAGE(H20,J20,L20),0))) -> 5 | R20: =IF(N20>20,"EXTRA","ORD") -> ORD
A21: 10 | C21: CABRERA | D21: MARTINEZ | E21: JESUS ADRIAN | G21: 0 | H21: 10 | M21: =G21+I21+K21 -> 0 | N21: =(M21*100)/$P$8 -> 0 | O21: =H21+J21+L21 -> 10 | P21: =IF(AVERAGE(H21,J21,L21)<6,(5),(ROUND(AVERAGE(H21,J21,L21),0))) -> 10 | R21: =IF(N21>20,"EXTRA","ORD") -> ORD
B22: 11 | C22: CARDONA | D22: ZARATE | E22: JULIA EMILY | G22: 0 | H22: 8 | M22: =G22+I22+K22 -> 0 | N22: =(M22*100)/$P$8 -> 0 | O22: =H22+J22+L22 -> 8 | P22: =IF(AVERAGE(H22,J22,L22)<6,(5),(ROUND(AVERAGE(H22,J22,L22),0))) -> 8 | R22: =IF(N22>20,"EXTRA","ORD") -> ORD
A23: 12 | C23: CASALES | D23: LORANCA | E23: EDSON | G23: 0 | H23: 6 | M23: =G23+I23+K23 -> 0 | N23: =(M23*100)/$P$8 -> 0 | O23: =H23+J23+L23 -> 6 | P23: =IF(AVERAGE(H23,J23,L23)<6,(5),(ROUND(AVERAGE(H23,J23,L23),0))) -> 6 | R23: =IF(N23>20,"EXTRA","ORD") -> ORD
A24: 13 | C24: CRUZ | D24: GARCÍA | E24: PEDRO YASHIR | G24: 0 | H24: 5 | M24: =G24+I24+K24 -> 0 | N24: =(M24*100)/$P$8 -> 0 | O24: =H24+J24+L24 -> 5 | P24: =IF(AVERAGE(H24,J24,L24)<6,(5),(ROUND(AVERAGE(H24,J24,L24),0))) -> 5 | R24: =IF(N24>20,"EXTRA","ORD") -> ORD
B25: 14 | C25: FUENTES | D25: VALADEZ | E25: ALEXIA DANNAE | G25: 0 | H25: 10 | M25: =G25+I25+K25 -> 0 | N25: =(M25*100)/$P$8 -> 0 | O25: =H25+J25+L25 -> 10 | P25: =IF(AVERAGE(H25,J25,L25)<6,(5),(ROUND(AVERAGE(H25,J25,L25),0))) -> 10 | R25: =IF(N25>20,"EXTRA","ORD") -> ORD
A26: 15 | C26: GARCIA | D26: RANGEL | E26: ADRIAN | G26: 0 | H26: 10 | M26: =G26+I26+K26 -> 0 | N26: =(M26*100)/$P$8 -> 0 | O26: =H26+J26+L26 -> 10 | P26: =IF(AVERAGE(H26,J26,L26)<6,(5),(ROUND(AVERAGE(H26,J26,L26),0))) -> 10 | R26: =IF(N26>20,"EXTRA","ORD") -> ORD
B27: 16 | C27: GOMEZ | D27: ARREDONDO | E27: AMERICA NAOMI | G27: 0 | H27: 5 | M27: =G27+I27+K27 -> 0 | N27: =(M27*100)/$P$8 -> 0 | O27: =H27+J27+L27 -> 5 | P27: =IF(AVERAGE(H27,J27,L27)<6,(5),(ROUND(AVERAGE(H27,J27,L27),0))) -> 5 | R27: =IF(N27>20,"EXTRA","ORD") -> ORD
B28: 17 | C28: GOMEZ | D28: VAZQUEZ | E28: BIBIANA | G28: 0 | H28: 7 | M28: =G28+I28+K28 -> 0 | N28: =(M28*100)/$P$8 -> 0 | O28: =H28+J28+L28 -> 7 | P28: =IF(AVERAGE(H28,J28,L28)<6,(5),(ROUND(AVERAGE(H28,J28,L28),0))) -> 7 | R28: =IF(N28>20,"EXTRA","ORD") -> ORD
B29: 18 | C29: GONZALEZ | D29: REYNA | E29: PAULA EDITH | G29: 0 | H29: 6 | M29: =G29+I29+K29 -> 0 | N29: =(M29*100)/$P$8 -> 0 | O29: =H29+J29+L29 -> 6 | P29: =IF(AVERAGE(H29,J29,L29)<6,(5),(ROUND(AVERAGE(H29,J29,L29),0))) -> 6 | R29: =IF(N29>20,"EXTRA","ORD") -> ORD
A30: 19 | C30: HERNANDEZ | D30: CHAVEZ | E30: DEREK | G30: 1 | H30: 6 | M30: =G30+I30+K30 -> 1 | N30: =(M30*100)/$P$8 -> 1.6666667 | O30: =H30+J30+L30 -> 6 | P30: =IF(AVERAGE(H30,J30,L30)<6,(5),(ROUND(AVERAGE(H30,J30,L30),0))) -> 6 | R30: =IF(N30>20,"EXTRA","ORD") -> ORD
B31: 20 | C31: HERNANDEZ | D31: LEDEZMA | E31: IRIARY GUADALUPE | G31: 0 | H31: 10 | M31: =G31+I31+K31 -> 0 | N31: =(M31*100)/$P$8 -> 0 | O31: =H31+J31+L31 -> 10 | P31: =IF(AVERAGE(H31,J31,L31)<6,(5),(ROUND(AVERAGE(H31,J31,L31),0))) -> 10 | R31: =IF(N31>20,"EXTRA","ORD") -> ORD
A32: 21 | C32: JARALEÑO | D32: BLANCO | E32: IRVING GAEL | G32: 0 | H32: 9 | M32: =G32+I32+K32 -> 0 | N32: =(M32*100)/$P$8 -> 0 | O32: =H32+J32+L32 -> 9 | P32: =IF(AVERAGE(H32,J32,L32)<6,(5),(ROUND(AVERAGE(H32,J32,L32),0))) -> 9 | R32: =IF(N32>20,"EXTRA","ORD") -> ORD
B33: 22 | C33: LIMA | D33: ACEVES | E33: DAFNE ERIN | G33: 0 | H33: 6 | M33: =G33+I33+K33 -> 0 | N33: =(M33*100)/$P$8 -> 0 | O33: =H33+J33+L33 -> 6 | P33: =IF(AVERAGE(H33,J33,L33)<6,(5),(ROUND(AVERAGE(H33,J33,L33),0))) -> 6 | R33: =IF(N33>20,"EXTRA","ORD") -> ORD
B34: 23 | C34: LOPEZ | D34: GODINEZ | E34: AZUL XIMENA | G34: 1 | H34: 5 | M34: =G34+I34+K34 -> 1 | N34: =(M34*100)/$P$8 -> 1.6666667 | O34: =H34+J34+L34 -> 5 | P34: =IF(AVERAGE(H34,J34,L34)<6,(5),(ROUND(AVERAGE(H34,J34,L34),0))) -> 5 | R34: =IF(N34>20,"EXTRA","ORD") -> ORD
A35: 24 | C35: LUGO | D35: GONZALEZ | E35: LUIS DARIO | G35: 2 | H35: 7 | M35: =G35+I35+K35 -> 2 | N35: =(M35*100)/$P$8 -> 3.3333333 | O35: =H35+J35+L35 -> 7 | P35: =IF(AVERAGE(H35,J35,L35)<6,(5),(ROUND(AVERAGE(H35,J35,L35),0))) -> 7 | R35: =IF(N35>20,"EXTRA","ORD") -> ORD
A36: 25 | C36: MARQUEZ | D36: YAÑEZ | E36: ISRAEL | G36: 0 | H36: 7 | M36: =G36+I36+K36 -> 0 | N36: =(M36*100)/$P$8 -> 0 | O36: =H36+J36+L36 -> 7 | P36: =IF(AVERAGE(H36,J36,L36)<6,(5),(ROUND(AVERAGE(H36,J36,L36),0))) -> 7 | R36: =IF(N36>20,"EXTRA","ORD") -> ORD
A37: 26 | C37: MARTINEZ | D37: MONTERO | E37: ANGEL YAIR | G37: 0 | H37: 7 | M37: =G37+I37+K37 -> 0 | N37: =(M37*100)/$P$8 -> 0 | O37: =H37+J37+L37 -> 7 | P37: =IF(AVERAGE(H37,J37,L37)<6,(5),(ROUND(AVERAGE(H37,J37,L37),0))) -> 7 | R37: =IF(N37>20,"EXTRA","ORD") -> ORD
A38: 27 | C38: MENDOZA | D38: CRUZ | E38: IAN YAMIL | G38: 0 | H38: 7 | M38: =G38+I38+K38 -> 0 | N38: =(M38*100)/$P$8 -> 0 | O38: =H38+J38+L38 -> 7 | P38: =IF(AVERAGE(H38,J38,L38)<6,(5),(ROUND(AVERAGE(H38,J38,L38),0))) -> 7 | R38: =IF(N38>20,"EXTRA","ORD") -> ORD
B39: 28 | C39: MONTOYA | D39: LOPEZ | E39: WENDY MARIEL | G39: 0 | H39: 8 | M39: =G39+I39+K39 -> 0 | N39: =(M39*100)/$P$8 -> 0 | O39: =H39+J39+L39 -> 8 | P39: =IF(AVERAGE(H39,J39,L39)<6,(5),(ROUND(AVERAGE(H39,J39,L39),0))) -> 8 | R39: =IF(N39>20,"EXTRA","ORD") -> ORD
B40: 29 | C40: MORA | D40: SORIANO | E40: GIANNINA | G40: 0 | H40: 8 | M40: =G40+I40+K40 -> 0 | N40: =(M40*100)/$P$8 -> 0 | O40: =H40+J40+L40 -> 8 | P40: =IF(AVERAGE(H40,J40,L40)<6,(5),(ROUND(AVERAGE(H40,J40,L40),0))) -> 8 | R40: =IF(N40>20,"EXTRA","ORD") -> ORD
...

Sheet 3-1 conciencia historica iii
O1: HORAS IMPARTIDAS
C2: ORIENTADORA | D2: NEFATLÍ MARGARITA MORLÁN ORTÍZ | H2: ESCUELA PREPARATORIA OFICIAL NÚM.67 | O2: Febrero
H3: “2026. Año del Humanismo Mexicano en el Estado de México ”. | O3: Marzo
H4: CICLO ESCOLAR: 2025 -2026 | O4: Abril
E5: TURNO : | G5: MATUTINO | J5: Grado | K5: 3° | L5: Grupo | M5: 1 | O5: Mayo | P5: 15
E6: PROFESOR(A): | K6: UAC | L6: CONCIENCIA HISTÓRICA III | O6: Junio
G7: HOMBRES | H7: =A59 -> 23 | O7: Julio | P7: 3
G8: MUJERES | H8: =B59 -> 22 | O8: TOTAL | P8: =SUM(P2:P7) -> 18
G9: TOTAL | H9: =H7+H8 -> 45
A10: N | B10: P | C10: NOMBRE DEL ALUMNO | G10: PRIMERA EVALUACIÓN | I10: SEGUNDA EVALUACIÓN | K10: TERCERA EVALUACIÓN | M10: EVALUACIÓN FINAL
A11: H | B11: M | G11: FALTAS | H11: CALIF. | I11: FALTAS | J11: CALIF. | K11: FALTAS | L11: CALIF. | M11: TOT. DE FALTAS | N11: % FALTAS | O11: TOTAL DE PUNTOS | P11: CALIF. FINAL | Q11: FIRMA DEL ALUMNO | R11: ESTATUS
A12: 1 | C12: ABARCA | D12: MELENDEZ | E12: ANDRES SAID | G12: 0 | H12: 7 | M12: =G12+I12+K12 -> 0 | N12: =(M12*100)/$P$8 -> 0 | O12: =H12+J12+L12 -> 7 | P12: =IF(AVERAGE(H12,J12,L12)<6,(5),(ROUND(AVERAGE(H12,J12,L12),0))) -> 7 | R12: =IF(N12>20,"EXTRA","ORD") -> ORD
B13: 2 | C13: ALCANTARA | D13: BELTRAN | E13: JESSICA | G13: 0 | H13: 10 | M13: =G13+I13+K13 -> 0 | N13: =(M13*100)/$P$8 -> 0 | O13: =H13+J13+L13 -> 10 | P13: =IF(AVERAGE(H13,J13,L13)<6,(5),(ROUND(AVERAGE(H13,J13,L13),0))) -> 10 | R13: =IF(N13>20,"EXTRA","ORD") -> ORD
A14: 3 | C14: ALVAREZ | D14: BERNALDO | E14: ANGEL ALBERTO | G14: 0 | H14: 10 | M14: =G14+I14+K14 -> 0 | N14: =(M14*100)/$P$8 -> 0 | O14: =H14+J14+L14 -> 10 | P14: =IF(AVERAGE(H14,J14,L14)<6,(5),(ROUND(AVERAGE(H14,J14,L14),0))) -> 10 | R14: =IF(N14>20,"EXTRA","ORD") -> ORD
B15: 4 | C15: ALVAREZ | D15: GONZALEZ | E15: ALLISON JADE | G15: 0 | H15: 6 | M15: =G15+I15+K15 -> 0 | N15: =(M15*100)/$P$8 -> 0 | O15: =H15+J15+L15 -> 6 | P15: =IF(AVERAGE(H15,J15,L15)<6,(5),(ROUND(AVERAGE(H15,J15,L15),0))) -> 6 | R15: =IF(N15>20,"EXTRA","ORD") -> ORD
A16: 5 | C16: ANZALDO | D16: MARTINEZ | E16: NAYONEL YAEL | G16: 0 | H16: 8 | M16: =G16+I16+K16 -> 0 | N16: =(M16*100)/$P$8 -> 0 | O16: =H16+J16+L16 -> 8 | P16: =IF(AVERAGE(H16,J16,L16)<6,(5),(ROUND(AVERAGE(H16,J16,L16),0))) -> 8 | R16: =IF(N16>20,"EXTRA","ORD") -> ORD
A17: 6 | C17: AVILA | D17: ESCAMILLA | E17: JUSTIN YAHEL | G17: 21 | H17: 8 | M17: =G17+I17+K17 -> 21 | N17: =(M17*100)/$P$8 -> 116.66667 | O17: =H17+J17+L17 -> 8 | P17: =IF(AVERAGE(H17,J17,L17)<6,(5),(ROUND(AVERAGE(H17,J17,L17),0))) -> 8 | R17: =IF(N17>20,"EXTRA","ORD") -> EXTRA
A18: 7 | C18: AYALA | D18: LARA | E18: ISAAC | G18: 0 | H18: 8 | M18: =G18+I18+K18 -> 0 | N18: =(M18*100)/$P$8 -> 0 | O18: =H18+J18+L18 -> 8 | P18: =IF(AVERAGE(H18,J18,L18)<6,(5),(ROUND(AVERAGE(H18,J18,L18),0))) -> 8 | R18: =IF(N18>20,"EXTRA","ORD") -> ORD
B19: 8 | C19: BATRES | D19: CERDA | E19: MARIA DEL PILAR | G19: 0 | H19: 10 | M19: =G19+I19+K19 -> 0 | N19: =(M19*100)/$P$8 -> 0 | O19: =H19+J19+L19 -> 10 | P19: =IF(AVERAGE(H19,J19,L19)<6,(5),(ROUND(AVERAGE(H19,J19,L19),0))) -> 10 | R19: =IF(N19>20,"EXTRA","ORD") -> ORD
A20: 9 | C20: BONILLA | D20: TREJO | E20: FRANCISCO TONATIUH | G20: 0 | H20: 5 | M20: =G20+I20+K20 -> 0 | N20: =(M20*100)/$P$8 -> 0 | O20: =H20+J20+L20 -> 5 | P20: =IF(AVERAGE(H20,J20,L20)<6,(5),(ROUND(AVERAGE(H20,J20,L20),0))) -> 5 | R20: =IF(N20>20,"EXTRA","ORD") -> ORD
A21: 10 | C21: CABRERA | D21: MARTINEZ | E21: JESUS ADRIAN | G21: 0 | H21: 10 | M21: =G21+I21+K21 -> 0 | N21: =(M21*100)/$P$8 -> 0 | O21: =H21+J21+L21 -> 10 | P21: =IF(AVERAGE(H21,J21,L21)<6,(5),(ROUND(AVERAGE(H21,J21,L21),0))) -> 10 | R21: =IF(N21>20,"EXTRA","ORD") -> ORD
B22: 11 | C22: CARDONA | D22: ZARATE | E22: JULIA EMILY | G22: 0 | H22: 8 | M22: =G22+I22+K22 -> 0 | N22: =(M22*100)/$P$8 -> 0 | O22: =H22+J22+L22 -> 8 | P22: =IF(AVERAGE(H22,J22,L22)<6,(5),(ROUND(AVERAGE(H22,J22,L22),0))) -> 8 | R22: =IF(N22>20,"EXTRA","ORD") -> ORD
A23: 12 | C23: CASALES | D23: LORANCA | E23: EDSON | G23: 0 | H23: 6 | M23: =G23+I23+K23 -> 0 | N23: =(M23*100)/$P$8 -> 0 | O23: =H23+J23+L23 -> 6 | P23: =IF(AVERAGE(H23,J23,L23)<6,(5),(ROUND(AVERAGE(H23,J23,L23),0))) -> 6 | R23: =IF(N23>20,"EXTRA","ORD") -> ORD
A24: 13 | C24: CRUZ | D24: GARCÍA | E24: PEDRO YASHIR | G24: 0 | H24: 5 | M24: =G24+I24+K24 -> 0 | N24: =(M24*100)/$P$8 -> 0 | O24: =H24+J24+L24 -> 5 | P24: =IF(AVERAGE(H24,J24,L24)<6,(5),(ROUND(AVERAGE(H24,J24,L24),0))) -> 5 | R24: =IF(N24>20,"EXTRA","ORD") -> ORD
B25: 14 | C25: FUENTES | D25: VALADEZ | E25: ALEXIA DANNAE | G25: 0 | H25: 10 | M25: =G25+I25+K25 -> 0 | N25: =(M25*100)/$P$8 -> 0 | O25: =H25+J25+L25 -> 10 | P25: =IF(AVERAGE(H25,J25,L25)<6,(5),(ROUND(AVERAGE(H25,J25,L25),0))) -> 10 | R25: =IF(N25>20,"EXTRA","ORD") -> ORD
A26: 15 | C26: GARCIA | D26: RANGEL | E26: ADRIAN | G26: 0 | H26: 10 | M26: =G26+I26+K26 -> 0 | N26: =(M26*100)/$P$8 -> 0 | O26: =H26+J26+L26 -> 10 | P26: =IF(AVERAGE(H26,J26,L26)<6,(5),(ROUND(AVERAGE(H26,J26,L26),0))) -> 10 | R26: =IF(N26>20,"EXTRA","ORD") -> ORD
B27: 16 | C27: GOMEZ | D27: ARREDONDO | E27: AMERICA NAOMI | G27: 0 | H27: 5 | M27: =G27+I27+K27 -> 0 | N27: =(M27*100)/$P$8 -> 0 | O27: =H27+J27+L27 -> 5 | P27: =IF(AVERAGE(H27,J27,L27)<6,(5),(ROUND(AVERAGE(H27,J27,L27),0))) -> 5 | R27: =IF(N27>20,"EXTRA","ORD") -> ORD
B28: 17 | C28: GOMEZ | D28: VAZQUEZ | E28: BIBIANA | G28: 0 | H28: 7 | M28: =G28+I28+K28 -> 0 | N28: =(M28*100)/$P$8 -> 0 | O28: =H28+J28+L28 -> 7 | P28: =IF(AVERAGE(H28,J28,L28)<6,(5),(ROUND(AVERAGE(H28,J28,L28),0))) -> 7 | R28: =IF(N28>20,"EXTRA","ORD") -> ORD
B29: 18 | C29: GONZALEZ | D29: REYNA | E29: PAULA EDITH | G29: 0 | H29: 6 | M29: =G29+I29+K29 -> 0 | N29: =(M29*100)/$P$8 -> 0 | O29: =H29+J29+L29 -> 6 | P29: =IF(AVERAGE(H29,J29,L29)<6,(5),(ROUND(AVERAGE(H29,J29,L29),0))) -> 6 | R29: =IF(N29>20,"EXTRA","ORD") -> ORD
A30: 19 | C30: HERNANDEZ | D30: CHAVEZ | E30: DEREK | G30: 1 | H30: 6 | M30: =G30+I30+K30 -> 1 | N30: =(M30*100)/$P$8 -> 5.5555556 | O30: =H30+J30+L30 -> 6 | P30: =IF(AVERAGE(H30,J30,L30)<6,(5),(ROUND(AVERAGE(H30,J30,L30),0))) -> 6 | R30: =IF(N30>20,"EXTRA","ORD") -> ORD
B31: 20 | C31: HERNANDEZ | D31: LEDEZMA | E31: IRIARY GUADALUPE | G31: 0 | H31: 10 | M31: =G31+I31+K31 -> 0 | N31: =(M31*100)/$P$8 -> 0 | O31: =H31+J31+L31 -> 10 | P31: =IF(AVERAGE(H31,J31,L31)<6,(5),(ROUND(AVERAGE(H31,J31,L31),0))) -> 10 | R31: =IF(N31>20,"EXTRA","ORD") -> ORD
A32: 21 | C32: JARALEÑO | D32: BLANCO | E32: IRVING GAEL | G32: 0 | H32: 9 | M32: =G32+I32+K32 -> 0 | N32: =(M32*100)/$P$8 -> 0 | O32: =H32+J32+L32 -> 9 | P32: =IF(AVERAGE(H32,J32,L32)<6,(5),(ROUND(AVERAGE(H32,J32,L32),0))) -> 9 | R32: =IF(N32>20,"EXTRA","ORD") -> ORD
B33: 22 | C33: LIMA | D33: ACEVES | E33: DAFNE ERIN | G33: 0 | H33: 6 | M33: =G33+I33+K33 -> 0 | N33: =(M33*100)/$P$8 -> 0 | O33: =H33+J33+L33 -> 6 | P33: =IF(AVERAGE(H33,J33,L33)<6,(5),(ROUND(AVERAGE(H33,J33,L33),0))) -> 6 | R33: =IF(N33>20,"EXTRA","ORD") -> ORD
B34: 23 | C34: LOPEZ | D34: GODINEZ | E34: AZUL XIMENA | G34: 1 | H34: 5 | M34: =G34+I34+K34 -> 1 | N34: =(M34*100)/$P$8 -> 5.5555556 | O34: =H34+J34+L34 -> 5 | P34: =IF(AVERAGE(H34,J34,L34)<6,(5),(ROUND(AVERAGE(H34,J34,L34),0))) -> 5 | R34: =IF(N34>20,"EXTRA","ORD") -> ORD
A35: 24 | C35: LUGO | D35: GONZALEZ | E35: LUIS DARIO | G35: 2 | H35: 7 | M35: =G35+I35+K35 -> 2 | N35: =(M35*100)/$P$8 -> 11.111111 | O35: =H35+J35+L35 -> 7 | P35: =IF(AVERAGE(H35,J35,L35)<6,(5),(ROUND(AVERAGE(H35,J35,L35),0))) -> 7 | R35: =IF(N35>20,"EXTRA","ORD") -> ORD
A36: 25 | C36: MARQUEZ | D36: YAÑEZ | E36: ISRAEL | G36: 0 | H36: 7 | M36: =G36+I36+K36 -> 0 | N36: =(M36*100)/$P$8 -> 0 | O36: =H36+J36+L36 -> 7 | P36: =IF(AVERAGE(H36,J36,L36)<6,(5),(ROUND(AVERAGE(H36,J36,L36),0))) -> 7 | R36: =IF(N36>20,"EXTRA","ORD") -> ORD
A37: 26 | C37: MARTINEZ | D37: MONTERO | E37: ANGEL YAIR | G37: 0 | H37: 7 | M37: =G37+I37+K37 -> 0 | N37: =(M37*100)/$P$8 -> 0 | O37: =H37+J37+L37 -> 7 | P37: =IF(AVERAGE(H37,J37,L37)<6,(5),(ROUND(AVERAGE(H37,J37,L37),0))) -> 7 | R37: =IF(N37>20,"EXTRA","ORD") -> ORD
A38: 27 | C38: MENDOZA | D38: CRUZ | E38: IAN YAMIL | G38: 0 | H38: 7 | M38: =G38+I38+K38 -> 0 | N38: =(M38*100)/$P$8 -> 0 | O38: =H38+J38+L38 -> 7 | P38: =IF(AVERAGE(H38,J38,L38)<6,(5),(ROUND(AVERAGE(H38,J38,L38),0))) -> 7 | R38: =IF(N38>20,"EXTRA","ORD") -> ORD
B39: 28 | C39: MONTOYA | D39: LOPEZ | E39: WENDY MARIEL | G39: 0 | H39: 8 | M39: =G39+I39+K39 -> 0 | N39: =(M39*100)/$P$8 -> 0 | O39: =H39+J39+L39 -> 8 | P39: =IF(AVERAGE(H39,J39,L39)<6,(5),(ROUND(AVERAGE(H39,J39,L39),0))) -> 8 | R39: =IF(N39>20,"EXTRA","ORD") -> ORD
B40: 29 | C40: MORA | D40: SORIANO | E40: GIANNINA | G40: 0 | H40: 8 | M40: =G40+I40+K40 -> 0 | N40: =(M40*100)/$P$8 -> 0 | O40: =H40+J40+L40 -> 8 | P40: =IF(AVERAGE(H40,J40,L40)<6,(5),(ROUND(AVERAGE(H40,J40,L40),0))) -> 8 | R40: =IF(N40>20,"EXTRA","ORD") -> ORD
...

Sheet 3-1 organismos
O1: HORAS IMPARTIDAS
C2: ORIENTADORA | D2: NEFATLÍ MARGARITA MORLÁN ORTÍZ | H2: ESCUELA PREPARATORIA OFICIAL NÚM.67 | O2: Febrero
H3: “2026. Año del Humanismo Mexicano en el Estado de México ”. | O3: Marzo
H4: CICLO ESCOLAR: 2025 -2026 | O4: Abril
E5: TURNO : | G5: MATUTINO | J5: Grado | K5: 3° | L5: Grupo | M5: 1 | O5: Mayo | P5: 9
E6: PROFESOR(A): | K6: UAC | L6: ORGANISMOS | O6: Junio
G7: HOMBRES | H7: =A59 -> 23 | O7: Julio | P7: 3
G8: MUJERES | H8: =B59 -> 22 | O8: TOTAL | P8: =SUM(P2:P7) -> 12
G9: TOTAL | H9: =H7+H8 -> 45
A10: N | B10: P | C10: NOMBRE DEL ALUMNO | G10: PRIMERA EVALUACIÓN | I10: SEGUNDA EVALUACIÓN | K10: TERCERA EVALUACIÓN | M10: EVALUACIÓN FINAL
A11: H | B11: M | G11: FALTAS | H11: CALIF. | I11: FALTAS | J11: CALIF. | K11: FALTAS | L11: CALIF. | M11: TOT. DE FALTAS | N11: % FALTAS | O11: TOTAL DE PUNTOS | P11: CALIF. FINAL | Q11: FIRMA DEL ALUMNO | R11: ESTATUS
A12: 1 | C12: ABARCA | D12: MELENDEZ | E12: ANDRES SAID | G12: 0 | H12: 7 | M12: =G12+I12+K12 -> 0 | N12: =(M12*100)/$P$8 -> 0 | O12: =H12+J12+L12 -> 7 | P12: =IF(AVERAGE(H12,J12,L12)<6,(5),(ROUND(AVERAGE(H12,J12,L12),0))) -> 7 | R12: =IF(N12>20,"EXTRA","ORD") -> ORD
B13: 2 | C13: ALCANTARA | D13: BELTRAN | E13: JESSICA | G13: 0 | H13: 10 | M13: =G13+I13+K13 -> 0 | N13: =(M13*100)/$P$8 -> 0 | O13: =H13+J13+L13 -> 10 | P13: =IF(AVERAGE(H13,J13,L13)<6,(5),(ROUND(AVERAGE(H13,J13,L13),0))) -> 10 | R13: =IF(N13>20,"EXTRA","ORD") -> ORD
A14: 3 | C14: ALVAREZ | D14: BERNALDO | E14: ANGEL ALBERTO | G14: 0 | H14: 10 | M14: =G14+I14+K14 -> 0 | N14: =(M14*100)/$P$8 -> 0 | O14: =H14+J14+L14 -> 10 | P14: =IF(AVERAGE(H14,J14,L14)<6,(5),(ROUND(AVERAGE(H14,J14,L14),0))) -> 10 | R14: =IF(N14>20,"EXTRA","ORD") -> ORD
B15: 4 | C15: ALVAREZ | D15: GONZALEZ | E15: ALLISON JADE | G15: 0 | H15: 6 | M15: =G15+I15+K15 -> 0 | N15: =(M15*100)/$P$8 -> 0 | O15: =H15+J15+L15 -> 6 | P15: =IF(AVERAGE(H15,J15,L15)<6,(5),(ROUND(AVERAGE(H15,J15,L15),0))) -> 6 | R15: =IF(N15>20,"EXTRA","ORD") -> ORD
A16: 5 | C16: ANZALDO | D16: MARTINEZ | E16: NAYONEL YAEL | G16: 0 | H16: 8 | M16: =G16+I16+K16 -> 0 | N16: =(M16*100)/$P$8 -> 0 | O16: =H16+J16+L16 -> 8 | P16: =IF(AVERAGE(H16,J16,L16)<6,(5),(ROUND(AVERAGE(H16,J16,L16),0))) -> 8 | R16: =IF(N16>20,"EXTRA","ORD") -> ORD
A17: 6 | C17: AVILA | D17: ESCAMILLA | E17: JUSTIN YAHEL | G17: 21 | H17: 8 | M17: =G17+I17+K17 -> 21 | N17: =(M17*100)/$P$8 -> 175 | O17: =H17+J17+L17 -> 8 | P17: =IF(AVERAGE(H17,J17,L17)<6,(5),(ROUND(AVERAGE(H17,J17,L17),0))) -> 8 | R17: =IF(N17>20,"EXTRA","ORD") -> EXTRA
A18: 7 | C18: AYALA | D18: LARA | E18: ISAAC | G18: 0 | H18: 8 | M18: =G18+I18+K18 -> 0 | N18: =(M18*100)/$P$8 -> 0 | O18: =H18+J18+L18 -> 8 | P18: =IF(AVERAGE(H18,J18,L18)<6,(5),(ROUND(AVERAGE(H18,J18,L18),0))) -> 8 | R18: =IF(N18>20,"EXTRA","ORD") -> ORD
B19: 8 | C19: BATRES | D19: CERDA | E19: MARIA DEL PILAR | G19: 0 | H19: 10 | M19: =G19+I19+K19 -> 0 | N19: =(M19*100)/$P$8 -> 0 | O19: =H19+J19+L19 -> 10 | P19: =IF(AVERAGE(H19,J19,L19)<6,(5),(ROUND(AVERAGE(H19,J19,L19),0))) -> 10 | R19: =IF(N19>20,"EXTRA","ORD") -> ORD
A20: 9 | C20: BONILLA | D20: TREJO | E20: FRANCISCO TONATIUH | G20: 0 | H20: 5 | M20: =G20+I20+K20 -> 0 | N20: =(M20*100)/$P$8 -> 0 | O20: =H20+J20+L20 -> 5 | P20: =IF(AVERAGE(H20,J20,L20)<6,(5),(ROUND(AVERAGE(H20,J20,L20),0))) -> 5 | R20: =IF(N20>20,"EXTRA","ORD") -> ORD
A21: 10 | C21: CABRERA | D21: MARTINEZ | E21: JESUS ADRIAN | G21: 0 | H21: 10 | M21: =G21+I21+K21 -> 0 | N21: =(M21*100)/$P$8 -> 0 | O21: =H21+J21+L21 -> 10 | P21: =IF(AVERAGE(H21,J21,L21)<6,(5),(ROUND(AVERAGE(H21,J21,L21),0))) -> 10 | R21: =IF(N21>20,"EXTRA","ORD") -> ORD
B22: 11 | C22: CARDONA | D22: ZARATE | E22: JULIA EMILY | G22: 0 | H22: 8 | M22: =G22+I22+K22 -> 0 | N22: =(M22*100)/$P$8 -> 0 | O22: =H22+J22+L22 -> 8 | P22: =IF(AVERAGE(H22,J22,L22)<6,(5),(ROUND(AVERAGE(H22,J22,L22),0))) -> 8 | R22: =IF(N22>20,"EXTRA","ORD") -> ORD
A23: 12 | C23: CASALES | D23: LORANCA | E23: EDSON | G23: 0 | H23: 6 | M23: =G23+I23+K23 -> 0 | N23: =(M23*100)/$P$8 -> 0 | O23: =H23+J23+L23 -> 6 | P23: =IF(AVERAGE(H23,J23,L23)<6,(5),(ROUND(AVERAGE(H23,J23,L23),0))) -> 6 | R23: =IF(N23>20,"EXTRA","ORD") -> ORD
A24: 13 | C24: CRUZ | D24: GARCÍA | E24: PEDRO YASHIR | G24: 0 | H24: 5 | M24: =G24+I24+K24 -> 0 | N24: =(M24*100)/$P$8 -> 0 | O24: =H24+J24+L24 -> 5 | P24: =IF(AVERAGE(H24,J24,L24)<6,(5),(ROUND(AVERAGE(H24,J24,L24),0))) -> 5 | R24: =IF(N24>20,"EXTRA","ORD") -> ORD
B25: 14 | C25: FUENTES | D25: VALADEZ | E25: ALEXIA DANNAE | G25: 0 | H25: 10 | M25: =G25+I25+K25 -> 0 | N25: =(M25*100)/$P$8 -> 0 | O25: =H25+J25+L25 -> 10 | P25: =IF(AVERAGE(H25,J25,L25)<6,(5),(ROUND(AVERAGE(H25,J25,L25),0))) -> 10 | R25: =IF(N25>20,"EXTRA","ORD") -> ORD
A26: 15 | C26: GARCIA | D26: RANGEL | E26: ADRIAN | G26: 0 | H26: 10 | M26: =G26+I26+K26 -> 0 | N26: =(M26*100)/$P$8 -> 0 | O26: =H26+J26+L26 -> 10 | P26: =IF(AVERAGE(H26,J26,L26)<6,(5),(ROUND(AVERAGE(H26,J26,L26),0))) -> 10 | R26: =IF(N26>20,"EXTRA","ORD") -> ORD
B27: 16 | C27: GOMEZ | D27: ARREDONDO | E27: AMERICA NAOMI | G27: 0 | H27: 5 | M27: =G27+I27+K27 -> 0 | N27: =(M27*100)/$P$8 -> 0 | O27: =H27+J27+L27 -> 5 | P27: =IF(AVERAGE(H27,J27,L27)<6,(5),(ROUND(AVERAGE(H27,J27,L27),0))) -> 5 | R27: =IF(N27>20,"EXTRA","ORD") -> ORD
B28: 17 | C28: GOMEZ | D28: VAZQUEZ | E28: BIBIANA | G28: 0 | H28: 7 | M28: =G28+I28+K28 -> 0 | N28: =(M28*100)/$P$8 -> 0 | O28: =H28+J28+L28 -> 7 | P28: =IF(AVERAGE(H28,J28,L28)<6,(5),(ROUND(AVERAGE(H28,J28,L28),0))) -> 7 | R28: =IF(N28>20,"EXTRA","ORD") -> ORD
B29: 18 | C29: GONZALEZ | D29: REYNA | E29: PAULA EDITH | G29: 0 | H29: 6 | M29: =G29+I29+K29 -> 0 | N29: =(M29*100)/$P$8 -> 0 | O29: =H29+J29+L29 -> 6 | P29: =IF(AVERAGE(H29,J29,L29)<6,(5),(ROUND(AVERAGE(H29,J29,L29),0))) -> 6 | R29: =IF(N29>20,"EXTRA","ORD") -> ORD
A30: 19 | C30: HERNANDEZ | D30: CHAVEZ | E30: DEREK | G30: 1 | H30: 6 | M30: =G30+I30+K30 -> 1 | N30: =(M30*100)/$P$8 -> 8.3333333 | O30: =H30+J30+L30 -> 6 | P30: =IF(AVERAGE(H30,J30,L30)<6,(5),(ROUND(AVERAGE(H30,J30,L30),0))) -> 6 | R30: =IF(N30>20,"EXTRA","ORD") -> ORD
B31: 20 | C31: HERNANDEZ | D31: LEDEZMA | E31: IRIARY GUADALUPE | G31: 0 | H31: 10 | M31: =G31+I31+K31 -> 0 | N31: =(M31*100)/$P$8 -> 0 | O31: =H31+J31+L31 -> 10 | P31: =IF(AVERAGE(H31,J31,L31)<6,(5),(ROUND(AVERAGE(H31,J31,L31),0))) -> 10 | R31: =IF(N31>20,"EXTRA","ORD") -> ORD
A32: 21 | C32: JARALEÑO | D32: BLANCO | E32: IRVING GAEL | G32: 0 | H32: 9 | M32: =G32+I32+K32 -> 0 | N32: =(M32*100)/$P$8 -> 0 | O32: =H32+J32+L32 -> 9 | P32: =IF(AVERAGE(H32,J32,L32)<6,(5),(ROUND(AVERAGE(H32,J32,L32),0))) -> 9 | R32: =IF(N32>20,"EXTRA","ORD") -> ORD
B33: 22 | C33: LIMA | D33: ACEVES | E33: DAFNE ERIN | G33: 0 | H33: 6 | M33: =G33+I33+K33 -> 0 | N33: =(M33*100)/$P$8 -> 0 | O33: =H33+J33+L33 -> 6 | P33: =IF(AVERAGE(H33,J33,L33)<6,(5),(ROUND(AVERAGE(H33,J33,L33),0))) -> 6 | R33: =IF(N33>20,"EXTRA","ORD") -> ORD
B34: 23 | C34: LOPEZ | D34: GODINEZ | E34: AZUL XIMENA | G34: 1 | H34: 5 | M34: =G34+I34+K34 -> 1 | N34: =(M34*100)/$P$8 -> 8.3333333 | O34: =H34+J34+L34 -> 5 | P34: =IF(AVERAGE(H34,J34,L34)<6,(5),(ROUND(AVERAGE(H34,J34,L34),0))) -> 5 | R34: =IF(N34>20,"EXTRA","ORD") -> ORD
A35: 24 | C35: LUGO | D35: GONZALEZ | E35: LUIS DARIO | G35: 2 | H35: 7 | M35: =G35+I35+K35 -> 2 | N35: =(M35*100)/$P$8 -> 16.666667 | O35: =H35+J35+L35 -> 7 | P35: =IF(AVERAGE(H35,J35,L35)<6,(5),(ROUND(AVERAGE(H35,J35,L35),0))) -> 7 | R35: =IF(N35>20,"EXTRA","ORD") -> ORD
A36: 25 | C36: MARQUEZ | D36: YAÑEZ | E36: ISRAEL | G36: 0 | H36: 7 | M36: =G36+I36+K36 -> 0 | N36: =(M36*100)/$P$8 -> 0 | O36: =H36+J36+L36 -> 7 | P36: =IF(AVERAGE(H36,J36,L36)<6,(5),(ROUND(AVERAGE(H36,J36,L36),0))) -> 7 | R36: =IF(N36>20,"EXTRA","ORD") -> ORD
A37: 26 | C37: MARTINEZ | D37: MONTERO | E37: ANGEL YAIR | G37: 0 | H37: 7 | M37: =G37+I37+K37 -> 0 | N37: =(M37*100)/$P$8 -> 0 | O37: =H37+J37+L37 -> 7 | P37: =IF(AVERAGE(H37,J37,L37)<6,(5),(ROUND(AVERAGE(H37,J37,L37),0))) -> 7 | R37: =IF(N37>20,"EXTRA","ORD") -> ORD
A38: 27 | C38: MENDOZA | D38: CRUZ | E38: IAN YAMIL | G38: 0 | H38: 7 | M38: =G38+I38+K38 -> 0 | N38: =(M38*100)/$P$8 -> 0 | O38: =H38+J38+L38 -> 7 | P38: =IF(AVERAGE(H38,J38,L38)<6,(5),(ROUND(AVERAGE(H38,J38,L38),0))) -> 7 | R38: =IF(N38>20,"EXTRA","ORD") -> ORD
B39: 28 | C39: MONTOYA | D39: LOPEZ | E39: WENDY MARIEL | G39: 0 | H39: 8 | M39: =G39+I39+K39 -> 0 | N39: =(M39*100)/$P$8 -> 0 | O39: =H39+J39+L39 -> 8 | P39: =IF(AVERAGE(H39,J39,L39)<6,(5),(ROUND(AVERAGE(H39,J39,L39),0))) -> 8 | R39: =IF(N39>20,"EXTRA","ORD") -> ORD
B40: 29 | C40: MORA | D40: SORIANO | E40: GIANNINA | G40: 0 | H40: 8 | M40: =G40+I40+K40 -> 0 | N40: =(M40*100)/$P$8 -> 0 | O40: =H40+J40+L40 -> 8 | P40: =IF(AVERAGE(H40,J40,L40)<6,(5),(ROUND(AVERAGE(H40,J40,L40),0))) -> 8 | R40: =IF(N40>20,"EXTRA","ORD") -> ORD
...

Sheet 3-1 temas selectos de filosofia
O1: HORAS IMPARTIDAS
C2: ORIENTADORA | D2: NEFATLÍ MARGARITA MORLÁN ORTÍZ | H2: ESCUELA PREPARATORIA OFICIAL NÚM.67 | O2: Febrero
H3: “2026. Año del Humanismo Mexicano en el Estado de México ”. | O3: Marzo | P3: 12
H4: CICLO ESCOLAR: 2025 -2026 | O4: Abril
E5: TURNO : | G5: MATUTINO | J5: Grado | K5: 3° | L5: Grupo | M5: 1 | O5: Mayo
E6: PROFESOR(A): | K6: UAC | L6: TEMAS SELECTOS DE FILOSOFÍA | O6: Junio
G7: HOMBRES | H7: =A59 -> 23 | O7: Julio | P7: 3
G8: MUJERES | H8: =B59 -> 22 | O8: TOTAL | P8: =SUM(P2:P7) -> 15
G9: TOTAL | H9: =H7+H8 -> 45
A10: N | B10: P | C10: NOMBRE DEL ALUMNO | G10: PRIMERA EVALUACIÓN | I10: SEGUNDA EVALUACIÓN | K10: TERCERA EVALUACIÓN | M10: EVALUACIÓN FINAL
A11: H | B11: M | G11: FALTAS | H11: CALIF. | I11: FALTAS | J11: CALIF. | K11: FALTAS | L11: CALIF. | M11: TOT. DE FALTAS | N11: % FALTAS | O11: TOTAL DE PUNTOS | P11: CALIF. FINAL | Q11: FIRMA DEL ALUMNO | R11: ESTATUS
A12: 1 | C12: ABARCA | D12: MELENDEZ | E12: ANDRES SAID | G12: 0 | H12: 7 | M12: =G12+I12+K12 -> 0 | N12: =(M12*100)/$P$8 -> 0 | O12: =H12+J12+L12 -> 7 | P12: =IF(AVERAGE(H12,J12,L12)<6,(5),(ROUND(AVERAGE(H12,J12,L12),0))) -> 7 | R12: =IF(N12>20,"EXTRA","ORD") -> ORD
B13: 2 | C13: ALCANTARA | D13: BELTRAN | E13: JESSICA | G13: 0 | H13: 10 | M13: =G13+I13+K13 -> 0 | N13: =(M13*100)/$P$8 -> 0 | O13: =H13+J13+L13 -> 10 | P13: =IF(AVERAGE(H13,J13,L13)<6,(5),(ROUND(AVERAGE(H13,J13,L13),0))) -> 10 | R13: =IF(N13>20,"EXTRA","ORD") -> ORD
A14: 3 | C14: ALVAREZ | D14: BERNALDO | E14: ANGEL ALBERTO | G14: 0 | H14: 10 | M14: =G14+I14+K14 -> 0 | N14: =(M14*100)/$P$8 -> 0 | O14: =H14+J14+L14 -> 10 | P14: =IF(AVERAGE(H14,J14,L14)<6,(5),(ROUND(AVERAGE(H14,J14,L14),0))) -> 10 | R14: =IF(N14>20,"EXTRA","ORD") -> ORD
B15: 4 | C15: ALVAREZ | D15: GONZALEZ | E15: ALLISON JADE | G15: 0 | H15: 6 | M15: =G15+I15+K15 -> 0 | N15: =(M15*100)/$P$8 -> 0 | O15: =H15+J15+L15 -> 6 | P15: =IF(AVERAGE(H15,J15,L15)<6,(5),(ROUND(AVERAGE(H15,J15,L15),0))) -> 6 | R15: =IF(N15>20,"EXTRA","ORD") -> ORD
A16: 5 | C16: ANZALDO | D16: MARTINEZ | E16: NAYONEL YAEL | G16: 0 | H16: 8 | M16: =G16+I16+K16 -> 0 | N16: =(M16*100)/$P$8 -> 0 | O16: =H16+J16+L16 -> 8 | P16: =IF(AVERAGE(H16,J16,L16)<6,(5),(ROUND(AVERAGE(H16,J16,L16),0))) -> 8 | R16: =IF(N16>20,"EXTRA","ORD") -> ORD
A17: 6 | C17: AVILA | D17: ESCAMILLA | E17: JUSTIN YAHEL | G17: 21 | H17: 8 | M17: =G17+I17+K17 -> 21 | N17: =(M17*100)/$P$8 -> 140 | O17: =H17+J17+L17 -> 8 | P17: =IF(AVERAGE(H17,J17,L17)<6,(5),(ROUND(AVERAGE(H17,J17,L17),0))) -> 8 | R17: =IF(N17>20,"EXTRA","ORD") -> EXTRA
A18: 7 | C18: AYALA | D18: LARA | E18: ISAAC | G18: 0 | H18: 8 | M18: =G18+I18+K18 -> 0 | N18: =(M18*100)/$P$8 -> 0 | O18: =H18+J18+L18 -> 8 | P18: =IF(AVERAGE(H18,J18,L18)<6,(5),(ROUND(AVERAGE(H18,J18,L18),0))) -> 8 | R18: =IF(N18>20,"EXTRA","ORD") -> ORD
B19: 8 | C19: BATRES | D19: CERDA | E19: MARIA DEL PILAR | G19: 0 | H19: 10 | M19: =G19+I19+K19 -> 0 | N19: =(M19*100)/$P$8 -> 0 | O19: =H19+J19+L19 -> 10 | P19: =IF(AVERAGE(H19,J19,L19)<6,(5),(ROUND(AVERAGE(H19,J19,L19),0))) -> 10 | R19: =IF(N19>20,"EXTRA","ORD") -> ORD
A20: 9 | C20: BONILLA | D20: TREJO | E20: FRANCISCO TONATIUH | G20: 0 | H20: 5 | M20: =G20+I20+K20 -> 0 | N20: =(M20*100)/$P$8 -> 0 | O20: =H20+J20+L20 -> 5 | P20: =IF(AVERAGE(H20,J20,L20)<6,(5),(ROUND(AVERAGE(H20,J20,L20),0))) -> 5 | R20: =IF(N20>20,"EXTRA","ORD") -> ORD
A21: 10 | C21: CABRERA | D21: MARTINEZ | E21: JESUS ADRIAN | G21: 0 | H21: 10 | M21: =G21+I21+K21 -> 0 | N21: =(M21*100)/$P$8 -> 0 | O21: =H21+J21+L21 -> 10 | P21: =IF(AVERAGE(H21,J21,L21)<6,(5),(ROUND(AVERAGE(H21,J21,L21),0))) -> 10 | R21: =IF(N21>20,"EXTRA","ORD") -> ORD
B22: 11 | C22: CARDONA | D22: ZARATE | E22: JULIA EMILY | G22: 0 | H22: 8 | M22: =G22+I22+K22 -> 0 | N22: =(M22*100)/$P$8 -> 0 | O22: =H22+J22+L22 -> 8 | P22: =IF(AVERAGE(H22,J22,L22)<6,(5),(ROUND(AVERAGE(H22,J22,L22),0))) -> 8 | R22: =IF(N22>20,"EXTRA","ORD") -> ORD
A23: 12 | C23: CASALES | D23: LORANCA | E23: EDSON | G23: 0 | H23: 6 | M23: =G23+I23+K23 -> 0 | N23: =(M23*100)/$P$8 -> 0 | O23: =H23+J23+L23 -> 6 | P23: =IF(AVERAGE(H23,J23,L23)<6,(5),(ROUND(AVERAGE(H23,J23,L23),0))) -> 6 | R23: =IF(N23>20,"EXTRA","ORD") -> ORD
A24: 13 | C24: CRUZ | D24: GARCÍA | E24: PEDRO YASHIR | G24: 0 | H24: 5 | M24: =G24+I24+K24 -> 0 | N24: =(M24*100)/$P$8 -> 0 | O24: =H24+J24+L24 -> 5 | P24: =IF(AVERAGE(H24,J24,L24)<6,(5),(ROUND(AVERAGE(H24,J24,L24),0))) -> 5 | R24: =IF(N24>20,"EXTRA","ORD") -> ORD
B25: 14 | C25: FUENTES | D25: VALADEZ | E25: ALEXIA DANNAE | G25: 0 | H25: 10 | M25: =G25+I25+K25 -> 0 | N25: =(M25*100)/$P$8 -> 0 | O25: =H25+J25+L25 -> 10 | P25: =IF(AVERAGE(H25,J25,L25)<6,(5),(ROUND(AVERAGE(H25,J25,L25),0))) -> 10 | R25: =IF(N25>20,"EXTRA","ORD") -> ORD
A26: 15 | C26: GARCIA | D26: RANGEL | E26: ADRIAN | G26: 0 | H26: 10 | M26: =G26+I26+K26 -> 0 | N26: =(M26*100)/$P$8 -> 0 | O26: =H26+J26+L26 -> 10 | P26: =IF(AVERAGE(H26,J26,L26)<6,(5),(ROUND(AVERAGE(H26,J26,L26),0))) -> 10 | R26: =IF(N26>20,"EXTRA","ORD") -> ORD
B27: 16 | C27: GOMEZ | D27: ARREDONDO | E27: AMERICA NAOMI | G27: 0 | H27: 5 | M27: =G27+I27+K27 -> 0 | N27: =(M27*100)/$P$8 -> 0 | O27: =H27+J27+L27 -> 5 | P27: =IF(AVERAGE(H27,J27,L27)<6,(5),(ROUND(AVERAGE(H27,J27,L27),0))) -> 5 | R27: =IF(N27>20,"EXTRA","ORD") -> ORD
B28: 17 | C28: GOMEZ | D28: VAZQUEZ | E28: BIBIANA | G28: 0 | H28: 7 | M28: =G28+I28+K28 -> 0 | N28: =(M28*100)/$P$8 -> 0 | O28: =H28+J28+L28 -> 7 | P28: =IF(AVERAGE(H28,J28,L28)<6,(5),(ROUND(AVERAGE(H28,J28,L28),0))) -> 7 | R28: =IF(N28>20,"EXTRA","ORD") -> ORD
B29: 18 | C29: GONZALEZ | D29: REYNA | E29: PAULA EDITH | G29: 0 | H29: 6 | M29: =G29+I29+K29 -> 0 | N29: =(M29*100)/$P$8 -> 0 | O29: =H29+J29+L29 -> 6 | P29: =IF(AVERAGE(H29,J29,L29)<6,(5),(ROUND(AVERAGE(H29,J29,L29),0))) -> 6 | R29: =IF(N29>20,"EXTRA","ORD") -> ORD
A30: 19 | C30: HERNANDEZ | D30: CHAVEZ | E30: DEREK | G30: 1 | H30: 6 | M30: =G30+I30+K30 -> 1 | N30: =(M30*100)/$P$8 -> 6.6666667 | O30: =H30+J30+L30 -> 6 | P30: =IF(AVERAGE(H30,J30,L30)<6,(5),(ROUND(AVERAGE(H30,J30,L30),0))) -> 6 | R30: =IF(N30>20,"EXTRA","ORD") -> ORD
B31: 20 | C31: HERNANDEZ | D31: LEDEZMA | E31: IRIARY GUADALUPE | G31: 0 | H31: 10 | M31: =G31+I31+K31 -> 0 | N31: =(M31*100)/$P$8 -> 0 | O31: =H31+J31+L31 -> 10 | P31: =IF(AVERAGE(H31,J31,L31)<6,(5),(ROUND(AVERAGE(H31,J31,L31),0))) -> 10 | R31: =IF(N31>20,"EXTRA","ORD") -> ORD
A32: 21 | C32: JARALEÑO | D32: BLANCO | E32: IRVING GAEL | G32: 0 | H32: 9 | M32: =G32+I32+K32 -> 0 | N32: =(M32*100)/$P$8 -> 0 | O32: =H32+J32+L32 -> 9 | P32: =IF(AVERAGE(H32,J32,L32)<6,(5),(ROUND(AVERAGE(H32,J32,L32),0))) -> 9 | R32: =IF(N32>20,"EXTRA","ORD") -> ORD
B33: 22 | C33: LIMA | D33: ACEVES | E33: DAFNE ERIN | G33: 0 | H33: 6 | M33: =G33+I33+K33 -> 0 | N33: =(M33*100)/$P$8 -> 0 | O33: =H33+J33+L33 -> 6 | P33: =IF(AVERAGE(H33,J33,L33)<6,(5),(ROUND(AVERAGE(H33,J33,L33),0))) -> 6 | R33: =IF(N33>20,"EXTRA","ORD") -> ORD
B34: 23 | C34: LOPEZ | D34: GODINEZ | E34: AZUL XIMENA | G34: 1 | H34: 5 | M34: =G34+I34+K34 -> 1 | N34: =(M34*100)/$P$8 -> 6.6666667 | O34: =H34+J34+L34 -> 5 | P34: =IF(AVERAGE(H34,J34,L34)<6,(5),(ROUND(AVERAGE(H34,J34,L34),0))) -> 5 | R34: =IF(N34>20,"EXTRA","ORD") -> ORD
A35: 24 | C35: LUGO | D35: GONZALEZ | E35: LUIS DARIO | G35: 2 | H35: 7 | M35: =G35+I35+K35 -> 2 | N35: =(M35*100)/$P$8 -> 13.333333 | O35: =H35+J35+L35 -> 7 | P35: =IF(AVERAGE(H35,J35,L35)<6,(5),(ROUND(AVERAGE(H35,J35,L35),0))) -> 7 | R35: =IF(N35>20,"EXTRA","ORD") -> ORD
A36: 25 | C36: MARQUEZ | D36: YAÑEZ | E36: ISRAEL | G36: 0 | H36: 7 | M36: =G36+I36+K36 -> 0 | N36: =(M36*100)/$P$8 -> 0 | O36: =H36+J36+L36 -> 7 | P36: =IF(AVERAGE(H36,J36,L36)<6,(5),(ROUND(AVERAGE(H36,J36,L36),0))) -> 7 | R36: =IF(N36>20,"EXTRA","ORD") -> ORD
A37: 26 | C37: MARTINEZ | D37: MONTERO | E37: ANGEL YAIR | G37: 0 | H37: 7 | M37: =G37+I37+K37 -> 0 | N37: =(M37*100)/$P$8 -> 0 | O37: =H37+J37+L37 -> 7 | P37: =IF(AVERAGE(H37,J37,L37)<6,(5),(ROUND(AVERAGE(H37,J37,L37),0))) -> 7 | R37: =IF(N37>20,"EXTRA","ORD") -> ORD
A38: 27 | C38: MENDOZA | D38: CRUZ | E38: IAN YAMIL | G38: 0 | H38: 7 | M38: =G38+I38+K38 -> 0 | N38: =(M38*100)/$P$8 -> 0 | O38: =H38+J38+L38 -> 7 | P38: =IF(AVERAGE(H38,J38,L38)<6,(5),(ROUND(AVERAGE(H38,J38,L38),0))) -> 7 | R38: =IF(N38>20,"EXTRA","ORD") -> ORD
B39: 28 | C39: MONTOYA | D39: LOPEZ | E39: WENDY MARIEL | G39: 0 | H39: 8 | M39: =G39+I39+K39 -> 0 | N39: =(M39*100)/$P$8 -> 0 | O39: =H39+J39+L39 -> 8 | P39: =IF(AVERAGE(H39,J39,L39)<6,(5),(ROUND(AVERAGE(H39,J39,L39),0))) -> 8 | R39: =IF(N39>20,"EXTRA","ORD") -> ORD
B40: 29 | C40: MORA | D40: SORIANO | E40: GIANNINA | G40: 0 | H40: 8 | M40: =G40+I40+K40 -> 0 | N40: =(M40*100)/$P$8 -> 0 | O40: =H40+J40+L40 -> 8 | P40: =IF(AVERAGE(H40,J40,L40)<6,(5),(ROUND(AVERAGE(H40,J40,L40),0))) -> 8 | R40: =IF(N40>20,"EXTRA","ORD") -> ORD
...

Sheet 3-1 diseño digital
O1: HORAS IMPARTIDAS
C2: ORIENTADORA | D2: NEFATLÍ MARGARITA MORLÁN ORTÍZ | H2: ESCUELA PREPARATORIA OFICIAL NÚM.67 | O2: Febrero
H3: “2026. Año del Humanismo Mexicano en el Estado de México ”. | O3: Marzo | P3: 7
H4: CICLO ESCOLAR: 2025 -2026 | O4: Abril
E5: TURNO : | G5: MATUTINO | J5: Grado | K5: 3° | L5: Grupo | M5: 1 | O5: Mayo
E6: PROFESOR(A): | K6: UAC | L6: DISEÑO DIGITAL | O6: Junio
G7: HOMBRES | H7: =A59 -> 23 | O7: Julio | P7: 3
G8: MUJERES | H8: =B59 -> 22 | O8: TOTAL | P8: =SUM(P2:P7) -> 10
G9: TOTAL | H9: =H7+H8 -> 45
A10: N | B10: P | C10: NOMBRE DEL ALUMNO | G10: PRIMERA EVALUACIÓN | I10: SEGUNDA EVALUACIÓN | K10: TERCERA EVALUACIÓN | M10: EVALUACIÓN FINAL
A11: H | B11: M | G11: FALTAS | H11: CALIF. | I11: FALTAS | J11: CALIF. | K11: FALTAS | L11: CALIF. | M11: TOT. DE FALTAS | N11: % FALTAS | O11: TOTAL DE PUNTOS | P11: CALIF. FINAL | Q11: FIRMA DEL ALUMNO | R11: ESTATUS
A12: 1 | C12: ABARCA | D12: MELENDEZ | E12: ANDRES SAID | G12: 0 | H12: 7 | M12: =G12+I12+K12 -> 0 | N12: =(M12*100)/$P$8 -> 0 | O12: =H12+J12+L12 -> 7 | P12: =IF(AVERAGE(H12,J12,L12)<6,(5),(ROUND(AVERAGE(H12,J12,L12),0))) -> 7 | R12: =IF(N12>20,"EXTRA","ORD") -> ORD
B13: 2 | C13: ALCANTARA | D13: BELTRAN | E13: JESSICA | G13: 0 | H13: 10 | M13: =G13+I13+K13 -> 0 | N13: =(M13*100)/$P$8 -> 0 | O13: =H13+J13+L13 -> 10 | P13: =IF(AVERAGE(H13,J13,L13)<6,(5),(ROUND(AVERAGE(H13,J13,L13),0))) -> 10 | R13: =IF(N13>20,"EXTRA","ORD") -> ORD
A14: 3 | C14: ALVAREZ | D14: BERNALDO | E14: ANGEL ALBERTO | G14: 0 | H14: 10 | M14: =G14+I14+K14 -> 0 | N14: =(M14*100)/$P$8 -> 0 | O14: =H14+J14+L14 -> 10 | P14: =IF(AVERAGE(H14,J14,L14)<6,(5),(ROUND(AVERAGE(H14,J14,L14),0))) -> 10 | R14: =IF(N14>20,"EXTRA","ORD") -> ORD
B15: 4 | C15: ALVAREZ | D15: GONZALEZ | E15: ALLISON JADE | G15: 0 | H15: 6 | M15: =G15+I15+K15 -> 0 | N15: =(M15*100)/$P$8 -> 0 | O15: =H15+J15+L15 -> 6 | P15: =IF(AVERAGE(H15,J15,L15)<6,(5),(ROUND(AVERAGE(H15,J15,L15),0))) -> 6 | R15: =IF(N15>20,"EXTRA","ORD") -> ORD
A16: 5 | C16: ANZALDO | D16: MARTINEZ | E16: NAYONEL YAEL | G16: 0 | H16: 8 | M16: =G16+I16+K16 -> 0 | N16: =(M16*100)/$P$8 -> 0 | O16: =H16+J16+L16 -> 8 | P16: =IF(AVERAGE(H16,J16,L16)<6,(5),(ROUND(AVERAGE(H16,J16,L16),0))) -> 8 | R16: =IF(N16>20,"EXTRA","ORD") -> ORD
A17: 6 | C17: AVILA | D17: ESCAMILLA | E17: JUSTIN YAHEL | G17: 21 | H17: 8 | M17: =G17+I17+K17 -> 21 | N17: =(M17*100)/$P$8 -> 210 | O17: =H17+J17+L17 -> 8 | P17: =IF(AVERAGE(H17,J17,L17)<6,(5),(ROUND(AVERAGE(H17,J17,L17),0))) -> 8 | R17: =IF(N17>20,"EXTRA","ORD") -> EXTRA
A18: 7 | C18: AYALA | D18: LARA | E18: ISAAC | G18: 0 | H18: 8 | M18: =G18+I18+K18 -> 0 | N18: =(M18*100)/$P$8 -> 0 | O18: =H18+J18+L18 -> 8 | P18: =IF(AVERAGE(H18,J18,L18)<6,(5),(ROUND(AVERAGE(H18,J18,L18),0))) -> 8 | R18: =IF(N18>20,"EXTRA","ORD") -> ORD
B19: 8 | C19: BATRES | D19: CERDA | E19: MARIA DEL PILAR | G19: 0 | H19: 10 | M19: =G19+I19+K19 -> 0 | N19: =(M19*100)/$P$8 -> 0 | O19: =H19+J19+L19 -> 10 | P19: =IF(AVERAGE(H19,J19,L19)<6,(5),(ROUND(AVERAGE(H19,J19,L19),0))) -> 10 | R19: =IF(N19>20,"EXTRA","ORD") -> ORD
A20: 9 | C20: BONILLA | D20: TREJO | E20: FRANCISCO TONATIUH | G20: 0 | H20: 5 | M20: =G20+I20+K20 -> 0 | N20: =(M20*100)/$P$8 -> 0 | O20: =H20+J20+L20 -> 5 | P20: =IF(AVERAGE(H20,J20,L20)<6,(5),(ROUND(AVERAGE(H20,J20,L20),0))) -> 5 | R20: =IF(N20>20,"EXTRA","ORD") -> ORD
A21: 10 | C21: CABRERA | D21: MARTINEZ | E21: JESUS ADRIAN | G21: 0 | H21: 10 | M21: =G21+I21+K21 -> 0 | N21: =(M21*100)/$P$8 -> 0 | O21: =H21+J21+L21 -> 10 | P21: =IF(AVERAGE(H21,J21,L21)<6,(5),(ROUND(AVERAGE(H21,J21,L21),0))) -> 10 | R21: =IF(N21>20,"EXTRA","ORD") -> ORD
B22: 11 | C22: CARDONA | D22: ZARATE | E22: JULIA EMILY | G22: 0 | H22: 8 | M22: =G22+I22+K22 -> 0 | N22: =(M22*100)/$P$8 -> 0 | O22: =H22+J22+L22 -> 8 | P22: =IF(AVERAGE(H22,J22,L22)<6,(5),(ROUND(AVERAGE(H22,J22,L22),0))) -> 8 | R22: =IF(N22>20,"EXTRA","ORD") -> ORD
A23: 12 | C23: CASALES | D23: LORANCA | E23: EDSON | G23: 0 | H23: 6 | M23: =G23+I23+K23 -> 0 | N23: =(M23*100)/$P$8 -> 0 | O23: =H23+J23+L23 -> 6 | P23: =IF(AVERAGE(H23,J23,L23)<6,(5),(ROUND(AVERAGE(H23,J23,L23),0))) -> 6 | R23: =IF(N23>20,"EXTRA","ORD") -> ORD
A24: 13 | C24: CRUZ | D24: GARCÍA | E24: PEDRO YASHIR | G24: 0 | H24: 5 | M24: =G24+I24+K24 -> 0 | N24: =(M24*100)/$P$8 -> 0 | O24: =H24+J24+L24 -> 5 | P24: =IF(AVERAGE(H24,J24,L24)<6,(5),(ROUND(AVERAGE(H24,J24,L24),0))) -> 5 | R24: =IF(N24>20,"EXTRA","ORD") -> ORD
B25: 14 | C25: FUENTES | D25: VALADEZ | E25: ALEXIA DANNAE | G25: 0 | H25: 10 | M25: =G25+I25+K25 -> 0 | N25: =(M25*100)/$P$8 -> 0 | O25: =H25+J25+L25 -> 10 | P25: =IF(AVERAGE(H25,J25,L25)<6,(5),(ROUND(AVERAGE(H25,J25,L25),0))) -> 10 | R25: =IF(N25>20,"EXTRA","ORD") -> ORD
A26: 15 | C26: GARCIA | D26: RANGEL | E26: ADRIAN | G26: 0 | H26: 10 | M26: =G26+I26+K26 -> 0 | N26: =(M26*100)/$P$8 -> 0 | O26: =H26+J26+L26 -> 10 | P26: =IF(AVERAGE(H26,J26,L26)<6,(5),(ROUND(AVERAGE(H26,J26,L26),0))) -> 10 | R26: =IF(N26>20,"EXTRA","ORD") -> ORD
B27: 16 | C27: GOMEZ | D27: ARREDONDO | E27: AMERICA NAOMI | G27: 0 | H27: 5 | M27: =G27+I27+K27 -> 0 | N27: =(M27*100)/$P$8 -> 0 | O27: =H27+J27+L27 -> 5 | P27: =IF(AVERAGE(H27,J27,L27)<6,(5),(ROUND(AVERAGE(H27,J27,L27),0))) -> 5 | R27: =IF(N27>20,"EXTRA","ORD") -> ORD
B28: 17 | C28: GOMEZ | D28: VAZQUEZ | E28: BIBIANA | G28: 0 | H28: 7 | M28: =G28+I28+K28 -> 0 | N28: =(M28*100)/$P$8 -> 0 | O28: =H28+J28+L28 -> 7 | P28: =IF(AVERAGE(H28,J28,L28)<6,(5),(ROUND(AVERAGE(H28,J28,L28),0))) -> 7 | R28: =IF(N28>20,"EXTRA","ORD") -> ORD
B29: 18 | C29: GONZALEZ | D29: REYNA | E29: PAULA EDITH | G29: 0 | H29: 6 | M29: =G29+I29+K29 -> 0 | N29: =(M29*100)/$P$8 -> 0 | O29: =H29+J29+L29 -> 6 | P29: =IF(AVERAGE(H29,J29,L29)<6,(5),(ROUND(AVERAGE(H29,J29,L29),0))) -> 6 | R29: =IF(N29>20,"EXTRA","ORD") -> ORD
A30: 19 | C30: HERNANDEZ | D30: CHAVEZ | E30: DEREK | G30: 1 | H30: 6 | M30: =G30+I30+K30 -> 1 | N30: =(M30*100)/$P$8 -> 10 | O30: =H30+J30+L30 -> 6 | P30: =IF(AVERAGE(H30,J30,L30)<6,(5),(ROUND(AVERAGE(H30,J30,L30),0))) -> 6 | R30: =IF(N30>20,"EXTRA","ORD") -> ORD
B31: 20 | C31: HERNANDEZ | D31: LEDEZMA | E31: IRIARY GUADALUPE | G31: 0 | H31: 10 | M31: =G31+I31+K31 -> 0 | N31: =(M31*100)/$P$8 -> 0 | O31: =H31+J31+L31 -> 10 | P31: =IF(AVERAGE(H31,J31,L31)<6,(5),(ROUND(AVERAGE(H31,J31,L31),0))) -> 10 | R31: =IF(N31>20,"EXTRA","ORD") -> ORD
