Workbook

Sheet TURNO MATUTINO
A1: Parcial | B1: Materia | C1: Asistencia | D1: Promedio | E1: Reprobación | F1: Número de reprobados | G1: Aprovechamiento | H1: Grado | I1: Grupo
A2: =IFERROR(__xludf.DUMMYFUNCTION("IMPORTRANGE(""https://docs.google.com/spreadsheets/d/1yE2bVnWkWF--pAxAHe5w8xpgNOtO54kuuoafly0-jNE/edit?usp=sharing"",""INDICADORES!N2:V34"")"),1.0) -> 1 | B2: =IFERROR(__xludf.DUMMYFUNCTION("""COMPUTED_VALUE"""),"LENGUA Y COMUNICACIÓN II") -> LENGUA Y COMUNICACIÓN II | C2: =IFERROR(__xludf.DUMMYFUNCTION("""COMPUTED_VALUE"""),94.68553459119497) -> 94.685535 | D2: =IFERROR(__xludf.DUMMYFUNCTION("""COMPUTED_VALUE"""),7.113207547169812) -> 7.1132075 | E2: =IFERROR(__xludf.DUMMYFUNCTION("""COMPUTED_VALUE"""),3.7735849056603774) -> 3.7735849 | F2: =IFERROR(__xludf.DUMMYFUNCTION("""COMPUTED_VALUE"""),2.0) -> 2 | G2: =IFERROR(__xludf.DUMMYFUNCTION("""COMPUTED_VALUE"""),96.22641509433963) -> 96.226415 | H2: =IFERROR(__xludf.DUMMYFUNCTION("""COMPUTED_VALUE"""),1.0) -> 1 | I2: =IFERROR(__xludf.DUMMYFUNCTION("""COMPUTED_VALUE"""),46023.0) -> 46023
A3: =IFERROR(__xludf.DUMMYFUNCTION("""COMPUTED_VALUE"""),1.0) -> 1 | B3: =IFERROR(__xludf.DUMMYFUNCTION("""COMPUTED_VALUE"""),"INGLÉS II") -> INGLÉS II | C3: =IFERROR(__xludf.DUMMYFUNCTION("""COMPUTED_VALUE"""),99.51482479784366) -> 99.514825 | D3: =IFERROR(__xludf.DUMMYFUNCTION("""COMPUTED_VALUE"""),8.641509433962264) -> 8.6415094 | E3: =IFERROR(__xludf.DUMMYFUNCTION("""COMPUTED_VALUE"""),7.547169811320755) -> 7.5471698 | F3: =IFERROR(__xludf.DUMMYFUNCTION("""COMPUTED_VALUE"""),4.0) -> 4 | G3: =IFERROR(__xludf.DUMMYFUNCTION("""COMPUTED_VALUE"""),92.45283018867924) -> 92.45283 | H3: =IFERROR(__xludf.DUMMYFUNCTION("""COMPUTED_VALUE"""),1.0) -> 1 | I3: =IFERROR(__xludf.DUMMYFUNCTION("""COMPUTED_VALUE"""),46023.0) -> 46023
A4: =IFERROR(__xludf.DUMMYFUNCTION("""COMPUTED_VALUE"""),1.0) -> 1 | B4: =IFERROR(__xludf.DUMMYFUNCTION("""COMPUTED_VALUE"""),"PENSAMIENTO MATEMÁTICO II") -> PENSAMIENTO MATEMÁTICO II | C4: =IFERROR(__xludf.DUMMYFUNCTION("""COMPUTED_VALUE"""),99.81132075471699) -> 99.811321 | D4: =IFERROR(__xludf.DUMMYFUNCTION("""COMPUTED_VALUE"""),6.452830188679245) -> 6.4528302 | E4: =IFERROR(__xludf.DUMMYFUNCTION("""COMPUTED_VALUE"""),39.62264150943396) -> 39.622642 | F4: =IFERROR(__xludf.DUMMYFUNCTION("""COMPUTED_VALUE"""),21.0) -> 21 | G4: =IFERROR(__xludf.DUMMYFUNCTION("""COMPUTED_VALUE"""),60.37735849056604) -> 60.377358 | H4: =IFERROR(__xludf.DUMMYFUNCTION("""COMPUTED_VALUE"""),1.0) -> 1 | I4: =IFERROR(__xludf.DUMMYFUNCTION("""COMPUTED_VALUE"""),46023.0) -> 46023
A5: =IFERROR(__xludf.DUMMYFUNCTION("""COMPUTED_VALUE"""),1.0) -> 1 | B5: =IFERROR(__xludf.DUMMYFUNCTION("""COMPUTED_VALUE"""),"CULTURA DIGITAL II") -> CULTURA DIGITAL II | C5: =IFERROR(__xludf.DUMMYFUNCTION("""COMPUTED_VALUE"""),99.24528301886792) -> 99.245283 | D5: =IFERROR(__xludf.DUMMYFUNCTION("""COMPUTED_VALUE"""),7.886792452830188) -> 7.8867925 | E5: =IFERROR(__xludf.DUMMYFUNCTION("""COMPUTED_VALUE"""),11.320754716981131) -> 11.320755 | F5: =IFERROR(__xludf.DUMMYFUNCTION("""COMPUTED_VALUE"""),6.0) -> 6 | G5: =IFERROR(__xludf.DUMMYFUNCTION("""COMPUTED_VALUE"""),88.67924528301887) -> 88.679245 | H5: =IFERROR(__xludf.DUMMYFUNCTION("""COMPUTED_VALUE"""),1.0) -> 1 | I5: =IFERROR(__xludf.DUMMYFUNCTION("""COMPUTED_VALUE"""),46023.0) -> 46023
A6: =IFERROR(__xludf.DUMMYFUNCTION("""COMPUTED_VALUE"""),1.0) -> 1 | B6: =IFERROR(__xludf.DUMMYFUNCTION("""COMPUTED_VALUE"""),"CIENCIAS NATURALES, EXPERIMENTALES Y TECNOLOGIA II") -> CIENCIAS NATURALES, EXPERIMENTALES Y TECNOLOGIA II | C6: =IFERROR(__xludf.DUMMYFUNCTION("""COMPUTED_VALUE"""),98.74213836477988) -> 98.742138 | D6: =IFERROR(__xludf.DUMMYFUNCTION("""COMPUTED_VALUE"""),7.886792452830188) -> 7.8867925 | E6: =IFERROR(__xludf.DUMMYFUNCTION("""COMPUTED_VALUE"""),11.320754716981131) -> 11.320755 | F6: =IFERROR(__xludf.DUMMYFUNCTION("""COMPUTED_VALUE"""),6.0) -> 6 | G6: =IFERROR(__xludf.DUMMYFUNCTION("""COMPUTED_VALUE"""),88.67924528301887) -> 88.679245 | H6: =IFERROR(__xludf.DUMMYFUNCTION("""COMPUTED_VALUE"""),1.0) -> 1 | I6: =IFERROR(__xludf.DUMMYFUNCTION("""COMPUTED_VALUE"""),46023.0) -> 46023
A7: =IFERROR(__xludf.DUMMYFUNCTION("""COMPUTED_VALUE"""),1.0) -> 1 | B7: =IFERROR(__xludf.DUMMYFUNCTION("""COMPUTED_VALUE"""),"PENSAMIENTO FILOSÓFICO Y HUMANIDADES II") -> PENSAMIENTO FILOSÓFICO Y HUMANIDADES II | C7: =IFERROR(__xludf.DUMMYFUNCTION("""COMPUTED_VALUE"""),99.05660377358491) -> 99.056604 | D7: =IFERROR(__xludf.DUMMYFUNCTION("""COMPUTED_VALUE"""),7.886792452830188) -> 7.8867925 | E7: =IFERROR(__xludf.DUMMYFUNCTION("""COMPUTED_VALUE"""),11.320754716981131) -> 11.320755 | F7: =IFERROR(__xludf.DUMMYFUNCTION("""COMPUTED_VALUE"""),6.0) -> 6 | G7: =IFERROR(__xludf.DUMMYFUNCTION("""COMPUTED_VALUE"""),88.67924528301887) -> 88.679245 | H7: =IFERROR(__xludf.DUMMYFUNCTION("""COMPUTED_VALUE"""),1.0) -> 1 | I7: =IFERROR(__xludf.DUMMYFUNCTION("""COMPUTED_VALUE"""),46023.0) -> 46023
A8: =IFERROR(__xludf.DUMMYFUNCTION("""COMPUTED_VALUE"""),1.0) -> 1 | B8: =IFERROR(__xludf.DUMMYFUNCTION("""COMPUTED_VALUE"""),"CIENCIAS SOCIALES II") -> CIENCIAS SOCIALES II | C8: =IFERROR(__xludf.DUMMYFUNCTION("""COMPUTED_VALUE"""),98.38274932614556) -> 98.382749 | D8: =IFERROR(__xludf.DUMMYFUNCTION("""COMPUTED_VALUE"""),7.886792452830188) -> 7.8867925 | E8: =IFERROR(__xludf.DUMMYFUNCTION("""COMPUTED_VALUE"""),11.320754716981131) -> 11.320755 | F8: =IFERROR(__xludf.DUMMYFUNCTION("""COMPUTED_VALUE"""),6.0) -> 6 | G8: =IFERROR(__xludf.DUMMYFUNCTION("""COMPUTED_VALUE"""),88.67924528301887) -> 88.679245 | H8: =IFERROR(__xludf.DUMMYFUNCTION("""COMPUTED_VALUE"""),1.0) -> 1 | I8: =IFERROR(__xludf.DUMMYFUNCTION("""COMPUTED_VALUE"""),46023.0) -> 46023
A9: =IFERROR(__xludf.DUMMYFUNCTION("""COMPUTED_VALUE"""),1.0) -> 1 | B9: =IFERROR(__xludf.DUMMYFUNCTION("""COMPUTED_VALUE"""),"TALLER DE CIENCIAS I") -> TALLER DE CIENCIAS I | C9: =IFERROR(__xludf.DUMMYFUNCTION("""COMPUTED_VALUE"""),98.58490566037736) -> 98.584906 | D9: =IFERROR(__xludf.DUMMYFUNCTION("""COMPUTED_VALUE"""),7.886792452830188) -> 7.8867925 | E9: =IFERROR(__xludf.DUMMYFUNCTION("""COMPUTED_VALUE"""),11.320754716981131) -> 11.320755 | F9: =IFERROR(__xludf.DUMMYFUNCTION("""COMPUTED_VALUE"""),6.0) -> 6 | G9: =IFERROR(__xludf.DUMMYFUNCTION("""COMPUTED_VALUE"""),88.67924528301887) -> 88.679245 | H9: =IFERROR(__xludf.DUMMYFUNCTION("""COMPUTED_VALUE"""),1.0) -> 1 | I9: =IFERROR(__xludf.DUMMYFUNCTION("""COMPUTED_VALUE"""),46023.0) -> 46023
A10: =IFERROR(__xludf.DUMMYFUNCTION("""COMPUTED_VALUE"""),1.0) -> 1 | B10: =IFERROR(__xludf.DUMMYFUNCTION("""COMPUTED_VALUE"""),"ACTIVIDADES FISICAS Y DEPORTIVAS II") -> ACTIVIDADES FISICAS Y DEPORTIVAS II | C10: =IFERROR(__xludf.DUMMYFUNCTION("""COMPUTED_VALUE"""),98.74213836477988) -> 98.742138 | D10: =IFERROR(__xludf.DUMMYFUNCTION("""COMPUTED_VALUE"""),7.886792452830188) -> 7.8867925 | E10: =IFERROR(__xludf.DUMMYFUNCTION("""COMPUTED_VALUE"""),11.320754716981131) -> 11.320755 | F10: =IFERROR(__xludf.DUMMYFUNCTION("""COMPUTED_VALUE"""),6.0) -> 6 | G10: =IFERROR(__xludf.DUMMYFUNCTION("""COMPUTED_VALUE"""),88.67924528301887) -> 88.679245 | H10: =IFERROR(__xludf.DUMMYFUNCTION("""COMPUTED_VALUE"""),1.0) -> 1 | I10: =IFERROR(__xludf.DUMMYFUNCTION("""COMPUTED_VALUE"""),46023.0) -> 46023
A11: =IFERROR(__xludf.DUMMYFUNCTION("""COMPUTED_VALUE"""),1.0) -> 1 | B11: =IFERROR(__xludf.DUMMYFUNCTION("""COMPUTED_VALUE"""),"EDUCACION PARA LA SALUD II") -> EDUCACION PARA LA SALUD II | C11: =IFERROR(__xludf.DUMMYFUNCTION("""COMPUTED_VALUE"""),97.73584905660377) -> 97.735849 | D11: =IFERROR(__xludf.DUMMYFUNCTION("""COMPUTED_VALUE"""),7.886792452830188) -> 7.8867925 | E11: =IFERROR(__xludf.DUMMYFUNCTION("""COMPUTED_VALUE"""),11.320754716981131) -> 11.320755 | F11: =IFERROR(__xludf.DUMMYFUNCTION("""COMPUTED_VALUE"""),6.0) -> 6 | G11: =IFERROR(__xludf.DUMMYFUNCTION("""COMPUTED_VALUE"""),88.67924528301887) -> 88.679245 | H11: =IFERROR(__xludf.DUMMYFUNCTION("""COMPUTED_VALUE"""),1.0) -> 1 | I11: =IFERROR(__xludf.DUMMYFUNCTION("""COMPUTED_VALUE"""),46023.0) -> 46023
A12: =IFERROR(__xludf.DUMMYFUNCTION("""COMPUTED_VALUE"""),1.0) -> 1 | B12: =IFERROR(__xludf.DUMMYFUNCTION("""COMPUTED_VALUE"""),"TEMAS SELECTOS DE IGUALDAD Y DERECHOS HUMANOS II") -> TEMAS SELECTOS DE IGUALDAD Y DERECHOS HUMANOS II | C12: =IFERROR(__xludf.DUMMYFUNCTION("""COMPUTED_VALUE"""),96.22641509433963) -> 96.226415 | D12: =IFERROR(__xludf.DUMMYFUNCTION("""COMPUTED_VALUE"""),7.113207547169812) -> 7.1132075 | E12: =IFERROR(__xludf.DUMMYFUNCTION("""COMPUTED_VALUE"""),3.7735849056603774) -> 3.7735849 | F12: =IFERROR(__xludf.DUMMYFUNCTION("""COMPUTED_VALUE"""),2.0) -> 2 | G12: =IFERROR(__xludf.DUMMYFUNCTION("""COMPUTED_VALUE"""),96.22641509433963) -> 96.226415 | H12: =IFERROR(__xludf.DUMMYFUNCTION("""COMPUTED_VALUE"""),1.0) -> 1 | I12: =IFERROR(__xludf.DUMMYFUNCTION("""COMPUTED_VALUE"""),46023.0) -> 46023
A13: =IFERROR(__xludf.DUMMYFUNCTION("""COMPUTED_VALUE"""),2.0) -> 2 | B13: =IFERROR(__xludf.DUMMYFUNCTION("""COMPUTED_VALUE"""),"LENGUA Y COMUNICACIÓN II") -> LENGUA Y COMUNICACIÓN II | C13: =IFERROR(__xludf.DUMMYFUNCTION("""COMPUTED_VALUE"""),94.68553459119497) -> 94.685535 | D13: =IFERROR(__xludf.DUMMYFUNCTION("""COMPUTED_VALUE"""),7.113207547169812) -> 7.1132075 | E13: =IFERROR(__xludf.DUMMYFUNCTION("""COMPUTED_VALUE"""),3.7735849056603774) -> 3.7735849 | F13: =IFERROR(__xludf.DUMMYFUNCTION("""COMPUTED_VALUE"""),2.0) -> 2 | G13: =IFERROR(__xludf.DUMMYFUNCTION("""COMPUTED_VALUE"""),96.22641509433963) -> 96.226415 | H13: =IFERROR(__xludf.DUMMYFUNCTION("""COMPUTED_VALUE"""),1.0) -> 1 | I13: =IFERROR(__xludf.DUMMYFUNCTION("""COMPUTED_VALUE"""),46023.0) -> 46023
A14: =IFERROR(__xludf.DUMMYFUNCTION("""COMPUTED_VALUE"""),2.0) -> 2 | B14: =IFERROR(__xludf.DUMMYFUNCTION("""COMPUTED_VALUE"""),"INGLÉS II") -> INGLÉS II | C14: =IFERROR(__xludf.DUMMYFUNCTION("""COMPUTED_VALUE"""),99.51482479784366) -> 99.514825 | D14: =IFERROR(__xludf.DUMMYFUNCTION("""COMPUTED_VALUE"""),"#DIV/0!") -> #DIV/0! | E14: =IFERROR(__xludf.DUMMYFUNCTION("""COMPUTED_VALUE"""),0.0) -> 0 | F14: =IFERROR(__xludf.DUMMYFUNCTION("""COMPUTED_VALUE"""),0.0) -> 0 | G14: =IFERROR(__xludf.DUMMYFUNCTION("""COMPUTED_VALUE"""),0.0) -> 0 | H14: =IFERROR(__xludf.DUMMYFUNCTION("""COMPUTED_VALUE"""),1.0) -> 1 | I14: =IFERROR(__xludf.DUMMYFUNCTION("""COMPUTED_VALUE"""),46023.0) -> 46023
A15: =IFERROR(__xludf.DUMMYFUNCTION("""COMPUTED_VALUE"""),2.0) -> 2 | B15: =IFERROR(__xludf.DUMMYFUNCTION("""COMPUTED_VALUE"""),"PENSAMIENTO MATEMÁTICO II") -> PENSAMIENTO MATEMÁTICO II | C15: =IFERROR(__xludf.DUMMYFUNCTION("""COMPUTED_VALUE"""),99.81132075471699) -> 99.811321 | D15: =IFERROR(__xludf.DUMMYFUNCTION("""COMPUTED_VALUE"""),"#DIV/0!") -> #DIV/0! | E15: =IFERROR(__xludf.DUMMYFUNCTION("""COMPUTED_VALUE"""),0.0) -> 0 | F15: =IFERROR(__xludf.DUMMYFUNCTION("""COMPUTED_VALUE"""),0.0) -> 0 | G15: =IFERROR(__xludf.DUMMYFUNCTION("""COMPUTED_VALUE"""),0.0) -> 0 | H15: =IFERROR(__xludf.DUMMYFUNCTION("""COMPUTED_VALUE"""),1.0) -> 1 | I15: =IFERROR(__xludf.DUMMYFUNCTION("""COMPUTED_VALUE"""),46023.0) -> 46023
A16: =IFERROR(__xludf.DUMMYFUNCTION("""COMPUTED_VALUE"""),2.0) -> 2 | B16: =IFERROR(__xludf.DUMMYFUNCTION("""COMPUTED_VALUE"""),"CULTURA DIGITAL II") -> CULTURA DIGITAL II | C16: =IFERROR(__xludf.DUMMYFUNCTION("""COMPUTED_VALUE"""),99.24528301886792) -> 99.245283 | D16: =IFERROR(__xludf.DUMMYFUNCTION("""COMPUTED_VALUE"""),"#DIV/0!") -> #DIV/0! | E16: =IFERROR(__xludf.DUMMYFUNCTION("""COMPUTED_VALUE"""),0.0) -> 0 | F16: =IFERROR(__xludf.DUMMYFUNCTION("""COMPUTED_VALUE"""),0.0) -> 0 | G16: =IFERROR(__xludf.DUMMYFUNCTION("""COMPUTED_VALUE"""),0.0) -> 0 | H16: =IFERROR(__xludf.DUMMYFUNCTION("""COMPUTED_VALUE"""),1.0) -> 1 | I16: =IFERROR(__xludf.DUMMYFUNCTION("""COMPUTED_VALUE"""),46023.0) -> 46023
A17: =IFERROR(__xludf.DUMMYFUNCTION("""COMPUTED_VALUE"""),2.0) -> 2 | B17: =IFERROR(__xludf.DUMMYFUNCTION("""COMPUTED_VALUE"""),"CIENCIAS NATURALES, EXPERIMENTALES Y TECNOLOGIA II") -> CIENCIAS NATURALES, EXPERIMENTALES Y TECNOLOGIA II | C17: =IFERROR(__xludf.DUMMYFUNCTION("""COMPUTED_VALUE"""),98.74213836477988) -> 98.742138 | D17: =IFERROR(__xludf.DUMMYFUNCTION("""COMPUTED_VALUE"""),"#DIV/0!") -> #DIV/0! | E17: =IFERROR(__xludf.DUMMYFUNCTION("""COMPUTED_VALUE"""),0.0) -> 0 | F17: =IFERROR(__xludf.DUMMYFUNCTION("""COMPUTED_VALUE"""),0.0) -> 0 | G17: =IFERROR(__xludf.DUMMYFUNCTION("""COMPUTED_VALUE"""),0.0) -> 0 | H17: =IFERROR(__xludf.DUMMYFUNCTION("""COMPUTED_VALUE"""),1.0) -> 1 | I17: =IFERROR(__xludf.DUMMYFUNCTION("""COMPUTED_VALUE"""),46023.0) -> 46023
A18: =IFERROR(__xludf.DUMMYFUNCTION("""COMPUTED_VALUE"""),2.0) -> 2 | B18: =IFERROR(__xludf.DUMMYFUNCTION("""COMPUTED_VALUE"""),"PENSAMIENTO FILOSÓFICO Y HUMANIDADES II") -> PENSAMIENTO FILOSÓFICO Y HUMANIDADES II | C18: =IFERROR(__xludf.DUMMYFUNCTION("""COMPUTED_VALUE"""),99.05660377358491) -> 99.056604 | D18: =IFERROR(__xludf.DUMMYFUNCTION("""COMPUTED_VALUE"""),"#DIV/0!") -> #DIV/0! | E18: =IFERROR(__xludf.DUMMYFUNCTION("""COMPUTED_VALUE"""),0.0) -> 0 | F18: =IFERROR(__xludf.DUMMYFUNCTION("""COMPUTED_VALUE"""),0.0) -> 0 | G18: =IFERROR(__xludf.DUMMYFUNCTION("""COMPUTED_VALUE"""),0.0) -> 0 | H18: =IFERROR(__xludf.DUMMYFUNCTION("""COMPUTED_VALUE"""),1.0) -> 1 | I18: =IFERROR(__xludf.DUMMYFUNCTION("""COMPUTED_VALUE"""),46023.0) -> 46023
A19: =IFERROR(__xludf.DUMMYFUNCTION("""COMPUTED_VALUE"""),2.0) -> 2 | B19: =IFERROR(__xludf.DUMMYFUNCTION("""COMPUTED_VALUE"""),"CIENCIAS SOCIALES II") -> CIENCIAS SOCIALES II | C19: =IFERROR(__xludf.DUMMYFUNCTION("""COMPUTED_VALUE"""),98.38274932614556) -> 98.382749 | D19: =IFERROR(__xludf.DUMMYFUNCTION("""COMPUTED_VALUE"""),"#DIV/0!") -> #DIV/0! | E19: =IFERROR(__xludf.DUMMYFUNCTION("""COMPUTED_VALUE"""),0.0) -> 0 | F19: =IFERROR(__xludf.DUMMYFUNCTION("""COMPUTED_VALUE"""),0.0) -> 0 | G19: =IFERROR(__xludf.DUMMYFUNCTION("""COMPUTED_VALUE"""),0.0) -> 0 | H19: =IFERROR(__xludf.DUMMYFUNCTION("""COMPUTED_VALUE"""),1.0) -> 1 | I19: =IFERROR(__xludf.DUMMYFUNCTION("""COMPUTED_VALUE"""),46023.0) -> 46023
A20: =IFERROR(__xludf.DUMMYFUNCTION("""COMPUTED_VALUE"""),2.0) -> 2 | B20: =IFERROR(__xludf.DUMMYFUNCTION("""COMPUTED_VALUE"""),"TALLER DE CIENCIAS I") -> TALLER DE CIENCIAS I | C20: =IFERROR(__xludf.DUMMYFUNCTION("""COMPUTED_VALUE"""),98.58490566037736) -> 98.584906 | D20: =IFERROR(__xludf.DUMMYFUNCTION("""COMPUTED_VALUE"""),"#DIV/0!") -> #DIV/0! | E20: =IFERROR(__xludf.DUMMYFUNCTION("""COMPUTED_VALUE"""),0.0) -> 0 | F20: =IFERROR(__xludf.DUMMYFUNCTION("""COMPUTED_VALUE"""),0.0) -> 0 | G20: =IFERROR(__xludf.DUMMYFUNCTION("""COMPUTED_VALUE"""),0.0) -> 0 | H20: =IFERROR(__xludf.DUMMYFUNCTION("""COMPUTED_VALUE"""),1.0) -> 1 | I20: =IFERROR(__xludf.DUMMYFUNCTION("""COMPUTED_VALUE"""),46023.0) -> 46023
A21: =IFERROR(__xludf.DUMMYFUNCTION("""COMPUTED_VALUE"""),2.0) -> 2 | B21: =IFERROR(__xludf.DUMMYFUNCTION("""COMPUTED_VALUE"""),"ACTIVIDADES FISICAS Y DEPORTIVAS II") -> ACTIVIDADES FISICAS Y DEPORTIVAS II | C21: =IFERROR(__xludf.DUMMYFUNCTION("""COMPUTED_VALUE"""),98.74213836477988) -> 98.742138 | D21: =IFERROR(__xludf.DUMMYFUNCTION("""COMPUTED_VALUE"""),"#DIV/0!") -> #DIV/0! | E21: =IFERROR(__xludf.DUMMYFUNCTION("""COMPUTED_VALUE"""),0.0) -> 0 | F21: =IFERROR(__xludf.DUMMYFUNCTION("""COMPUTED_VALUE"""),0.0) -> 0 | G21: =IFERROR(__xludf.DUMMYFUNCTION("""COMPUTED_VALUE"""),0.0) -> 0 | H21: =IFERROR(__xludf.DUMMYFUNCTION("""COMPUTED_VALUE"""),1.0) -> 1 | I21: =IFERROR(__xludf.DUMMYFUNCTION("""COMPUTED_VALUE"""),46023.0) -> 46023
A22: =IFERROR(__xludf.DUMMYFUNCTION("""COMPUTED_VALUE"""),2.0) -> 2 | B22: =IFERROR(__xludf.DUMMYFUNCTION("""COMPUTED_VALUE"""),"EDUCACION PARA LA SALUD II") -> EDUCACION PARA LA SALUD II | C22: =IFERROR(__xludf.DUMMYFUNCTION("""COMPUTED_VALUE"""),97.73584905660377) -> 97.735849 | D22: =IFERROR(__xludf.DUMMYFUNCTION("""COMPUTED_VALUE"""),"#DIV/0!") -> #DIV/0! | E22: =IFERROR(__xludf.DUMMYFUNCTION("""COMPUTED_VALUE"""),0.0) -> 0 | F22: =IFERROR(__xludf.DUMMYFUNCTION("""COMPUTED_VALUE"""),0.0) -> 0 | G22: =IFERROR(__xludf.DUMMYFUNCTION("""COMPUTED_VALUE"""),0.0) -> 0 | H22: =IFERROR(__xludf.DUMMYFUNCTION("""COMPUTED_VALUE"""),1.0) -> 1 | I22: =IFERROR(__xludf.DUMMYFUNCTION("""COMPUTED_VALUE"""),46023.0) -> 46023
A23: =IFERROR(__xludf.DUMMYFUNCTION("""COMPUTED_VALUE"""),2.0) -> 2 | B23: =IFERROR(__xludf.DUMMYFUNCTION("""COMPUTED_VALUE"""),"TEMAS SELECTOS DE IGUALDAD Y DERECHOS HUMANOS II") -> TEMAS SELECTOS DE IGUALDAD Y DERECHOS HUMANOS II | C23: =IFERROR(__xludf.DUMMYFUNCTION("""COMPUTED_VALUE"""),96.22641509433963) -> 96.226415 | D23: =IFERROR(__xludf.DUMMYFUNCTION("""COMPUTED_VALUE"""),"#DIV/0!") -> #DIV/0! | E23: =IFERROR(__xludf.DUMMYFUNCTION("""COMPUTED_VALUE"""),0.0) -> 0 | F23: =IFERROR(__xludf.DUMMYFUNCTION("""COMPUTED_VALUE"""),0.0) -> 0 | G23: =IFERROR(__xludf.DUMMYFUNCTION("""COMPUTED_VALUE"""),0.0) -> 0 | H23: =IFERROR(__xludf.DUMMYFUNCTION("""COMPUTED_VALUE"""),1.0) -> 1 | I23: =IFERROR(__xludf.DUMMYFUNCTION("""COMPUTED_VALUE"""),46023.0) -> 46023
A24: =IFERROR(__xludf.DUMMYFUNCTION("""COMPUTED_VALUE"""),3.0) -> 3 | B24: =IFERROR(__xludf.DUMMYFUNCTION("""COMPUTED_VALUE"""),"LENGUA Y COMUNICACIÓN II") -> LENGUA Y COMUNICACIÓN II | C24: =IFERROR(__xludf.DUMMYFUNCTION("""COMPUTED_VALUE"""),94.68553459119497) -> 94.685535 | D24: =IFERROR(__xludf.DUMMYFUNCTION("""COMPUTED_VALUE"""),7.113207547169812) -> 7.1132075 | E24: =IFERROR(__xludf.DUMMYFUNCTION("""COMPUTED_VALUE"""),3.7735849056603774) -> 3.7735849 | F24: =IFERROR(__xludf.DUMMYFUNCTION("""COMPUTED_VALUE"""),2.0) -> 2 | G24: =IFERROR(__xludf.DUMMYFUNCTION("""COMPUTED_VALUE"""),2.0) -> 2 | H24: =IFERROR(__xludf.DUMMYFUNCTION("""COMPUTED_VALUE"""),1.0) -> 1 | I24: =IFERROR(__xludf.DUMMYFUNCTION("""COMPUTED_VALUE"""),46023.0) -> 46023
A25: =IFERROR(__xludf.DUMMYFUNCTION("""COMPUTED_VALUE"""),3.0) -> 3 | B25: =IFERROR(__xludf.DUMMYFUNCTION("""COMPUTED_VALUE"""),"INGLÉS II") -> INGLÉS II | C25: =IFERROR(__xludf.DUMMYFUNCTION("""COMPUTED_VALUE"""),99.51482479784366) -> 99.514825 | D25: =IFERROR(__xludf.DUMMYFUNCTION("""COMPUTED_VALUE"""),"#DIV/0!") -> #DIV/0! | E25: =IFERROR(__xludf.DUMMYFUNCTION("""COMPUTED_VALUE"""),0.0) -> 0 | F25: =IFERROR(__xludf.DUMMYFUNCTION("""COMPUTED_VALUE"""),0.0) -> 0 | G25: =IFERROR(__xludf.DUMMYFUNCTION("""COMPUTED_VALUE"""),0.0) -> 0 | H25: =IFERROR(__xludf.DUMMYFUNCTION("""COMPUTED_VALUE"""),1.0) -> 1 | I25: =IFERROR(__xludf.DUMMYFUNCTION("""COMPUTED_VALUE"""),46054.0) -> 46054
A26: =IFERROR(__xludf.DUMMYFUNCTION("""COMPUTED_VALUE"""),3.0) -> 3 | B26: =IFERROR(__xludf.DUMMYFUNCTION("""COMPUTED_VALUE"""),"PENSAMIENTO MATEMÁTICO II") -> PENSAMIENTO MATEMÁTICO II | C26: =IFERROR(__xludf.DUMMYFUNCTION("""COMPUTED_VALUE"""),99.81132075471699) -> 99.811321 | D26: =IFERROR(__xludf.DUMMYFUNCTION("""COMPUTED_VALUE"""),"#DIV/0!") -> #DIV/0! | E26: =IFERROR(__xludf.DUMMYFUNCTION("""COMPUTED_VALUE"""),0.0) -> 0 | F26: =IFERROR(__xludf.DUMMYFUNCTION("""COMPUTED_VALUE"""),0.0) -> 0 | G26: =IFERROR(__xludf.DUMMYFUNCTION("""COMPUTED_VALUE"""),0.0) -> 0 | H26: =IFERROR(__xludf.DUMMYFUNCTION("""COMPUTED_VALUE"""),1.0) -> 1 | I26: =IFERROR(__xludf.DUMMYFUNCTION("""COMPUTED_VALUE"""),46023.0) -> 46023
A27: =IFERROR(__xludf.DUMMYFUNCTION("""COMPUTED_VALUE"""),3.0) -> 3 | B27: =IFERROR(__xludf.DUMMYFUNCTION("""COMPUTED_VALUE"""),"CULTURA DIGITAL II") -> CULTURA DIGITAL II | C27: =IFERROR(__xludf.DUMMYFUNCTION("""COMPUTED_VALUE"""),99.24528301886792) -> 99.245283 | D27: =IFERROR(__xludf.DUMMYFUNCTION("""COMPUTED_VALUE"""),"#DIV/0!") -> #DIV/0! | E27: =IFERROR(__xludf.DUMMYFUNCTION("""COMPUTED_VALUE"""),0.0) -> 0 | F27: =IFERROR(__xludf.DUMMYFUNCTION("""COMPUTED_VALUE"""),0.0) -> 0 | G27: =IFERROR(__xludf.DUMMYFUNCTION("""COMPUTED_VALUE"""),0.0) -> 0 | H27: =IFERROR(__xludf.DUMMYFUNCTION("""COMPUTED_VALUE"""),1.0) -> 1 | I27: =IFERROR(__xludf.DUMMYFUNCTION("""COMPUTED_VALUE"""),46023.0) -> 46023
A28: =IFERROR(__xludf.DUMMYFUNCTION("""COMPUTED_VALUE"""),3.0) -> 3 | B28: =IFERROR(__xludf.DUMMYFUNCTION("""COMPUTED_VALUE"""),"CIENCIAS NATURALES, EXPERIMENTALES Y TECNOLOGIA II") -> CIENCIAS NATURALES, EXPERIMENTALES Y TECNOLOGIA II | C28: =IFERROR(__xludf.DUMMYFUNCTION("""COMPUTED_VALUE"""),98.74213836477988) -> 98.742138 | D28: =IFERROR(__xludf.DUMMYFUNCTION("""COMPUTED_VALUE"""),"#DIV/0!") -> #DIV/0! | E28: =IFERROR(__xludf.DUMMYFUNCTION("""COMPUTED_VALUE"""),0.0) -> 0 | F28: =IFERROR(__xludf.DUMMYFUNCTION("""COMPUTED_VALUE"""),0.0) -> 0 | G28: =IFERROR(__xludf.DUMMYFUNCTION("""COMPUTED_VALUE"""),0.0) -> 0 | H28: =IFERROR(__xludf.DUMMYFUNCTION("""COMPUTED_VALUE"""),1.0) -> 1 | I28: =IFERROR(__xludf.DUMMYFUNCTION("""COMPUTED_VALUE"""),46023.0) -> 46023
A29: =IFERROR(__xludf.DUMMYFUNCTION("""COMPUTED_VALUE"""),3.0) -> 3 | B29: =IFERROR(__xludf.DUMMYFUNCTION("""COMPUTED_VALUE"""),"PENSAMIENTO FILOSÓFICO Y HUMANIDADES II") -> PENSAMIENTO FILOSÓFICO Y HUMANIDADES II | C29: =IFERROR(__xludf.DUMMYFUNCTION("""COMPUTED_VALUE"""),99.05660377358491) -> 99.056604 | D29: =IFERROR(__xludf.DUMMYFUNCTION("""COMPUTED_VALUE"""),"#DIV/0!") -> #DIV/0! | E29: =IFERROR(__xludf.DUMMYFUNCTION("""COMPUTED_VALUE"""),0.0) -> 0 | F29: =IFERROR(__xludf.DUMMYFUNCTION("""COMPUTED_VALUE"""),0.0) -> 0 | G29: =IFERROR(__xludf.DUMMYFUNCTION("""COMPUTED_VALUE"""),0.0) -> 0 | H29: =IFERROR(__xludf.DUMMYFUNCTION("""COMPUTED_VALUE"""),1.0) -> 1 | I29: =IFERROR(__xludf.DUMMYFUNCTION("""COMPUTED_VALUE"""),46023.0) -> 46023
A30: =IFERROR(__xludf.DUMMYFUNCTION("""COMPUTED_VALUE"""),3.0) -> 3 | B30: =IFERROR(__xludf.DUMMYFUNCTION("""COMPUTED_VALUE"""),"CIENCIAS SOCIALES II") -> CIENCIAS SOCIALES II | C30: =IFERROR(__xludf.DUMMYFUNCTION("""COMPUTED_VALUE"""),98.38274932614556) -> 98.382749 | D30: =IFERROR(__xludf.DUMMYFUNCTION("""COMPUTED_VALUE"""),"#DIV/0!") -> #DIV/0! | E30: =IFERROR(__xludf.DUMMYFUNCTION("""COMPUTED_VALUE"""),0.0) -> 0 | F30: =IFERROR(__xludf.DUMMYFUNCTION("""COMPUTED_VALUE"""),0.0) -> 0 | G30: =IFERROR(__xludf.DUMMYFUNCTION("""COMPUTED_VALUE"""),0.0) -> 0 | H30: =IFERROR(__xludf.DUMMYFUNCTION("""COMPUTED_VALUE"""),1.0) -> 1 | I30: =IFERROR(__xludf.DUMMYFUNCTION("""COMPUTED_VALUE"""),46023.0) -> 46023
A31: =IFERROR(__xludf.DUMMYFUNCTION("""COMPUTED_VALUE"""),3.0) -> 3 | B31: =IFERROR(__xludf.DUMMYFUNCTION("""COMPUTED_VALUE"""),"TALLER DE CIENCIAS I") -> TALLER DE CIENCIAS I | C31: =IFERROR(__xludf.DUMMYFUNCTION("""COMPUTED_VALUE"""),98.58490566037736) -> 98.584906 | D31: =IFERROR(__xludf.DUMMYFUNCTION("""COMPUTED_VALUE"""),"#DIV/0!") -> #DIV/0! | E31: =IFERROR(__xludf.DUMMYFUNCTION("""COMPUTED_VALUE"""),0.0) -> 0 | F31: =IFERROR(__xludf.DUMMYFUNCTION("""COMPUTED_VALUE"""),0.0) -> 0 | G31: =IFERROR(__xludf.DUMMYFUNCTION("""COMPUTED_VALUE"""),0.0) -> 0 | H31: =IFERROR(__xludf.DUMMYFUNCTION("""COMPUTED_VALUE"""),1.0) -> 1 | I31: =IFERROR(__xludf.DUMMYFUNCTION("""COMPUTED_VALUE"""),46023.0) -> 46023
A32: =IFERROR(__xludf.DUMMYFUNCTION("""COMPUTED_VALUE"""),3.0) -> 3 | B32: =IFERROR(__xludf.DUMMYFUNCTION("""COMPUTED_VALUE"""),"ACTIVIDADES FISICAS Y DEPORTIVAS II") -> ACTIVIDADES FISICAS Y DEPORTIVAS II | C32: =IFERROR(__xludf.DUMMYFUNCTION("""COMPUTED_VALUE"""),98.74213836477988) -> 98.742138 | D32: =IFERROR(__xludf.DUMMYFUNCTION("""COMPUTED_VALUE"""),"#DIV/0!") -> #DIV/0! | E32: =IFERROR(__xludf.DUMMYFUNCTION("""COMPUTED_VALUE"""),0.0) -> 0 | F32: =IFERROR(__xludf.DUMMYFUNCTION("""COMPUTED_VALUE"""),0.0) -> 0 | G32: =IFERROR(__xludf.DUMMYFUNCTION("""COMPUTED_VALUE"""),0.0) -> 0 | H32: =IFERROR(__xludf.DUMMYFUNCTION("""COMPUTED_VALUE"""),1.0) -> 1 | I32: =IFERROR(__xludf.DUMMYFUNCTION("""COMPUTED_VALUE"""),46023.0) -> 46023
A33: =IFERROR(__xludf.DUMMYFUNCTION("""COMPUTED_VALUE"""),3.0) -> 3 | B33: =IFERROR(__xludf.DUMMYFUNCTION("""COMPUTED_VALUE"""),"EDUCACION PARA LA SALUD II") -> EDUCACION PARA LA SALUD II | C33: =IFERROR(__xludf.DUMMYFUNCTION("""COMPUTED_VALUE"""),97.73584905660377) -> 97.735849 | D33: =IFERROR(__xludf.DUMMYFUNCTION("""COMPUTED_VALUE"""),"#DIV/0!") -> #DIV/0! | E33: =IFERROR(__xludf.DUMMYFUNCTION("""COMPUTED_VALUE"""),0.0) -> 0 | F33: =IFERROR(__xludf.DUMMYFUNCTION("""COMPUTED_VALUE"""),0.0) -> 0 | G33: =IFERROR(__xludf.DUMMYFUNCTION("""COMPUTED_VALUE"""),0.0) -> 0 | H33: =IFERROR(__xludf.DUMMYFUNCTION("""COMPUTED_VALUE"""),1.0) -> 1 | I33: =IFERROR(__xludf.DUMMYFUNCTION("""COMPUTED_VALUE"""),46023.0) -> 46023
A34: =IFERROR(__xludf.DUMMYFUNCTION("""COMPUTED_VALUE"""),3.0) -> 3 | B34: =IFERROR(__xludf.DUMMYFUNCTION("""COMPUTED_VALUE"""),"TEMAS SELECTOS DE IGUALDAD Y DERECHOS HUMANOS II") -> TEMAS SELECTOS DE IGUALDAD Y DERECHOS HUMANOS II | C34: =IFERROR(__xludf.DUMMYFUNCTION("""COMPUTED_VALUE"""),96.22641509433963) -> 96.226415 | D34: =IFERROR(__xludf.DUMMYFUNCTION("""COMPUTED_VALUE"""),"#DIV/0!") -> #DIV/0! | E34: =IFERROR(__xludf.DUMMYFUNCTION("""COMPUTED_VALUE"""),0.0) -> 0 | F34: =IFERROR(__xludf.DUMMYFUNCTION("""COMPUTED_VALUE"""),0.0) -> 0 | G34: =IFERROR(__xludf.DUMMYFUNCTION("""COMPUTED_VALUE"""),0.0) -> 0 | H34: =IFERROR(__xludf.DUMMYFUNCTION("""COMPUTED_VALUE"""),1.0) -> 1 | I34: =IFERROR(__xludf.DUMMYFUNCTION("""COMPUTED_VALUE"""),46023.0) -> 46023
A35: =IFERROR(__xludf.DUMMYFUNCTION("IMPORTRANGE(""https://docs.google.com/spreadsheets/d/18uFFbBXq5f2l-NPGZ9zfx9hK3OXfozCBcwWhjkL8Elo/edit?usp=sharing"",""INDICADORES!N2:V34"")"),1.0) -> 1 | B35: =IFERROR(__xludf.DUMMYFUNCTION("""COMPUTED_VALUE"""),"LENGUA Y COMUNICACIÓN II") -> LENGUA Y COMUNICACIÓN II | C35: =IFERROR(__xludf.DUMMYFUNCTION("""COMPUTED_VALUE"""),99.16666666666667) -> 99.166667 | D35: =IFERROR(__xludf.DUMMYFUNCTION("""COMPUTED_VALUE"""),7.923076923076923) -> 7.9230769 | E35: =IFERROR(__xludf.DUMMYFUNCTION("""COMPUTED_VALUE"""),11.538461538461538) -> 11.538462 | F35: =IFERROR(__xludf.DUMMYFUNCTION("""COMPUTED_VALUE"""),6.0) -> 6 | G35: =IFERROR(__xludf.DUMMYFUNCTION("""COMPUTED_VALUE"""),88.46153846153847) -> 88.461538 | H35: =IFERROR(__xludf.DUMMYFUNCTION("""COMPUTED_VALUE"""),1.0) -> 1 | I35: =IFERROR(__xludf.DUMMYFUNCTION("""COMPUTED_VALUE"""),46054.0) -> 46054
A36: =IFERROR(__xludf.DUMMYFUNCTION("""COMPUTED_VALUE"""),1.0) -> 1 | B36: =IFERROR(__xludf.DUMMYFUNCTION("""COMPUTED_VALUE"""),"INGLÉS II") -> INGLÉS II | C36: =IFERROR(__xludf.DUMMYFUNCTION("""COMPUTED_VALUE"""),99.8076923076923) -> 99.807692 | D36: =IFERROR(__xludf.DUMMYFUNCTION("""COMPUTED_VALUE"""),8.634615384615385) -> 8.6346154 | E36: =IFERROR(__xludf.DUMMYFUNCTION("""COMPUTED_VALUE"""),7.6923076923076925) -> 7.6923077 | F36: =IFERROR(__xludf.DUMMYFUNCTION("""COMPUTED_VALUE"""),4.0) -> 4 | G36: =IFERROR(__xludf.DUMMYFUNCTION("""COMPUTED_VALUE"""),92.3076923076923) -> 92.307692 | H36: =IFERROR(__xludf.DUMMYFUNCTION("""COMPUTED_VALUE"""),1.0) -> 1 | I36: =IFERROR(__xludf.DUMMYFUNCTION("""COMPUTED_VALUE"""),46054.0) -> 46054
A37: =IFERROR(__xludf.DUMMYFUNCTION("""COMPUTED_VALUE"""),1.0) -> 1 | B37: =IFERROR(__xludf.DUMMYFUNCTION("""COMPUTED_VALUE"""),"PENSAMIENTO MATEMÁTICO II") -> PENSAMIENTO MATEMÁTICO II | C37: =IFERROR(__xludf.DUMMYFUNCTION("""COMPUTED_VALUE"""),99.8076923076923) -> 99.807692 | D37: =IFERROR(__xludf.DUMMYFUNCTION("""COMPUTED_VALUE"""),8.634615384615385) -> 8.6346154 | E37: =IFERROR(__xludf.DUMMYFUNCTION("""COMPUTED_VALUE"""),7.6923076923076925) -> 7.6923077 | F37: =IFERROR(__xludf.DUMMYFUNCTION("""COMPUTED_VALUE"""),4.0) -> 4 | G37: =IFERROR(__xludf.DUMMYFUNCTION("""COMPUTED_VALUE"""),92.3076923076923) -> 92.307692 | H37: =IFERROR(__xludf.DUMMYFUNCTION("""COMPUTED_VALUE"""),1.0) -> 1 | I37: =IFERROR(__xludf.DUMMYFUNCTION("""COMPUTED_VALUE"""),46054.0) -> 46054
A38: =IFERROR(__xludf.DUMMYFUNCTION("""COMPUTED_VALUE"""),1.0) -> 1 | B38: =IFERROR(__xludf.DUMMYFUNCTION("""COMPUTED_VALUE"""),"CULTURA DIGITAL II") -> CULTURA DIGITAL II | C38: =IFERROR(__xludf.DUMMYFUNCTION("""COMPUTED_VALUE"""),96.15384615384616) -> 96.153846 | D38: =IFERROR(__xludf.DUMMYFUNCTION("""COMPUTED_VALUE"""),8.634615384615385) -> 8.6346154 | E38: =IFERROR(__xludf.DUMMYFUNCTION("""COMPUTED_VALUE"""),7.6923076923076925) -> 7.6923077 | F38: =IFERROR(__xludf.DUMMYFUNCTION("""COMPUTED_VALUE"""),4.0) -> 4 | G38: =IFERROR(__xludf.DUMMYFUNCTION("""COMPUTED_VALUE"""),92.3076923076923) -> 92.307692 | H38: =IFERROR(__xludf.DUMMYFUNCTION("""COMPUTED_VALUE"""),1.0) -> 1 | I38: =IFERROR(__xludf.DUMMYFUNCTION("""COMPUTED_VALUE"""),46054.0) -> 46054
A39: =IFERROR(__xludf.DUMMYFUNCTION("""COMPUTED_VALUE"""),1.0) -> 1 | B39: =IFERROR(__xludf.DUMMYFUNCTION("""COMPUTED_VALUE"""),"CIENCIAS NATURALES, EXPERIMENTALES Y TECNOLOGIA II") -> CIENCIAS NATURALES, EXPERIMENTALES Y TECNOLOGIA II | C39: =IFERROR(__xludf.DUMMYFUNCTION("""COMPUTED_VALUE"""),98.07692307692308) -> 98.076923 | D39: =IFERROR(__xludf.DUMMYFUNCTION("""COMPUTED_VALUE"""),8.634615384615385) -> 8.6346154 | E39: =IFERROR(__xludf.DUMMYFUNCTION("""COMPUTED_VALUE"""),7.6923076923076925) -> 7.6923077 | F39: =IFERROR(__xludf.DUMMYFUNCTION("""COMPUTED_VALUE"""),4.0) -> 4 | G39: =IFERROR(__xludf.DUMMYFUNCTION("""COMPUTED_VALUE"""),92.3076923076923) -> 92.307692 | H39: =IFERROR(__xludf.DUMMYFUNCTION("""COMPUTED_VALUE"""),1.0) -> 1 | I39: =IFERROR(__xludf.DUMMYFUNCTION("""COMPUTED_VALUE"""),46054.0) -> 46054
A40: =IFERROR(__xludf.DUMMYFUNCTION("""COMPUTED_VALUE"""),1.0) -> 1 | B40: =IFERROR(__xludf.DUMMYFUNCTION("""COMPUTED_VALUE"""),"PENSAMIENTO FILOSÓFICO Y HUMANIDADES II") -> PENSAMIENTO FILOSÓFICO Y HUMANIDADES II | C40: =IFERROR(__xludf.DUMMYFUNCTION("""COMPUTED_VALUE"""),96.15384615384616) -> 96.153846 | D40: =IFERROR(__xludf.DUMMYFUNCTION("""COMPUTED_VALUE"""),8.634615384615385) -> 8.6346154 | E40: =IFERROR(__xludf.DUMMYFUNCTION("""COMPUTED_VALUE"""),7.6923076923076925) -> 7.6923077 | F40: =IFERROR(__xludf.DUMMYFUNCTION("""COMPUTED_VALUE"""),4.0) -> 4 | G40: =IFERROR(__xludf.DUMMYFUNCTION("""COMPUTED_VALUE"""),92.3076923076923) -> 92.307692 | H40: =IFERROR(__xludf.DUMMYFUNCTION("""COMPUTED_VALUE"""),1.0) -> 1 | I40: =IFERROR(__xludf.DUMMYFUNCTION("""COMPUTED_VALUE"""),46054.0) -> 46054
...

Sheet PRIMERO
A1: PROMEDIO | B1: PARCIAL I | E1: PARCIAL II | H1: PARCIAL III
A2: UAC | B2: 46023 | C2: 46054 | D2: 46082 | E2: 46023 | F2: 46054 | G2: 46082 | H2: 46023 | I2: 46054 | J2: 46082
A3: ='TURNO MATUTINO'!B2 -> LENGUA Y COMUNICACIÓN II | B3: ='TURNO MATUTINO'!D2 -> 7.1132075 | C3: ='TURNO MATUTINO'!D35 -> 7.9230769 | D3: ='TURNO MATUTINO'!D68 -> 7.8867925
A4: ='TURNO MATUTINO'!B3 -> INGLÉS II | B4: ='TURNO MATUTINO'!D3 -> 8.6415094 | C4: ='TURNO MATUTINO'!D36 -> 8.6346154 | D4: ='TURNO MATUTINO'!D69 -> 8.6415094
A5: ='TURNO MATUTINO'!B4 -> PENSAMIENTO MATEMÁTICO II | B5: ='TURNO MATUTINO'!D4 -> 6.4528302 | C5: ='TURNO MATUTINO'!D37 -> 8.6346154 | D5: ='TURNO MATUTINO'!D70 -> 6.4528302
A6: ='TURNO MATUTINO'!B5 -> CULTURA DIGITAL II | B6: ='TURNO MATUTINO'!D5 -> 7.8867925 | C6: ='TURNO MATUTINO'!D38 -> 8.6346154 | D6: ='TURNO MATUTINO'!D71 -> 7.8867925
A7: ='TURNO MATUTINO'!B6 -> CIENCIAS NATURALES, EXPERIMENTALES Y TECNOLOGIA II | B7: ='TURNO MATUTINO'!D6 -> 7.8867925 | C7: ='TURNO MATUTINO'!D39 -> 8.6346154 | D7: ='TURNO MATUTINO'!D72 -> 7.8867925
A8: ='TURNO MATUTINO'!B7 -> PENSAMIENTO FILOSÓFICO Y HUMANIDADES II | B8: ='TURNO MATUTINO'!D7 -> 7.8867925 | C8: ='TURNO MATUTINO'!D40 -> 8.6346154 | D8: ='TURNO MATUTINO'!D73 -> 7.8867925
A9: ='TURNO MATUTINO'!B8 -> CIENCIAS SOCIALES II | B9: ='TURNO MATUTINO'!D8 -> 7.8867925 | C9: ='TURNO MATUTINO'!D41 -> 8.6346154 | D9: ='TURNO MATUTINO'!D74 -> 7.8867925
A10: ='TURNO MATUTINO'!B9 -> TALLER DE CIENCIAS I | B10: ='TURNO MATUTINO'!D9 -> 7.8867925 | C10: ='TURNO MATUTINO'!D42 -> 8.6346154 | D10: ='TURNO MATUTINO'!D75 -> 7.8867925
A11: ='TURNO MATUTINO'!B10 -> ACTIVIDADES FISICAS Y DEPORTIVAS II | B11: ='TURNO MATUTINO'!D10 -> 7.8867925 | C11: ='TURNO MATUTINO'!D43 -> 8.6346154 | D11: ='TURNO MATUTINO'!D76 -> 7.8867925
A12: ='TURNO MATUTINO'!B11 -> EDUCACION PARA LA SALUD II | B12: ='TURNO MATUTINO'!D11 -> 7.8867925 | C12: ='TURNO MATUTINO'!D44 -> 8.6346154 | D12: ='TURNO MATUTINO'!D77 -> 7.8867925
A13: ='TURNO MATUTINO'!B12 -> TEMAS SELECTOS DE IGUALDAD Y DERECHOS HUMANOS II | B13: ='TURNO MATUTINO'!D12 -> 7.1132075 | C13: ='TURNO MATUTINO'!D45 -> 8.6346154 | D13: ='TURNO MATUTINO'!D78 -> 7.8867925
B14: =AVERAGE(B3:B13) -> 7.6843911 | C14: =AVERAGE(C3:C13) -> 8.5699301 | D14: =AVERAGE(D3:D13) -> 7.8250429
B15: =AVERAGE(B14:D14) -> 8.0264547

Sheet SEGUNDO

Sheet TERCERO
